Workbook
Name CoName: SUCAP!$T$2
Name ImpEQT: SUCAP!$V$4
Name IQ_CH: 110000
Name IQ_CQ: 5000
Name IQ_CY: 10000
Name IQ_DAILY: 500000
Name IQ_FH: 100000
Name IQ_FQ: 500
Name IQ_FY: 1000
Name IQ_LTM: 2000
Name IQ_MONTH: 15000
Name IQ_NTM: 6000
Name IQ_WEEK: 50000
Name IQ_YTD: 3000
Name LastActDate: SUCAP!$T$4
Name LastFYE: SUCAP!$T$3
Name LTMDate: SUCAP!$V$3

Sheet SUCAP
C1: =++CoName -> [Company Name] ([Sponsor Name / Non-Sponsored]) | S1: Don't Delete Columns
C2: Sources & Uses | Pro Forma Capitalization | S2: Company: | T2: [Company Name] ([Sponsor Name / Non-Sponsored])
C3: =++TEXT(TODAY(),"MMMM D, YYYY") -> April 21, 2026 | S3: Last FYE: | T3: 45657 | U3: LTM Period: | V3: 45930
S4: Last Actuals: | T4: 45930 | U4: Implied Eqt (Y/N) | V4: 1
A5: x | B5: x | C5: =++C2 -> Sources & Uses | Pro Forma Capitalization
C6: USD in 000s, except where noted
A8: x | B8: x | C8: Sources | H8: Uses | M8: Opening FCCR
C10: =++S52 -> Priority Revolver ($0.0MM) | F10: =++INDEX($U$51:$U$71,MATCH($C10,$S$51:$S$71,0)) -> 0 | H10: [Purchase Price] | K10: 0 | M10: =++C42 -> LTM 9/25A CA EBITDA | P10: =++I42 -> 0
C11: =++S56 -> 1L Term Loan B | F11: =++INDEX($U$51:$U$71,MATCH($C11,$S$51:$S$71,0)) -> 0 | H11: [Use] | K11: 0 | M11: ( – ) Adjustments | P11: 0
C12: =++S59 -> 1L DDTL ($0.0MM) | F12: =++INDEX($U$51:$U$71,MATCH($C12,$S$51:$S$71,0)) -> 0 | H12: [Use] | K12: 0 | M12: ( – ) Cash Taxes | P12: 0
C13: Owner Common Equity | F13: =++F20-SUM(F10:F12) -> 0 | H13: [Use] | K13: 0 | M13: ( – ) Capital Expenditures | P13: 0
H14: Financing Fees | K14: =++SUM(AA51:AA71) -> 0 | M14: FCCR Numerator | P14: =++SUM(P10:P13) -> 0
H15: Transaction Expenses | K15: 0
M16: Cash Interest Expense | P16: 0
M17: ( + ) Mandatory Amortization | P17: 0
M18: FCCR Denomintor | P18: =++SUM(P16:P17) -> 0
C20: Total Sources | F20: =++K20 -> 0 | H20: Total Uses | K20: =++SUM(K10:K19) -> 0 | M20: FCCR | P20: =++IFERROR(P14/P18,0) -> 0
B23: x | C23: Pro Forma Capitalization
C25: USD in 000's, except where noted | I25: =++"Pro Forma ("&TEXT(LTMDate,"M/YY")&IF(LTMDate>LastActDate,"E","A")&")" -> Pro Forma (9/25A)
C27: =++"FYE "&TEXT(LastFYE,"MMMM DD")&"st" -> FYE December 31st | I27: $ | J27: Multiple | K27: % Cap | M27: Maturity | N27: Pricing | O27: OID | P27: Call Pro
C29: Cash & Equivalents | I29: 0
C31: =++C10 -> Priority Revolver ($0.0MM) | I31: =++F10 -> 0 | J31: =++IFERROR(I31/I$42,0) -> 0 | K31: =++IFERROR(I31/I$39,0) -> 0 | M31: =++INDEX(V$51:V$71,MATCH($C31,$S$51:$S$71,0)) -> 45199 | N31: =++"S + "&TEXT(INDEX(W$51:W$71,MATCH($C31,$S$51:$S$71,0))*10000,"#,###") -> S + 350 | O31: =100-(INDEX(Z$51:Z$71,MATCH($C31,$S$51:$S$71,0))*100) -> 99.5 | P31: =++INDEX(AB$51:AB$71,MATCH($C31,$S$51:$S$71,0)) -> n/a
C32: =++C11 -> 1L Term Loan B | I32: =++F11 -> 0 | J32: =++IFERROR(I32/I$42,0) -> 0 | K32: =++IFERROR(I32/I$39,0) -> 0 | M32: =++INDEX(V$51:V$71,MATCH($C32,$S$51:$S$71,0)) -> 45199 | N32: =++"S + "&TEXT(INDEX(W$51:W$71,MATCH($C32,$S$51:$S$71,0))*10000,"#,###") -> S + 525 | O32: =100-(INDEX(Z$51:Z$71,MATCH($C32,$S$51:$S$71,0))*100) -> 98 | P32: =++INDEX(AB$51:AB$71,MATCH($C32,$S$51:$S$71,0)) -> 102 / 101
C33: =++C12 -> 1L DDTL ($0.0MM) | I33: =++F12 -> 0 | J33: =++IFERROR(I33/I$42,0) -> 0 | K33: =++IFERROR(I33/I$39,0) -> 0 | M33: =++INDEX(V$51:V$71,MATCH($C33,$S$51:$S$71,0)) -> 45199 | N33: =++"S + "&TEXT(INDEX(W$51:W$71,MATCH($C33,$S$51:$S$71,0))*10000,"#,###") -> S + 525 | O33: =100-(INDEX(Z$51:Z$71,MATCH($C33,$S$51:$S$71,0))*100) -> 98 | P33: =++INDEX(AB$51:AB$71,MATCH($C33,$S$51:$S$71,0)) -> 102 / 101
C34: Total Debt | I34: =++SUM(I31:I33) -> 0 | J34: =++IFERROR(I34/I$42,0) -> 0 | K34: =++IFERROR(I34/I$39,0) -> 0
C35: Total Net Debt | I35: =++I34-I$29 -> 0 | J35: =++IFERROR(I35/I$42,0) -> 0
C37: =++C13 -> Owner Common Equity | I37: =++F13 -> 0 | J37: =++IFERROR(I37/I$42,0) -> 0 | K37: =++IFERROR(I37/I$39,0) -> 0
C38: Implied Equity | I38: =++IF(ImpEQT=1,I39-SUM(I34,I37),0) -> 0 | J38: =++IFERROR(I38/I$42,0) -> 0 | K38: =++IFERROR(I38/I$39,0) -> 0
C39: Total Capitalization | I39: =++IF(ImpEQT=1,SUM(I40,I29),SUM(I34,I37:I38)) -> 0 | J39: =++IFERROR(I39/I$42,0) -> 0 | K39: =++IFERROR(I39/I$39,0) -> 0
C40: TEV | I40: =++IF(ImpEQT=1,I42*J40,I39-I$29) -> 0 | J40: =++IF(ImpEQT=1,$U$76,IFERROR(I40/I$42,0)) -> 10
C42: =++"LTM "&TEXT(LTMDate,"M/YY")&IF(LTMDate>LastActDate,"E","A")&" CA EBITDA" -> LTM 9/25A CA EBITDA | I42: {=++INDEX(FinInputs!$G281:$AH281,0,MATCH(LTMDate,FinInputs!$G$3:$AH$3,0))} -> 0
A45: x | B45: x | S45: Facilities Detail
X47: Fees
S49: Tranche | T49: Global $ | U49: Funded $ | V49: Maturity | W49: Pricing | X49: Upfront Fees (%) | Y49: Deferred (%) | Z49: Total (%) | AA49: Upfront | AB49: Call Pro
S51: =++"ABL Revolver ($"&TEXT(T51/1000,"#,##0.0")&"MM)" -> ABL Revolver ($0.0MM) | T51: 0 | U51: 0 | V51: 45199 | W51: 0.035 | X51: 0.005 | Y51: 0 | Z51: =++SUM(X51:Y51) -> 0.005 | AA51: =++IFERROR(T51*X51,"n/a") -> 0 | AB51: n/a
S52: =++"Priority Revolver ($"&TEXT(T52/1000,"#,##0.0")&"MM)" -> Priority Revolver ($0.0MM) | T52: 0 | U52: 0 | V52: 45199 | W52: 0.035 | X52: 0.005 | Y52: 0 | Z52: =++SUM(X52:Y52) -> 0.005 | AA52: =++IFERROR(T52*X52,"n/a") -> 0 | AB52: n/a
S53: =++"Revolver ($"&TEXT(T53/1000,"#,##0.0")&"MM)" -> Revolver ($0.0MM) | T53: 0 | U53: 0 | V53: 45199 | W53: 0.0525 | X53: 0.02 | Y53: 0 | Z53: =++SUM(X53:Y53) -> 0.02 | AA53: =++IFERROR(T53*X53,"n/a") -> 0 | AB53: n/a
S54: 1L Term Loan A | T54: 0 | U54: =++T54 -> 0 | V54: 45199 | W54: 0.035 | X54: 0.01 | Y54: 0 | Z54: =++SUM(X54:Y54) -> 0.01 | AA54: =++IFERROR(T54*X54,"n/a") -> 0 | AB54: 101
S55: 1L FO Term Loan | T55: 0 | U55: =++T55 -> 0 | V55: 45199 | W55: 0.035 | X55: 0.01 | Y55: 0 | Z55: =++SUM(X55:Y55) -> 0.01 | AA55: =++IFERROR(T55*X55,"n/a") -> 0 | AB55: 101
S56: 1L Term Loan B | T56: 0 | U56: =++T56 -> 0 | V56: 45199 | W56: 0.0525 | X56: 0.02 | Y56: 0 | Z56: =++SUM(X56:Y56) -> 0.02 | AA56: =++IFERROR(T56*X56,"n/a") -> 0 | AB56: 102 / 101
...

Sheet Top Customer
C1: =++CoName -> [Company Name] ([Sponsor Name / Non-Sponsored])
C2: Top 10 Customer Detail | G2: =++EOMONTH(H2,-12) -> 44926 | H2: =++EOMONTH(I2,-12) -> 45291 | I2: =++LastFYE -> 45657 | J2: =++LastActDate -> 45930 | M2: =++G2 -> 44926 | N2: =++H2 -> 45291 | O2: =++I2 -> 45657 | P2: =++J2 -> 45930 | T2: =++EOMONTH(J2,-12) -> 45565
C3: =++TEXT(TODAY(),"MMMM D, YYYY") -> April 21, 2026
A5: x | B5: x | C5: =++C2 -> Top 10 Customer Detail
C7: =++"USD in 000s | FYE "&TEXT(LastFYE,"M/D") -> USD in 000s | FYE 12/31 | G7: TTM Revenue | M7: TTM [Gross Profit]
C9: Customer | G9: =++"FY'"&RIGHT(YEAR(G$2),2)&"A" -> FY'22A | H9: =++"FY'"&RIGHT(YEAR(H$2),2)&"A" -> FY'23A | I9: =++"FY'"&RIGHT(YEAR(I$2),2)&"A" -> FY'24A | J9: =++"LTM "&TEXT(J$2,"M/YY")&"A" -> LTM 9/25A | K9: % Total | M9: =++"FY'"&RIGHT(YEAR(G$2),2)&"A" -> FY'22A | N9: =++"FY'"&RIGHT(YEAR(H$2),2)&"A" -> FY'23A | O9: =++"FY'"&RIGHT(YEAR(I$2),2)&"A" -> FY'24A | P9: =++"LTM "&TEXT(P$2,"M/YY")&"A" -> LTM 9/25A | Q9: % Total | T9: =++"LTM "&TEXT(T$2,"M/YY") -> LTM 9/24
A11: x | B11: x | C11: [Customer] | G11: 0 | H11: 0 | I11: 0 | J11: 0 | K11: =++IFERROR(J11/J$24,0) -> 0 | M11: 0 | N11: 0 | O11: 0 | P11: 0 | Q11: =++IFERROR(P11/P$24,0) -> 0 | T11: 0
C12: [Customer] | G12: 0 | H12: 0 | I12: 0 | J12: 0 | K12: =++IFERROR(J12/J$24,0) -> 0 | M12: 0 | N12: 0 | O12: 0 | P12: 0 | Q12: =++IFERROR(P12/P$24,0) -> 0 | T12: 0
C13: [Customer] | G13: 0 | H13: 0 | I13: 0 | J13: 0 | K13: =++IFERROR(J13/J$24,0) -> 0 | M13: 0 | N13: 0 | O13: 0 | P13: 0 | Q13: =++IFERROR(P13/P$24,0) -> 0 | T13: 0
C14: [Customer] | G14: 0 | H14: 0 | I14: 0 | J14: 0 | K14: =++IFERROR(J14/J$24,0) -> 0 | M14: 0 | N14: 0 | O14: 0 | P14: 0 | Q14: =++IFERROR(P14/P$24,0) -> 0 | T14: 0
C15: [Customer] | G15: 0 | H15: 0 | I15: 0 | J15: 0 | K15: =++IFERROR(J15/J$24,0) -> 0 | M15: 0 | N15: 0 | O15: 0 | P15: 0 | Q15: =++IFERROR(P15/P$24,0) -> 0 | T15: 0
C16: [Customer] | G16: 0 | H16: 0 | I16: 0 | J16: 0 | K16: =++IFERROR(J16/J$24,0) -> 0 | M16: 0 | N16: 0 | O16: 0 | P16: 0 | Q16: =++IFERROR(P16/P$24,0) -> 0 | T16: 0
C17: [Customer] | G17: 0 | H17: 0 | I17: 0 | J17: 0 | K17: =++IFERROR(J17/J$24,0) -> 0 | M17: 0 | N17: 0 | O17: 0 | P17: 0 | Q17: =++IFERROR(P17/P$24,0) -> 0 | T17: 0
C18: [Customer] | G18: 0 | H18: 0 | I18: 0 | J18: 0 | K18: =++IFERROR(J18/J$24,0) -> 0 | M18: 0 | N18: 0 | O18: 0 | P18: 0 | Q18: =++IFERROR(P18/P$24,0) -> 0 | T18: 0
C19: [Customer] | G19: 0 | H19: 0 | I19: 0 | J19: 0 | K19: =++IFERROR(J19/J$24,0) -> 0 | M19: 0 | N19: 0 | O19: 0 | P19: 0 | Q19: =++IFERROR(P19/P$24,0) -> 0 | T19: 0
C20: [Customer] | G20: 0 | H20: 0 | I20: 0 | J20: 0 | K20: =++IFERROR(J20/J$24,0) -> 0 | M20: 0 | N20: 0 | O20: 0 | P20: 0 | Q20: =++IFERROR(P20/P$24,0) -> 0 | T20: 0
B21: x | C21: Top 10 Customers | G21: =++SUM(G11:G20) -> 0 | H21: =++SUM(H11:H20) -> 0 | I21: =++SUM(I11:I20) -> 0 | J21: =++SUM(J11:J20) -> 0 | K21: =++SUM(K11:K20) -> 0 | M21: =++SUM(M11:M20) -> 0 | N21: =++SUM(N11:N20) -> 0 | O21: =++SUM(O11:O20) -> 0 | P21: =++SUM(P11:P20) -> 0 | Q21: =++SUM(Q11:Q20) -> 0 | T21: =++SUM(T11:T20) -> 0
C23: All Other (n = [X]) | G23: =++G24-G21 -> 0 | H23: =++H24-H21 -> 0 | I23: =++I24-I21 -> 0 | J23: =++J24-J21 -> 0 | K23: =++IFERROR(J23/J$24,0) -> 0 | M23: =++M24-M21 -> 0 | N23: =++N24-N21 -> 0 | O23: =++O24-O21 -> 0 | P23: =++P24-P21 -> 0 | Q23: =++IFERROR(P23/P$24,0) -> 0 | T23: =++T24-T21 -> 0
B24: x | C24: Total | G24: {=++INDEX(FinInputs!$G210:$AH210,0,MATCH(G$2,FinInputs!$G$3:$AH$3,0))} -> 0 | H24: {=++INDEX(FinInputs!$G210:$AH210,0,MATCH(H$2,FinInputs!$G$3:$AH$3,0))} -> 0 | I24: {=++INDEX(FinInputs!$G210:$AH210,0,MATCH(I$2,FinInputs!$G$3:$AH$3,0))} -> 0 | J24: {=++INDEX(FinInputs!$G210:$AH210,0,MATCH(J$2,FinInputs!$G$3:$AH$3,0))} -> 0 | K24: =++SUM(K21,K23) -> 0 | M24: {=++INDEX(FinInputs!$G219:$AH219,0,MATCH(G$2,FinInputs!$G$3:$AH$3,0))} -> 0 | N24: {=++INDEX(FinInputs!$G219:$AH219,0,MATCH(H$2,FinInputs!$G$3:$AH$3,0))} -> 0 | O24: {=++INDEX(FinInputs!$G219:$AH219,0,MATCH(I$2,FinInputs!$G$3:$AH$3,0))} -> 0 | P24: {=++INDEX(FinInputs!$G219:$AH219,0,MATCH(J$2,FinInputs!$G$3:$AH$3,0))} -> 0 | Q24: =++SUM(Q21,Q23) -> 0 | T24: {=++INDEX(FinInputs!$G210:$AH210,0,MATCH(T$2,FinInputs!$G$3:$AH$3,0))} -> 0
C26: Memo: Global Top 1 / 10 Customer (% Total)
C27: Global Top Customer | G27: 0 | H27: 0 | I27: 0 | J27: =++K11 -> 0 | M27: 0 | N27: 0 | O27: 0 | P27: =++Q11 -> 0
C28: Global Top 10 Customer | G28: 0 | H28: 0 | I28: 0 | J28: =++K21 -> 0 | M28: 0 | N28: 0 | O28: 0 | P28: =++Q21 -> 0
G31: =++G7&" (% y/y)" -> TTM Revenue (% y/y) | M31: =++M7&" (% margin)" -> TTM [Gross Profit] (% margin)
C33: Customer | G33: =++"FY'"&RIGHT(YEAR(M$2),2)&"A" -> FY'22A | H33: =++"FY'"&RIGHT(YEAR(N$2),2)&"A" -> FY'23A | I33: =++"FY'"&RIGHT(YEAR(O$2),2)&"A" -> FY'24A | J33: =++"LTM "&TEXT(J$2,"M/YY")&"A" -> LTM 9/25A | K33: CAGR | M33: =++"FY'"&RIGHT(YEAR(M$2),2)&"A" -> FY'22A | N33: =++"FY'"&RIGHT(YEAR(N$2),2)&"A" -> FY'23A | O33: =++"FY'"&RIGHT(YEAR(O$2),2)&"A" -> FY'24A | P33: =++"LTM "&TEXT(P$2,"M/YY")&"A" -> LTM 9/25A | Q33: ∆ bps
C35: =++C11 -> [Customer] | H35: =++IFERROR(H11/G11-1,0) -> 0 | I35: =++IFERROR(I11/H11-1,0) -> 0 | J35: =++IFERROR(J11/T11-1,0) -> 0 | K35: =++IFERROR((J11/G11)^(1/YEARFRAC(G$2,J$2,1))-1,"nmf") -> nmf | M35: =++IFERROR(M11/G11,0) -> 0 | N35: =++IFERROR(N11/H11,0) -> 0 | O35: =++IFERROR(O11/I11,0) -> 0 | P35: =++IFERROR(P11/J11,0) -> 0 | Q35: =++(P35-M35)*10000 -> 0
C36: =++C12 -> [Customer] | H36: =++IFERROR(H12/G12-1,0) -> 0 | I36: =++IFERROR(I12/H12-1,0) -> 0 | J36: =++IFERROR(J12/T12-1,0) -> 0 | K36: =++IFERROR((J12/G12)^(1/YEARFRAC(G$2,J$2,1))-1,"nmf") -> nmf | M36: =++IFERROR(M12/G12,0) -> 0 | N36: =++IFERROR(N12/H12,0) -> 0 | O36: =++IFERROR(O12/I12,0) -> 0 | P36: =++IFERROR(P12/J12,0) -> 0 | Q36: =++(P36-M36)*10000 -> 0
C37: =++C13 -> [Customer] | H37: =++IFERROR(H13/G13-1,0) -> 0 | I37: =++IFERROR(I13/H13-1,0) -> 0 | J37: =++IFERROR(J13/T13-1,0) -> 0 | K37: =++IFERROR((J13/G13)^(1/YEARFRAC(G$2,J$2,1))-1,"nmf") -> nmf | M37: =++IFERROR(M13/G13,0) -> 0 | N37: =++IFERROR(N13/H13,0) -> 0 | O37: =++IFERROR(O13/I13,0) -> 0 | P37: =++IFERROR(P13/J13,0) -> 0 | Q37: =++(P37-M37)*10000 -> 0
C38: =++C14 -> [Customer] | H38: =++IFERROR(H14/G14-1,0) -> 0 | I38: =++IFERROR(I14/H14-1,0) -> 0 | J38: =++IFERROR(J14/T14-1,0) -> 0 | K38: =++IFERROR((J14/G14)^(1/YEARFRAC(G$2,J$2,1))-1,"nmf") -> nmf | M38: =++IFERROR(M14/G14,0) -> 0 | N38: =++IFERROR(N14/H14,0) -> 0 | O38: =++IFERROR(O14/I14,0) -> 0 | P38: =++IFERROR(P14/J14,0) -> 0 | Q38: =++(P38-M38)*10000 -> 0
C39: =++C15 -> [Customer] | H39: =++IFERROR(H15/G15-1,0) -> 0 | I39: =++IFERROR(I15/H15-1,0) -> 0 | J39: =++IFERROR(J15/T15-1,0) -> 0 | K39: =++IFERROR((J15/G15)^(1/YEARFRAC(G$2,J$2,1))-1,"nmf") -> nmf | M39: =++IFERROR(M15/G15,0) -> 0 | N39: =++IFERROR(N15/H15,0) -> 0 | O39: =++IFERROR(O15/I15,0) -> 0 | P39: =++IFERROR(P15/J15,0) -> 0 | Q39: =++(P39-M39)*10000 -> 0
C40: =++C16 -> [Customer] | H40: =++IFERROR(H16/G16-1,0) -> 0 | I40: =++IFERROR(I16/H16-1,0) -> 0 | J40: =++IFERROR(J16/T16-1,0) -> 0 | K40: =++IFERROR((J16/G16)^(1/YEARFRAC(G$2,J$2,1))-1,"nmf") -> nmf | M40: =++IFERROR(M16/G16,0) -> 0 | N40: =++IFERROR(N16/H16,0) -> 0 | O40: =++IFERROR(O16/I16,0) -> 0 | P40: =++IFERROR(P16/J16,0) -> 0 | Q40: =++(P40-M40)*10000 -> 0
C41: =++C17 -> [Customer] | H41: =++IFERROR(H17/G17-1,0) -> 0 | I41: =++IFERROR(I17/H17-1,0) -> 0 | J41: =++IFERROR(J17/T17-1,0) -> 0 | K41: =++IFERROR((J17/G17)^(1/YEARFRAC(G$2,J$2,1))-1,"nmf") -> nmf | M41: =++IFERROR(M17/G17,0) -> 0 | N41: =++IFERROR(N17/H17,0) -> 0 | O41: =++IFERROR(O17/I17,0) -> 0 | P41: =++IFERROR(P17/J17,0) -> 0 | Q41: =++(P41-M41)*10000 -> 0
C42: =++C18 -> [Customer] | H42: =++IFERROR(H18/G18-1,0) -> 0 | I42: =++IFERROR(I18/H18-1,0) -> 0 | J42: =++IFERROR(J18/T18-1,0) -> 0 | K42: =++IFERROR((J18/G18)^(1/YEARFRAC(G$2,J$2,1))-1,"nmf") -> nmf | M42: =++IFERROR(M18/G18,0) -> 0 | N42: =++IFERROR(N18/H18,0) -> 0 | O42: =++IFERROR(O18/I18,0) -> 0 | P42: =++IFERROR(P18/J18,0) -> 0 | Q42: =++(P42-M42)*10000 -> 0
C43: =++C19 -> [Customer] | H43: =++IFERROR(H19/G19-1,0) -> 0 | I43: =++IFERROR(I19/H19-1,0) -> 0 | J43: =++IFERROR(J19/T19-1,0) -> 0 | K43: =++IFERROR((J19/G19)^(1/YEARFRAC(G$2,J$2,1))-1,"nmf") -> nmf | M43: =++IFERROR(M19/G19,0) -> 0 | N43: =++IFERROR(N19/H19,0) -> 0 | O43: =++IFERROR(O19/I19,0) -> 0 | P43: =++IFERROR(P19/J19,0) -> 0 | Q43: =++(P43-M43)*10000 -> 0
C44: =++C20 -> [Customer] | H44: =++IFERROR(H20/G20-1,0) -> 0 | I44: =++IFERROR(I20/H20-1,0) -> 0 | J44: =++IFERROR(J20/T20-1,0) -> 0 | K44: =++IFERROR((J20/G20)^(1/YEARFRAC(G$2,J$2,1))-1,"nmf") -> nmf | M44: =++IFERROR(M20/G20,0) -> 0 | N44: =++IFERROR(N20/H20,0) -> 0 | O44: =++IFERROR(O20/I20,0) -> 0 | P44: =++IFERROR(P20/J20,0) -> 0 | Q44: =++(P44-M44)*10000 -> 0
C45: =++C21 -> Top 10 Customers | H45: =++IFERROR(H21/G21-1,0) -> 0 | I45: =++IFERROR(I21/H21-1,0) -> 0 | J45: =++IFERROR(J21/T21-1,0) -> 0 | K45: =++IFERROR((J21/G21)^(1/YEARFRAC(G$2,J$2,1))-1,"nmf") -> nmf | M45: =++IFERROR(M21/G21,0) -> 0 | N45: =++IFERROR(N21/H21,0) -> 0 | O45: =++IFERROR(O21/I21,0) -> 0 | P45: =++IFERROR(P21/J21,0) -> 0 | Q45: =++(P45-M45)*10000 -> 0
C47: =++C23 -> All Other (n = [X]) | H47: =++IFERROR(H23/G23-1,0) -> 0 | I47: =++IFERROR(I23/H23-1,0) -> 0 | J47: =++IFERROR(J23/T23-1,0) -> 0 | K47: =++IFERROR((J23/G23)^(1/YEARFRAC(G$2,J$2,1))-1,"nmf") -> nmf | M47: =++IFERROR(M23/G23,0) -> 0 | N47: =++IFERROR(N23/H23,0) -> 0 | O47: =++IFERROR(O23/I23,0) -> 0 | P47: =++IFERROR(P23/J23,0) -> 0 | Q47: =++(P47-M47)*10000 -> 0
C48: =++C24 -> Total | H48: =++IFERROR(H24/G24-1,0) -> 0 | I48: =++IFERROR(I24/H24-1,0) -> 0 | J48: =++IFERROR(J24/T24-1,0) -> 0 | K48: =++IFERROR((J24/G24)^(1/YEARFRAC(G$2,J$2,1))-1,"nmf") -> nmf | M48: =++IFERROR(M24/G24,0) -> 0 | N48: =++IFERROR(N24/H24,0) -> 0 | O48: =++IFERROR(O24/I24,0) -> 0 | P48: =++IFERROR(P24/J24,0) -> 0 | Q48: =++(P48-M48)*10000 -> 0
A52: x | B52: x

Sheet Top Supplier
C1: =++CoName -> [Company Name] ([Sponsor Name / Non-Sponsored])
C2: Top 10 Supplier Detail | G2: =++EOMONTH(H2,-12) -> 44926 | H2: =++EOMONTH(I2,-12) -> 45291 | I2: =++LastFYE -> 45657 | J2: =++LastActDate -> 45930 | M2: =++G2 -> 44926 | N2: =++H2 -> 45291 | O2: =++I2 -> 45657 | P2: =++J2 -> 45930 | T2: =++EOMONTH(J2,-12) -> 45565
C3: =++TEXT(TODAY(),"MMMM D, YYYY") -> April 21, 2026
A5: x | B5: x | C5: =++C2 -> Top 10 Supplier Detail
C7: =++"USD in 000s | FYE "&TEXT(LastFYE,"M/D") -> USD in 000s | FYE 12/31 | G7: TTM Purchases | M7: =++G7&" (% y/y)" -> TTM Purchases (% y/y)
C9: Supplier | G9: =++"FY'"&RIGHT(YEAR(G$2),2)&"A" -> FY'22A | H9: =++"FY'"&RIGHT(YEAR(H$2),2)&"A" -> FY'23A | I9: =++"FY'"&RIGHT(YEAR(I$2),2)&"A" -> FY'24A | J9: =++"LTM "&TEXT(J$2,"M/YY")&"A" -> LTM 9/25A | K9: % Total | M9: =++"FY'"&RIGHT(YEAR(M$2),2)&"A" -> FY'22A | N9: =++"FY'"&RIGHT(YEAR(N$2),2)&"A" -> FY'23A | O9: =++"FY'"&RIGHT(YEAR(O$2),2)&"A" -> FY'24A | P9: =++"LTM "&TEXT(P$2,"M/YY")&"A" -> LTM 9/25A | Q9: CAGR | T9: =++"LTM "&TEXT(T$2,"M/YY")&"A" -> LTM 9/24A
A11: x | B11: x | C11: [Supplier] | G11: 0 | H11: 0 | I11: 0 | J11: 0 | K11: =++IFERROR(J11/J$24,0) -> 0 | N11: =++IFERROR(H11/G11-1,0) -> 0 | O11: =++IFERROR(I11/H11-1,0) -> 0 | P11: =++IFERROR(J11/T11-1,0) -> 0 | Q11: =++IFERROR((J11/G11)^(1/YEARFRAC(G$2,J$2,1))-1,"nmf") -> nmf | T11: 0
C12: [Supplier] | G12: 0 | H12: 0 | I12: 0 | J12: 0 | K12: =++IFERROR(J12/J$24,0) -> 0 | N12: =++IFERROR(H12/G12-1,0) -> 0 | O12: =++IFERROR(I12/H12-1,0) -> 0 | P12: =++IFERROR(J12/T12-1,0) -> 0 | Q12: =++IFERROR((J12/G12)^(1/YEARFRAC(G$2,J$2,1))-1,"nmf") -> nmf | T12: 0
C13: [Supplier] | G13: 0 | H13: 0 | I13: 0 | J13: 0 | K13: =++IFERROR(J13/J$24,0) -> 0 | N13: =++IFERROR(H13/G13-1,0) -> 0 | O13: =++IFERROR(I13/H13-1,0) -> 0 | P13: =++IFERROR(J13/T13-1,0) -> 0 | Q13: =++IFERROR((J13/G13)^(1/YEARFRAC(G$2,J$2,1))-1,"nmf") -> nmf | T13: 0
C14: [Supplier] | G14: 0 | H14: 0 | I14: 0 | J14: 0 | K14: =++IFERROR(J14/J$24,0) -> 0 | N14: =++IFERROR(H14/G14-1,0) -> 0 | O14: =++IFERROR(I14/H14-1,0) -> 0 | P14: =++IFERROR(J14/T14-1,0) -> 0 | Q14: =++IFERROR((J14/G14)^(1/YEARFRAC(G$2,J$2,1))-1,"nmf") -> nmf | T14: 0
C15: [Supplier] | G15: 0 | H15: 0 | I15: 0 | J15: 0 | K15: =++IFERROR(J15/J$24,0) -> 0 | N15: =++IFERROR(H15/G15-1,0) -> 0 | O15: =++IFERROR(I15/H15-1,0) -> 0 | P15: =++IFERROR(J15/T15-1,0) -> 0 | Q15: =++IFERROR((J15/G15)^(1/YEARFRAC(G$2,J$2,1))-1,"nmf") -> nmf | T15: 0
C16: [Supplier] | G16: 0 | H16: 0 | I16: 0 | J16: 0 | K16: =++IFERROR(J16/J$24,0) -> 0 | N16: =++IFERROR(H16/G16-1,0) -> 0 | O16: =++IFERROR(I16/H16-1,0) -> 0 | P16: =++IFERROR(J16/T16-1,0) -> 0 | Q16: =++IFERROR((J16/G16)^(1/YEARFRAC(G$2,J$2,1))-1,"nmf") -> nmf | T16: 0
C17: [Supplier] | G17: 0 | H17: 0 | I17: 0 | J17: 0 | K17: =++IFERROR(J17/J$24,0) -> 0 | N17: =++IFERROR(H17/G17-1,0) -> 0 | O17: =++IFERROR(I17/H17-1,0) -> 0 | P17: =++IFERROR(J17/T17-1,0) -> 0 | Q17: =++IFERROR((J17/G17)^(1/YEARFRAC(G$2,J$2,1))-1,"nmf") -> nmf | T17: 0
C18: [Supplier] | G18: 0 | H18: 0 | I18: 0 | J18: 0 | K18: =++IFERROR(J18/J$24,0) -> 0 | N18: =++IFERROR(H18/G18-1,0) -> 0 | O18: =++IFERROR(I18/H18-1,0) -> 0 | P18: =++IFERROR(J18/T18-1,0) -> 0 | Q18: =++IFERROR((J18/G18)^(1/YEARFRAC(G$2,J$2,1))-1,"nmf") -> nmf | T18: 0
C19: [Supplier] | G19: 0 | H19: 0 | I19: 0 | J19: 0 | K19: =++IFERROR(J19/J$24,0) -> 0 | N19: =++IFERROR(H19/G19-1,0) -> 0 | O19: =++IFERROR(I19/H19-1,0) -> 0 | P19: =++IFERROR(J19/T19-1,0) -> 0 | Q19: =++IFERROR((J19/G19)^(1/YEARFRAC(G$2,J$2,1))-1,"nmf") -> nmf | T19: 0
C20: [Supplier] | G20: 0 | H20: 0 | I20: 0 | J20: 0 | K20: =++IFERROR(J20/J$24,0) -> 0 | N20: =++IFERROR(H20/G20-1,0) -> 0 | O20: =++IFERROR(I20/H20-1,0) -> 0 | P20: =++IFERROR(J20/T20-1,0) -> 0 | Q20: =++IFERROR((J20/G20)^(1/YEARFRAC(G$2,J$2,1))-1,"nmf") -> nmf | T20: 0
B21: x | C21: Top 10 Suppliers | G21: =++SUM(G11:G20) -> 0 | H21: =++SUM(H11:H20) -> 0 | I21: =++SUM(I11:I20) -> 0 | J21: =++SUM(J11:J20) -> 0 | K21: =++SUM(K11:K20) -> 0 | N21: =++IFERROR(H21/G21-1,0) -> 0 | O21: =++IFERROR(I21/H21-1,0) -> 0 | P21: =++IFERROR(J21/T21-1,0) -> 0 | Q21: =++IFERROR((J21/G21)^(1/YEARFRAC(G$2,J$2,1))-1,"nmf") -> nmf | T21: =++SUM(T11:T20) -> 0
C23: All Other (n = [X]) | G23: =++G24-G21 -> 0 | H23: =++H24-H21 -> 0 | I23: =++I24-I21 -> 0 | J23: =++J24-J21 -> 0 | K23: =++IFERROR(J23/J$24,0) -> 0 | N23: =++IFERROR(H23/G23-1,0) -> 0 | O23: =++IFERROR(I23/H23-1,0) -> 0 | P23: =++IFERROR(J23/T23-1,0) -> 0 | Q23: =++IFERROR((J23/G23)^(1/YEARFRAC(G$2,J$2,1))-1,"nmf") -> nmf | T23: =++T24-T21 -> 0
B24: x | C24: Total Purchases | G24: 0 | H24: 0 | I24: 0 | J24: 0 | K24: =++SUM(K21,K23) -> 0 | N24: =++IFERROR(H24/G24-1,0) -> 0 | O24: =++IFERROR(I24/H24-1,0) -> 0 | P24: =++IFERROR(J24/T24-1,0) -> 0 | Q24: =++IFERROR((J24/G24)^(1/YEARFRAC(G$2,J$2,1))-1,"nmf") -> nmf | T24: 0
A29: x | B29: x

Sheet HistFin
C1: =++CoName -> [Company Name] ([Sponsor Name / Non-Sponsored])
C2: Historical Financial Summary | G2: =++EOMONTH(H2,-12) -> 44926 | H2: =++EOMONTH(I2,-12) -> 45291 | I2: =++LastFYE -> 45657 | J2: =++LastActDate -> 45930 | K2: =++LTMDate -> 45930 | L2: =++EOMONTH(I2,12) -> 46022 | P2: =++EOMONTH(Q2,-12) -> 45565 | Q2: =++J2 -> 45930
C3: =++TEXT(TODAY(),"MMMM D, YYYY") -> April 21, 2026
A5: x | B5: x | C5: =++C2 -> Historical Financial Summary
C7: USD in 000s, except where noted | G7: Trailing Twelve Month Period Ending, | N7: CAGR | P7: YTD Period Ending,
C9: =++"FYE "&TEXT(LastFYE,"MMMM DD")&"st" -> FYE December 31st | G9: =++"FY'"&RIGHT(YEAR(G$2),2)&"A" -> FY'22A | H9: =++"FY'"&RIGHT(YEAR(H$2),2)&"A" -> FY'23A | I9: =++"FY'"&RIGHT(YEAR(I$2),2)&"A" -> FY'24A | J9: =++"LTM "&TEXT(J$2,"M/YY")&"A" -> LTM 9/25A | K9: =++"LTM "&TEXT(K$2,"M/YY")&IF(LTMDate>LastActDate,"E","A") -> LTM 9/25A | L9: =++"FY'"&RIGHT(YEAR(L$2),2)&"E" -> FY'25E | N9: =++RIGHT(G9,4)&" - LTM" -> '22A - LTM | P9: =++TEXT(P$2,"M/YY")&"A" -> 9/24A | Q9: =++TEXT(Q$2,"M/YY")&"A" -> 9/25A
A11: x | B11: x | C11: =++FinInputs!C204 -> [Segment] | G11: {=++INDEX(FinInputs!$G204:$AH204,0,MATCH(G$2,FinInputs!$G$3:$AH$3,0))} -> 0 | H11: {=++INDEX(FinInputs!$G204:$AH204,0,MATCH(H$2,FinInputs!$G$3:$AH$3,0))} -> 0 | I11: {=++INDEX(FinInputs!$G204:$AH204,0,MATCH(I$2,FinInputs!$G$3:$AH$3,0))} -> 0 | J11: {=++INDEX(FinInputs!$G204:$AH204,0,MATCH(J$2,FinInputs!$G$3:$AH$3,0))} -> 0 | K11: {=++INDEX(FinInputs!$G204:$AH204,0,MATCH(K$2,FinInputs!$G$3:$AH$3,0))} -> 0 | L11: {=++INDEX(FinInputs!$G204:$AH204,0,MATCH(L$2,FinInputs!$G$3:$AH$3,0))} -> 0 | N11: =++IFERROR((J11/G11)^(1/YEARFRAC(G$2,J$2,1))-1,"nmf") -> nmf | P11: {=++INDEX(FinInputs!$G107:$AH107,0,MATCH(P$2,FinInputs!$G$3:$AH$3,0))} -> 0 | Q11: {=++INDEX(FinInputs!$G107:$AH107,0,MATCH(Q$2,FinInputs!$G$3:$AH$3,0))} -> 0
C12: =++FinInputs!C205 -> [Segment] | G12: {=++INDEX(FinInputs!$G205:$AH205,0,MATCH(G$2,FinInputs!$G$3:$AH$3,0))} -> 0 | H12: {=++INDEX(FinInputs!$G205:$AH205,0,MATCH(H$2,FinInputs!$G$3:$AH$3,0))} -> 0 | I12: {=++INDEX(FinInputs!$G205:$AH205,0,MATCH(I$2,FinInputs!$G$3:$AH$3,0))} -> 0 | J12: {=++INDEX(FinInputs!$G205:$AH205,0,MATCH(J$2,FinInputs!$G$3:$AH$3,0))} -> 0 | K12: {=++INDEX(FinInputs!$G205:$AH205,0,MATCH(K$2,FinInputs!$G$3:$AH$3,0))} -> 0 | L12: {=++INDEX(FinInputs!$G205:$AH205,0,MATCH(L$2,FinInputs!$G$3:$AH$3,0))} -> 0 | N12: =++IFERROR((J12/G12)^(1/YEARFRAC(G$2,J$2,1))-1,"nmf") -> nmf | P12: {=++INDEX(FinInputs!$G108:$AH108,0,MATCH(P$2,FinInputs!$G$3:$AH$3,0))} -> 0 | Q12: {=++INDEX(FinInputs!$G108:$AH108,0,MATCH(Q$2,FinInputs!$G$3:$AH$3,0))} -> 0
C13: =++FinInputs!C206 -> [Segment] | G13: {=++INDEX(FinInputs!$G206:$AH206,0,MATCH(G$2,FinInputs!$G$3:$AH$3,0))} -> 0 | H13: {=++INDEX(FinInputs!$G206:$AH206,0,MATCH(H$2,FinInputs!$G$3:$AH$3,0))} -> 0 | I13: {=++INDEX(FinInputs!$G206:$AH206,0,MATCH(I$2,FinInputs!$G$3:$AH$3,0))} -> 0 | J13: {=++INDEX(FinInputs!$G206:$AH206,0,MATCH(J$2,FinInputs!$G$3:$AH$3,0))} -> 0 | K13: {=++INDEX(FinInputs!$G206:$AH206,0,MATCH(K$2,FinInputs!$G$3:$AH$3,0))} -> 0 | L13: {=++INDEX(FinInputs!$G206:$AH206,0,MATCH(L$2,FinInputs!$G$3:$AH$3,0))} -> 0 | N13: =++IFERROR((J13/G13)^(1/YEARFRAC(G$2,J$2,1))-1,"nmf") -> nmf | P13: {=++INDEX(FinInputs!$G109:$AH109,0,MATCH(P$2,FinInputs!$G$3:$AH$3,0))} -> 0 | Q13: {=++INDEX(FinInputs!$G109:$AH109,0,MATCH(Q$2,FinInputs!$G$3:$AH$3,0))} -> 0
C14: =++FinInputs!C207 -> [Segment] | G14: {=++INDEX(FinInputs!$G207:$AH207,0,MATCH(G$2,FinInputs!$G$3:$AH$3,0))} -> 0 | H14: {=++INDEX(FinInputs!$G207:$AH207,0,MATCH(H$2,FinInputs!$G$3:$AH$3,0))} -> 0 | I14: {=++INDEX(FinInputs!$G207:$AH207,0,MATCH(I$2,FinInputs!$G$3:$AH$3,0))} -> 0 | J14: {=++INDEX(FinInputs!$G207:$AH207,0,MATCH(J$2,FinInputs!$G$3:$AH$3,0))} -> 0 | K14: {=++INDEX(FinInputs!$G207:$AH207,0,MATCH(K$2,FinInputs!$G$3:$AH$3,0))} -> 0 | L14: {=++INDEX(FinInputs!$G207:$AH207,0,MATCH(L$2,FinInputs!$G$3:$AH$3,0))} -> 0 | N14: =++IFERROR((J14/G14)^(1/YEARFRAC(G$2,J$2,1))-1,"nmf") -> nmf | P14: {=++INDEX(FinInputs!$G110:$AH110,0,MATCH(P$2,FinInputs!$G$3:$AH$3,0))} -> 0 | Q14: {=++INDEX(FinInputs!$G110:$AH110,0,MATCH(Q$2,FinInputs!$G$3:$AH$3,0))} -> 0
C15: =++FinInputs!C208 -> [Segment] | G15: {=++INDEX(FinInputs!$G208:$AH208,0,MATCH(G$2,FinInputs!$G$3:$AH$3,0))} -> 0 | H15: {=++INDEX(FinInputs!$G208:$AH208,0,MATCH(H$2,FinInputs!$G$3:$AH$3,0))} -> 0 | I15: {=++INDEX(FinInputs!$G208:$AH208,0,MATCH(I$2,FinInputs!$G$3:$AH$3,0))} -> 0 | J15: {=++INDEX(FinInputs!$G208:$AH208,0,MATCH(J$2,FinInputs!$G$3:$AH$3,0))} -> 0 | K15: {=++INDEX(FinInputs!$G208:$AH208,0,MATCH(K$2,FinInputs!$G$3:$AH$3,0))} -> 0 | L15: {=++INDEX(FinInputs!$G208:$AH208,0,MATCH(L$2,FinInputs!$G$3:$AH$3,0))} -> 0 | N15: =++IFERROR((J15/G15)^(1/YEARFRAC(G$2,J$2,1))-1,"nmf") -> nmf | P15: {=++INDEX(FinInputs!$G111:$AH111,0,MATCH(P$2,FinInputs!$G$3:$AH$3,0))} -> 0 | Q15: {=++INDEX(FinInputs!$G111:$AH111,0,MATCH(Q$2,FinInputs!$G$3:$AH$3,0))} -> 0
C16: =++FinInputs!C209 -> Other | G16: =++G17-SUM(G11:G15) -> 0 | H16: =++H17-SUM(H11:H15) -> 0 | I16: =++I17-SUM(I11:I15) -> 0 | J16: =++J17-SUM(J11:J15) -> 0 | K16: =++K17-SUM(K11:K15) -> 0 | L16: =++L17-SUM(L11:L15) -> 0 | N16: =++IFERROR((J16/G16)^(1/YEARFRAC(G$2,J$2,1))-1,"nmf") -> nmf | P16: =++P17-SUM(P11:P15) -> 0 | Q16: =++Q17-SUM(Q11:Q15) -> 0
B17: x | C17: =++FinInputs!C210 -> Revenue | G17: {=++INDEX(FinInputs!$G210:$AH210,0,MATCH(G$2,FinInputs!$G$3:$AH$3,0))} -> 0 | H17: {=++INDEX(FinInputs!$G210:$AH210,0,MATCH(H$2,FinInputs!$G$3:$AH$3,0))} -> 0 | I17: {=++INDEX(FinInputs!$G210:$AH210,0,MATCH(I$2,FinInputs!$G$3:$AH$3,0))} -> 0 | J17: {=++INDEX(FinInputs!$G210:$AH210,0,MATCH(J$2,FinInputs!$G$3:$AH$3,0))} -> 0 | K17: {=++INDEX(FinInputs!$G210:$AH210,0,MATCH(K$2,FinInputs!$G$3:$AH$3,0))} -> 0 | L17: {=++INDEX(FinInputs!$G210:$AH210,0,MATCH(L$2,FinInputs!$G$3:$AH$3,0))} -> 0 | N17: =++IFERROR((J17/G17)^(1/YEARFRAC(G$2,J$2,1))-1,"nmf") -> nmf | P17: {=++INDEX(FinInputs!$G113:$AH113,0,MATCH(P$2,FinInputs!$G$3:$AH$3,0))} -> 0 | Q17: {=++INDEX(FinInputs!$G113:$AH113,0,MATCH(Q$2,FinInputs!$G$3:$AH$3,0))} -> 0
C18: =++FinInputs!C211 -> % y/y | H18: =++IFERROR(H17/G17-1,0) -> 0 | I18: =++IFERROR(I17/H17-1,0) -> 0 | J18: {=++INDEX(FinInputs!$G211:$AH211,0,MATCH(J$2,FinInputs!$G$3:$AH$3,0))} -> 0 | K18: {=++INDEX(FinInputs!$G211:$AH211,0,MATCH(K$2,FinInputs!$G$3:$AH$3,0))} -> 0 | L18: =++IFERROR(L17/I17-1,0) -> 0 | P18: {=++INDEX(FinInputs!$G114:$AH114,0,MATCH(P$2,FinInputs!$G$3:$AH$3,0))} -> 0 | Q18: =++IFERROR(Q17/P17-1,0) -> 0
C20: =++FinInputs!C213 -> [COGS] | G20: {=++INDEX(FinInputs!$G213:$AH213,0,MATCH(G$2,FinInputs!$G$3:$AH$3,0))} -> 0 | H20: {=++INDEX(FinInputs!$G213:$AH213,0,MATCH(H$2,FinInputs!$G$3:$AH$3,0))} -> 0 | I20: {=++INDEX(FinInputs!$G213:$AH213,0,MATCH(I$2,FinInputs!$G$3:$AH$3,0))} -> 0 | J20: {=++INDEX(FinInputs!$G213:$AH213,0,MATCH(J$2,FinInputs!$G$3:$AH$3,0))} -> 0 | K20: {=++INDEX(FinInputs!$G213:$AH213,0,MATCH(K$2,FinInputs!$G$3:$AH$3,0))} -> 0 | L20: {=++INDEX(FinInputs!$G213:$AH213,0,MATCH(L$2,FinInputs!$G$3:$AH$3,0))} -> 0 | N20: =++IFERROR((J20/G20)^(1/YEARFRAC(G$2,J$2,1))-1,"nmf") -> nmf | P20: {=++INDEX(FinInputs!$G116:$AH116,0,MATCH(P$2,FinInputs!$G$3:$AH$3,0))} -> 0 | Q20: {=++INDEX(FinInputs!$G116:$AH116,0,MATCH(Q$2,FinInputs!$G$3:$AH$3,0))} -> 0
C21: =++FinInputs!C214 -> [COGS] | G21: {=++INDEX(FinInputs!$G214:$AH214,0,MATCH(G$2,FinInputs!$G$3:$AH$3,0))} -> 0 | H21: {=++INDEX(FinInputs!$G214:$AH214,0,MATCH(H$2,FinInputs!$G$3:$AH$3,0))} -> 0 | I21: {=++INDEX(FinInputs!$G214:$AH214,0,MATCH(I$2,FinInputs!$G$3:$AH$3,0))} -> 0 | J21: {=++INDEX(FinInputs!$G214:$AH214,0,MATCH(J$2,FinInputs!$G$3:$AH$3,0))} -> 0 | K21: {=++INDEX(FinInputs!$G214:$AH214,0,MATCH(K$2,FinInputs!$G$3:$AH$3,0))} -> 0 | L21: {=++INDEX(FinInputs!$G214:$AH214,0,MATCH(L$2,FinInputs!$G$3:$AH$3,0))} -> 0 | N21: =++IFERROR((J21/G21)^(1/YEARFRAC(G$2,J$2,1))-1,"nmf") -> nmf | P21: {=++INDEX(FinInputs!$G117:$AH117,0,MATCH(P$2,FinInputs!$G$3:$AH$3,0))} -> 0 | Q21: {=++INDEX(FinInputs!$G117:$AH117,0,MATCH(Q$2,FinInputs!$G$3:$AH$3,0))} -> 0
C22: =++FinInputs!C215 -> [COGS] | G22: {=++INDEX(FinInputs!$G215:$AH215,0,MATCH(G$2,FinInputs!$G$3:$AH$3,0))} -> 0 | H22: {=++INDEX(FinInputs!$G215:$AH215,0,MATCH(H$2,FinInputs!$G$3:$AH$3,0))} -> 0 | I22: {=++INDEX(FinInputs!$G215:$AH215,0,MATCH(I$2,FinInputs!$G$3:$AH$3,0))} -> 0 | J22: {=++INDEX(FinInputs!$G215:$AH215,0,MATCH(J$2,FinInputs!$G$3:$AH$3,0))} -> 0 | K22: {=++INDEX(FinInputs!$G215:$AH215,0,MATCH(K$2,FinInputs!$G$3:$AH$3,0))} -> 0 | L22: {=++INDEX(FinInputs!$G215:$AH215,0,MATCH(L$2,FinInputs!$G$3:$AH$3,0))} -> 0 | N22: =++IFERROR((J22/G22)^(1/YEARFRAC(G$2,J$2,1))-1,"nmf") -> nmf | P22: {=++INDEX(FinInputs!$G118:$AH118,0,MATCH(P$2,FinInputs!$G$3:$AH$3,0))} -> 0 | Q22: {=++INDEX(FinInputs!$G118:$AH118,0,MATCH(Q$2,FinInputs!$G$3:$AH$3,0))} -> 0
C23: =++FinInputs!C216 -> [COGS] | G23: {=++INDEX(FinInputs!$G216:$AH216,0,MATCH(G$2,FinInputs!$G$3:$AH$3,0))} -> 0 | H23: {=++INDEX(FinInputs!$G216:$AH216,0,MATCH(H$2,FinInputs!$G$3:$AH$3,0))} -> 0 | I23: {=++INDEX(FinInputs!$G216:$AH216,0,MATCH(I$2,FinInputs!$G$3:$AH$3,0))} -> 0 | J23: {=++INDEX(FinInputs!$G216:$AH216,0,MATCH(J$2,FinInputs!$G$3:$AH$3,0))} -> 0 | K23: {=++INDEX(FinInputs!$G216:$AH216,0,MATCH(K$2,FinInputs!$G$3:$AH$3,0))} -> 0 | L23: {=++INDEX(FinInputs!$G216:$AH216,0,MATCH(L$2,FinInputs!$G$3:$AH$3,0))} -> 0 | N23: =++IFERROR((J23/G23)^(1/YEARFRAC(G$2,J$2,1))-1,"nmf") -> nmf | P23: {=++INDEX(FinInputs!$G119:$AH119,0,MATCH(P$2,FinInputs!$G$3:$AH$3,0))} -> 0 | Q23: {=++INDEX(FinInputs!$G119:$AH119,0,MATCH(Q$2,FinInputs!$G$3:$AH$3,0))} -> 0
C24: =++FinInputs!C217 -> [COGS] | G24: {=++INDEX(FinInputs!$G217:$AH217,0,MATCH(G$2,FinInputs!$G$3:$AH$3,0))} -> 0 | H24: {=++INDEX(FinInputs!$G217:$AH217,0,MATCH(H$2,FinInputs!$G$3:$AH$3,0))} -> 0 | I24: {=++INDEX(FinInputs!$G217:$AH217,0,MATCH(I$2,FinInputs!$G$3:$AH$3,0))} -> 0 | J24: {=++INDEX(FinInputs!$G217:$AH217,0,MATCH(J$2,FinInputs!$G$3:$AH$3,0))} -> 0 | K24: {=++INDEX(FinInputs!$G217:$AH217,0,MATCH(K$2,FinInputs!$G$3:$AH$3,0))} -> 0 | L24: {=++INDEX(FinInputs!$G217:$AH217,0,MATCH(L$2,FinInputs!$G$3:$AH$3,0))} -> 0 | N24: =++IFERROR((J24/G24)^(1/YEARFRAC(G$2,J$2,1))-1,"nmf") -> nmf | P24: {=++INDEX(FinInputs!$G120:$AH120,0,MATCH(P$2,FinInputs!$G$3:$AH$3,0))} -> 0 | Q24: {=++INDEX(FinInputs!$G120:$AH120,0,MATCH(Q$2,FinInputs!$G$3:$AH$3,0))} -> 0
C25: =++FinInputs!C218 -> Other COGS | G25: =++(G17-G26)-SUM(G20:G24) -> 0 | H25: =++(H17-H26)-SUM(H20:H24) -> 0 | I25: =++(I17-I26)-SUM(I20:I24) -> 0 | J25: =++(J17-J26)-SUM(J20:J24) -> 0 | K25: =++(K17-K26)-SUM(K20:K24) -> 0 | L25: =++(L17-L26)-SUM(L20:L24) -> 0 | N25: =++IFERROR((J25/G25)^(1/YEARFRAC(G$2,J$2,1))-1,"nmf") -> nmf | P25: =++(P17-P26)-SUM(P20:P24) -> 0 | Q25: =++(Q17-Q26)-SUM(Q20:Q24) -> 0
B26: x | C26: =++FinInputs!C219 -> Gross Profit | G26: {=++INDEX(FinInputs!$G219:$AH219,0,MATCH(G$2,FinInputs!$G$3:$AH$3,0))} -> 0 | H26: {=++INDEX(FinInputs!$G219:$AH219,0,MATCH(H$2,FinInputs!$G$3:$AH$3,0))} -> 0 | I26: {=++INDEX(FinInputs!$G219:$AH219,0,MATCH(I$2,FinInputs!$G$3:$AH$3,0))} -> 0 | J26: {=++INDEX(FinInputs!$G219:$AH219,0,MATCH(J$2,FinInputs!$G$3:$AH$3,0))} -> 0 | K26: {=++INDEX(FinInputs!$G219:$AH219,0,MATCH(K$2,FinInputs!$G$3:$AH$3,0))} -> 0 | L26: {=++INDEX(FinInputs!$G219:$AH219,0,MATCH(L$2,FinInputs!$G$3:$AH$3,0))} -> 0 | N26: =++IFERROR((J26/G26)^(1/YEARFRAC(G$2,J$2,1))-1,"nmf") -> nmf | P26: {=++INDEX(FinInputs!$G122:$AH122,0,MATCH(P$2,FinInputs!$G$3:$AH$3,0))} -> 0 | Q26: {=++INDEX(FinInputs!$G122:$AH122,0,MATCH(Q$2,FinInputs!$G$3:$AH$3,0))} -> 0
C27: =++FinInputs!C220 -> % margin | G27: =++IFERROR(G26/G$17,0) -> 0 | H27: =++IFERROR(H26/H$17,0) -> 0 | I27: =++IFERROR(I26/I$17,0) -> 0 | J27: =++IFERROR(J26/J$17,0) -> 0 | K27: =++IFERROR(K26/K$17,0) -> 0 | L27: =++IFERROR(L26/L$17,0) -> 0 | P27: =++IFERROR(P26/P$17,0) -> 0 | Q27: =++IFERROR(Q26/Q$17,0) -> 0
C28: =++FinInputs!C221 -> % y/y | H28: =++IFERROR(H26/G26-1,0) -> 0 | I28: =++IFERROR(I26/H26-1,0) -> 0 | J28: {=++INDEX(FinInputs!$G221:$AH221,0,MATCH(J$2,FinInputs!$G$3:$AH$3,0))} -> 0 | K28: {=++INDEX(FinInputs!$G221:$AH221,0,MATCH(K$2,FinInputs!$G$3:$AH$3,0))} -> 0 | L28: =++IFERROR(L26/I26-1,0) -> 0 | P28: {=++INDEX(FinInputs!$G124:$AH124,0,MATCH(P$2,FinInputs!$G$3:$AH$3,0))} -> 0 | Q28: =++IFERROR(Q26/P26-1,0) -> 0
C30: =++FinInputs!C223 -> [Operating Exepnse] | G30: {=++INDEX(FinInputs!$G223:$AH223,0,MATCH(G$2,FinInputs!$G$3:$AH$3,0))} -> 0 | H30: {=++INDEX(FinInputs!$G223:$AH223,0,MATCH(H$2,FinInputs!$G$3:$AH$3,0))} -> 0 | I30: {=++INDEX(FinInputs!$G223:$AH223,0,MATCH(I$2,FinInputs!$G$3:$AH$3,0))} -> 0 | J30: {=++INDEX(FinInputs!$G223:$AH223,0,MATCH(J$2,FinInputs!$G$3:$AH$3,0))} -> 0 | K30: {=++INDEX(FinInputs!$G223:$AH223,0,MATCH(K$2,FinInputs!$G$3:$AH$3,0))} -> 0 | L30: {=++INDEX(FinInputs!$G223:$AH223,0,MATCH(L$2,FinInputs!$G$3:$AH$3,0))} -> 0 | N30: =++IFERROR((J30/G30)^(1/YEARFRAC(G$2,J$2,1))-1,"nmf") -> nmf | P30: {=++INDEX(FinInputs!$G126:$AH126,0,MATCH(P$2,FinInputs!$G$3:$AH$3,0))} -> 0 | Q30: {=++INDEX(FinInputs!$G126:$AH126,0,MATCH(Q$2,FinInputs!$G$3:$AH$3,0))} -> 0
C31: =++FinInputs!C224 -> [Operating Exepnse] | G31: {=++INDEX(FinInputs!$G224:$AH224,0,MATCH(G$2,FinInputs!$G$3:$AH$3,0))} -> 0 | H31: {=++INDEX(FinInputs!$G224:$AH224,0,MATCH(H$2,FinInputs!$G$3:$AH$3,0))} -> 0 | I31: {=++INDEX(FinInputs!$G224:$AH224,0,MATCH(I$2,FinInputs!$G$3:$AH$3,0))} -> 0 | J31: {=++INDEX(FinInputs!$G224:$AH224,0,MATCH(J$2,FinInputs!$G$3:$AH$3,0))} -> 0 | K31: {=++INDEX(FinInputs!$G224:$AH224,0,MATCH(K$2,FinInputs!$G$3:$AH$3,0))} -> 0 | L31: {=++INDEX(FinInputs!$G224:$AH224,0,MATCH(L$2,FinInputs!$G$3:$AH$3,0))} -> 0 | N31: =++IFERROR((J31/G31)^(1/YEARFRAC(G$2,J$2,1))-1,"nmf") -> nmf | P31: {=++INDEX(FinInputs!$G127:$AH127,0,MATCH(P$2,FinInputs!$G$3:$AH$3,0))} -> 0 | Q31: {=++INDEX(FinInputs!$G127:$AH127,0,MATCH(Q$2,FinInputs!$G$3:$AH$3,0))} -> 0
C32: =++FinInputs!C225 -> [Operating Exepnse] | G32: {=++INDEX(FinInputs!$G225:$AH225,0,MATCH(G$2,FinInputs!$G$3:$AH$3,0))} -> 0 | H32: {=++INDEX(FinInputs!$G225:$AH225,0,MATCH(H$2,FinInputs!$G$3:$AH$3,0))} -> 0 | I32: {=++INDEX(FinInputs!$G225:$AH225,0,MATCH(I$2,FinInputs!$G$3:$AH$3,0))} -> 0 | J32: {=++INDEX(FinInputs!$G225:$AH225,0,MATCH(J$2,FinInputs!$G$3:$AH$3,0))} -> 0 | K32: {=++INDEX(FinInputs!$G225:$AH225,0,MATCH(K$2,FinInputs!$G$3:$AH$3,0))} -> 0 | L32: {=++INDEX(FinInputs!$G225:$AH225,0,MATCH(L$2,FinInputs!$G$3:$AH$3,0))} -> 0 | N32: =++IFERROR((J32/G32)^(1/YEARFRAC(G$2,J$2,1))-1,"nmf") -> nmf | P32: {=++INDEX(FinInputs!$G128:$AH128,0,MATCH(P$2,FinInputs!$G$3:$AH$3,0))} -> 0 | Q32: {=++INDEX(FinInputs!$G128:$AH128,0,MATCH(Q$2,FinInputs!$G$3:$AH$3,0))} -> 0
C33: =++FinInputs!C226 -> [Operating Exepnse] | G33: {=++INDEX(FinInputs!$G226:$AH226,0,MATCH(G$2,FinInputs!$G$3:$AH$3,0))} -> 0 | H33: {=++INDEX(FinInputs!$G226:$AH226,0,MATCH(H$2,FinInputs!$G$3:$AH$3,0))} -> 0 | I33: {=++INDEX(FinInputs!$G226:$AH226,0,MATCH(I$2,FinInputs!$G$3:$AH$3,0))} -> 0 | J33: {=++INDEX(FinInputs!$G226:$AH226,0,MATCH(J$2,FinInputs!$G$3:$AH$3,0))} -> 0 | K33: {=++INDEX(FinInputs!$G226:$AH226,0,MATCH(K$2,FinInputs!$G$3:$AH$3,0))} -> 0 | L33: {=++INDEX(FinInputs!$G226:$AH226,0,MATCH(L$2,FinInputs!$G$3:$AH$3,0))} -> 0 | N33: =++IFERROR((J33/G33)^(1/YEARFRAC(G$2,J$2,1))-1,"nmf") -> nmf | P33: {=++INDEX(FinInputs!$G129:$AH129,0,MATCH(P$2,FinInputs!$G$3:$AH$3,0))} -> 0 | Q33: {=++INDEX(FinInputs!$G129:$AH129,0,MATCH(Q$2,FinInputs!$G$3:$AH$3,0))} -> 0
C34: =++FinInputs!C227 -> [Operating Exepnse] | G34: {=++INDEX(FinInputs!$G227:$AH227,0,MATCH(G$2,FinInputs!$G$3:$AH$3,0))} -> 0 | H34: {=++INDEX(FinInputs!$G227:$AH227,0,MATCH(H$2,FinInputs!$G$3:$AH$3,0))} -> 0 | I34: {=++INDEX(FinInputs!$G227:$AH227,0,MATCH(I$2,FinInputs!$G$3:$AH$3,0))} -> 0 | J34: {=++INDEX(FinInputs!$G227:$AH227,0,MATCH(J$2,FinInputs!$G$3:$AH$3,0))} -> 0 | K34: {=++INDEX(FinInputs!$G227:$AH227,0,MATCH(K$2,FinInputs!$G$3:$AH$3,0))} -> 0 | L34: {=++INDEX(FinInputs!$G227:$AH227,0,MATCH(L$2,FinInputs!$G$3:$AH$3,0))} -> 0 | N34: =++IFERROR((J34/G34)^(1/YEARFRAC(G$2,J$2,1))-1,"nmf") -> nmf | P34: {=++INDEX(FinInputs!$G130:$AH130,0,MATCH(P$2,FinInputs!$G$3:$AH$3,0))} -> 0 | Q34: {=++INDEX(FinInputs!$G130:$AH130,0,MATCH(Q$2,FinInputs!$G$3:$AH$3,0))} -> 0
C35: Other Expense (Income) | G35: =++(G26-G36)-SUM(G30:G34) -> 0 | H35: =++(H26-H36)-SUM(H30:H34) -> 0 | I35: =++(I26-I36)-SUM(I30:I34) -> 0 | J35: =++(J26-J36)-SUM(J30:J34) -> 0 | K35: =++(K26-K36)-SUM(K30:K34) -> 0 | L35: =++(L26-L36)-SUM(L30:L34) -> 0 | N35: =++IFERROR((J35/G35)^(1/YEARFRAC(G$2,J$2,1))-1,"nmf") -> nmf | P35: =++(P26-P36)-SUM(P30:P34) -> 0 | Q35: =++(Q26-Q36)-SUM(Q30:Q34) -> 0
C36: =++FinInputs!C253 -> EBITDA (Reported) | G36: {=++INDEX(FinInputs!$G253:$AH253,0,MATCH(G$2,FinInputs!$G$3:$AH$3,0))} -> 0 | H36: {=++INDEX(FinInputs!$G253:$AH253,0,MATCH(H$2,FinInputs!$G$3:$AH$3,0))} -> 0 | I36: {=++INDEX(FinInputs!$G253:$AH253,0,MATCH(I$2,FinInputs!$G$3:$AH$3,0))} -> 0 | J36: {=++INDEX(FinInputs!$G253:$AH253,0,MATCH(J$2,FinInputs!$G$3:$AH$3,0))} -> 0 | K36: {=++INDEX(FinInputs!$G253:$AH253,0,MATCH(K$2,FinInputs!$G$3:$AH$3,0))} -> 0 | L36: {=++INDEX(FinInputs!$G253:$AH253,0,MATCH(L$2,FinInputs!$G$3:$AH$3,0))} -> 0 | N36: =++IFERROR((J36/G36)^(1/YEARFRAC(G$2,J$2,1))-1,"nmf") -> nmf | P36: {=++INDEX(FinInputs!$G156:$AH156,0,MATCH(P$2,FinInputs!$G$3:$AH$3,0))} -> 0 | Q36: {=++INDEX(FinInputs!$G156:$AH156,0,MATCH(Q$2,FinInputs!$G$3:$AH$3,0))} -> 0
C37: =++FinInputs!C254 -> % margin | G37: =++IFERROR(G36/G$17,0) -> 0 | H37: =++IFERROR(H36/H$17,0) -> 0 | I37: =++IFERROR(I36/I$17,0) -> 0 | J37: =++IFERROR(J36/J$17,0) -> 0 | K37: =++IFERROR(K36/K$17,0) -> 0 | L37: =++IFERROR(L36/L$17,0) -> 0 | P37: =++IFERROR(P36/P$17,0) -> 0 | Q37: =++IFERROR(Q36/Q$17,0) -> 0
C38: =++FinInputs!C255 -> % y/y | H38: =++IFERROR(H36/G36-1,0) -> 0 | I38: =++IFERROR(I36/H36-1,0) -> 0 | J38: {=++INDEX(FinInputs!$G255:$AH255,0,MATCH(J$2,FinInputs!$G$3:$AH$3,0))} -> 0 | K38: {=++INDEX(FinInputs!$G255:$AH255,0,MATCH(K$2,FinInputs!$G$3:$AH$3,0))} -> 0 | L38: =++IFERROR(L36/I36-1,0) -> 0 | P38: {=++INDEX(FinInputs!$G158:$AH158,0,MATCH(P$2,FinInputs!$G$3:$AH$3,0))} -> 0 | Q38: =++IFERROR(Q36/P36-1,0) -> 0
C40: ( + ) Adjustments | G40: =++G41-G36 -> 0 | H40: =++H41-H36 -> 0 | I40: =++I41-I36 -> 0 | J40: =++J41-J36 -> 0 | K40: =++K41-K36 -> 0 | L40: =++L41-L36 -> 0 | N40: =++IFERROR((J40/G40)^(1/YEARFRAC(G$2,J$2,1))-1,"nmf") -> nmf | P40: =++P41-P36 -> 0 | Q40: =++Q41-Q36 -> 0
B41: x | C41: =++FinInputs!C281 -> CA EBITDA | G41: {=++INDEX(FinInputs!$G281:$AH281,0,MATCH(G$2,FinInputs!$G$3:$AH$3,0))} -> 0 | H41: {=++INDEX(FinInputs!$G281:$AH281,0,MATCH(H$2,FinInputs!$G$3:$AH$3,0))} -> 0 | I41: {=++INDEX(FinInputs!$G281:$AH281,0,MATCH(I$2,FinInputs!$G$3:$AH$3,0))} -> 0 | J41: {=++INDEX(FinInputs!$G281:$AH281,0,MATCH(J$2,FinInputs!$G$3:$AH$3,0))} -> 0 | K41: {=++INDEX(FinInputs!$G281:$AH281,0,MATCH(K$2,FinInputs!$G$3:$AH$3,0))} -> 0 | L41: {=++INDEX(FinInputs!$G281:$AH281,0,MATCH(L$2,FinInputs!$G$3:$AH$3,0))} -> 0 | N41: =++IFERROR((J41/G41)^(1/YEARFRAC(G$2,J$2,1))-1,"nmf") -> nmf | P41: {=++INDEX(FinInputs!$G184:$AH184,0,MATCH(P$2,FinInputs!$G$3:$AH$3,0))} -> 0 | Q41: {=++INDEX(FinInputs!$G184:$AH184,0,MATCH(Q$2,FinInputs!$G$3:$AH$3,0))} -> 0
C42: =++FinInputs!C282 -> % margin | G42: =++IFERROR(G41/G$17,0) -> 0 | H42: =++IFERROR(H41/H$17,0) -> 0 | I42: =++IFERROR(I41/I$17,0) -> 0 | J42: =++IFERROR(J41/J$17,0) -> 0 | K42: =++IFERROR(K41/K$17,0) -> 0 | L42: =++IFERROR(L41/L$17,0) -> 0 | P42: =++IFERROR(P41/P$17,0) -> 0 | Q42: =++IFERROR(Q41/Q$17,0) -> 0
C43: =++FinInputs!C283 -> % y/y | H43: =++IFERROR(H41/G41-1,0) -> 0 | I43: =++IFERROR(I41/H41-1,0) -> 0 | J43: {=++INDEX(FinInputs!$G283:$AH283,0,MATCH(J$2,FinInputs!$G$3:$AH$3,0))} -> 0 | K43: {=++INDEX(FinInputs!$G283:$AH283,0,MATCH(K$2,FinInputs!$G$3:$AH$3,0))} -> 0 | L43: =++IFERROR(L41/I41-1,0) -> 0 | P43: {=++INDEX(FinInputs!$G186:$AH186,0,MATCH(P$2,FinInputs!$G$3:$AH$3,0))} -> 0 | Q43: =++IFERROR(Q41/P41-1,0) -> 0
C45: =++FinInputs!C285 -> Maintenance Capex | G45: {=++INDEX(FinInputs!$G285:$AH285,0,MATCH(G$2,FinInputs!$G$3:$AH$3,0))} -> 0 | H45: {=++INDEX(FinInputs!$G285:$AH285,0,MATCH(H$2,FinInputs!$G$3:$AH$3,0))} -> 0 | I45: {=++INDEX(FinInputs!$G285:$AH285,0,MATCH(I$2,FinInputs!$G$3:$AH$3,0))} -> 0 | J45: {=++INDEX(FinInputs!$G285:$AH285,0,MATCH(J$2,FinInputs!$G$3:$AH$3,0))} -> 0 | K45: {=++INDEX(FinInputs!$G285:$AH285,0,MATCH(K$2,FinInputs!$G$3:$AH$3,0))} -> 0 | L45: {=++INDEX(FinInputs!$G285:$AH285,0,MATCH(L$2,FinInputs!$G$3:$AH$3,0))} -> 0 | N45: =++IFERROR((J45/G45)^(1/YEARFRAC(G$2,J$2,1))-1,"nmf") -> nmf | P45: {=++INDEX(FinInputs!$G188:$AH188,0,MATCH(P$2,FinInputs!$G$3:$AH$3,0))} -> 0 | Q45: {=++INDEX(FinInputs!$G188:$AH188,0,MATCH(Q$2,FinInputs!$G$3:$AH$3,0))} -> 0
C46: =++FinInputs!C286 -> Growth Capex | G46: {=++INDEX(FinInputs!$G286:$AH286,0,MATCH(G$2,FinInputs!$G$3:$AH$3,0))} -> 0 | H46: {=++INDEX(FinInputs!$G286:$AH286,0,MATCH(H$2,FinInputs!$G$3:$AH$3,0))} -> 0 | I46: {=++INDEX(FinInputs!$G286:$AH286,0,MATCH(I$2,FinInputs!$G$3:$AH$3,0))} -> 0 | J46: {=++INDEX(FinInputs!$G286:$AH286,0,MATCH(J$2,FinInputs!$G$3:$AH$3,0))} -> 0 | K46: {=++INDEX(FinInputs!$G286:$AH286,0,MATCH(K$2,FinInputs!$G$3:$AH$3,0))} -> 0 | L46: {=++INDEX(FinInputs!$G286:$AH286,0,MATCH(L$2,FinInputs!$G$3:$AH$3,0))} -> 0 | N46: =++IFERROR((J46/G46)^(1/YEARFRAC(G$2,J$2,1))-1,"nmf") -> nmf | P46: {=++INDEX(FinInputs!$G189:$AH189,0,MATCH(P$2,FinInputs!$G$3:$AH$3,0))} -> 0 | Q46: {=++INDEX(FinInputs!$G189:$AH189,0,MATCH(Q$2,FinInputs!$G$3:$AH$3,0))} -> 0
C47: =++FinInputs!C287 -> Other Capex | G47: {=++INDEX(FinInputs!$G287:$AH287,0,MATCH(G$2,FinInputs!$G$3:$AH$3,0))} -> 0 | H47: {=++INDEX(FinInputs!$G287:$AH287,0,MATCH(H$2,FinInputs!$G$3:$AH$3,0))} -> 0 | I47: {=++INDEX(FinInputs!$G287:$AH287,0,MATCH(I$2,FinInputs!$G$3:$AH$3,0))} -> 0 | J47: {=++INDEX(FinInputs!$G287:$AH287,0,MATCH(J$2,FinInputs!$G$3:$AH$3,0))} -> 0 | K47: {=++INDEX(FinInputs!$G287:$AH287,0,MATCH(K$2,FinInputs!$G$3:$AH$3,0))} -> 0 | L47: {=++INDEX(FinInputs!$G287:$AH287,0,MATCH(L$2,FinInputs!$G$3:$AH$3,0))} -> 0 | N47: =++IFERROR((J47/G47)^(1/YEARFRAC(G$2,J$2,1))-1,"nmf") -> nmf | P47: {=++INDEX(FinInputs!$G190:$AH190,0,MATCH(P$2,FinInputs!$G$3:$AH$3,0))} -> 0 | Q47: {=++INDEX(FinInputs!$G190:$AH190,0,MATCH(Q$2,FinInputs!$G$3:$AH$3,0))} -> 0
B48: x | C48: =++FinInputs!C288 -> Capital Expenditures | G48: =++SUM(G45:G47) -> 0 | H48: =++SUM(H45:H47) -> 0 | I48: =++SUM(I45:I47) -> 0 | J48: =++SUM(J45:J47) -> 0 | K48: =++SUM(K45:K47) -> 0 | L48: =++SUM(L45:L47) -> 0 | N48: =++IFERROR((J48/G48)^(1/YEARFRAC(G$2,J$2,1))-1,"nmf") -> nmf | P48: =++SUM(P45:P47) -> 0 | Q48: =++SUM(Q45:Q47) -> 0
...

Sheet HistFin Charts
C1: =++CoName -> [Company Name] ([Sponsor Name / Non-Sponsored])
C2: Historical Financial Charts
C3: =++TEXT(TODAY(),"MMMM D, YYYY") -> April 21, 2026
A5: x | B5: x | C5: =++C2 -> Historical Financial Charts
A7: x | B7: x | C7: TTM Revenue (% y/y) | K7: TTM Gross Profit (% margin)
C9: USD in millions | K9: USD in millions
B27: x | C27: TTM CA EBITDA (% margin) | K27: TTM Capital Expenditures (% revenue)
C29: USD in millions | K29: USD in millions
A48: x | B48: x | T48: Date | U48: Revenue | V48: % y/y | W48: Gross Profit | X48: % margin | Y48: CA EBITDA | Z48: % margin | AA48: {=++TRANSPOSE(FinInputs!C285:C287)} -> Maintenance Capex | AB48: Growth Capex | AC48: Other Capex | AD48: Capex | AE48: % revenue
T49: =++EOMONTH(LastFYE,-24) -> 44926 | U49: {=++INDEX(FinInputs!$G$210:$AH$210,0,MATCH($T49,FinInputs!$G$3:$AH$3,0))/1000} -> 0 | W49: {=++INDEX(FinInputs!$G$219:$AH$219,0,MATCH($T49,FinInputs!$G$3:$AH$3,0))/1000} -> 0 | X49: =++IFERROR(W49/$U49,0) -> 0 | Y49: {=++INDEX(FinInputs!$G$281:$AH$281,0,MATCH($T49,FinInputs!$G$3:$AH$3,0))/1000} -> 0 | Z49: =++IFERROR(Y49/$U49,0) -> 0 | AA49: 100 | AB49: 100 | AC49: 50 | AD49: =++SUM(AA49:AC49) -> 250 | AE49: =++IFERROR(AD49/$U49,0) -> 0
T50: =++EOMONTH(T49,3) -> 45016 | U50: {=++INDEX(FinInputs!$G$210:$AH$210,0,MATCH($T50,FinInputs!$G$3:$AH$3,0))/1000} -> 0 | W50: {=++INDEX(FinInputs!$G$219:$AH$219,0,MATCH($T50,FinInputs!$G$3:$AH$3,0))/1000} -> 0 | X50: =++IFERROR(W50/$U50,0) -> 0 | Y50: {=++INDEX(FinInputs!$G$281:$AH$281,0,MATCH($T50,FinInputs!$G$3:$AH$3,0))/1000} -> 0 | Z50: =++IFERROR(Y50/$U50,0) -> 0 | AA50: 100 | AB50: 100 | AC50: 50 | AD50: =++SUM(AA50:AC50) -> 250 | AE50: =++IFERROR(AD50/$U50,0) -> 0
T51: =++EOMONTH(T50,3) -> 45107 | U51: {=++INDEX(FinInputs!$G$210:$AH$210,0,MATCH($T51,FinInputs!$G$3:$AH$3,0))/1000} -> 0 | W51: {=++INDEX(FinInputs!$G$219:$AH$219,0,MATCH($T51,FinInputs!$G$3:$AH$3,0))/1000} -> 0 | X51: =++IFERROR(W51/$U51,0) -> 0 | Y51: {=++INDEX(FinInputs!$G$281:$AH$281,0,MATCH($T51,FinInputs!$G$3:$AH$3,0))/1000} -> 0 | Z51: =++IFERROR(Y51/$U51,0) -> 0 | AA51: 100 | AB51: 100 | AC51: 50 | AD51: =++SUM(AA51:AC51) -> 250 | AE51: =++IFERROR(AD51/$U51,0) -> 0
T52: =++EOMONTH(T51,3) -> 45199 | U52: {=++INDEX(FinInputs!$G$210:$AH$210,0,MATCH($T52,FinInputs!$G$3:$AH$3,0))/1000} -> 0 | W52: {=++INDEX(FinInputs!$G$219:$AH$219,0,MATCH($T52,FinInputs!$G$3:$AH$3,0))/1000} -> 0 | X52: =++IFERROR(W52/$U52,0) -> 0 | Y52: {=++INDEX(FinInputs!$G$281:$AH$281,0,MATCH($T52,FinInputs!$G$3:$AH$3,0))/1000} -> 0 | Z52: =++IFERROR(Y52/$U52,0) -> 0 | AA52: 100 | AB52: 100 | AC52: 50 | AD52: =++SUM(AA52:AC52) -> 250 | AE52: =++IFERROR(AD52/$U52,0) -> 0
T53: =++EOMONTH(T52,3) -> 45291 | U53: {=++INDEX(FinInputs!$G$210:$AH$210,0,MATCH($T53,FinInputs!$G$3:$AH$3,0))/1000} -> 0 | V53: {=++INDEX(FinInputs!$G$211:$AH$211,0,MATCH($T53,FinInputs!$G$3:$AH$3,0))} -> 0 | W53: {=++INDEX(FinInputs!$G$219:$AH$219,0,MATCH($T53,FinInputs!$G$3:$AH$3,0))/1000} -> 0 | X53: =++IFERROR(W53/$U53,0) -> 0 | Y53: {=++INDEX(FinInputs!$G$281:$AH$281,0,MATCH($T53,FinInputs!$G$3:$AH$3,0))/1000} -> 0 | Z53: =++IFERROR(Y53/$U53,0) -> 0 | AA53: 100 | AB53: 100 | AC53: 50 | AD53: =++SUM(AA53:AC53) -> 250 | AE53: =++IFERROR(AD53/$U53,0) -> 0
T54: =++EOMONTH(T53,3) -> 45382 | U54: {=++INDEX(FinInputs!$G$210:$AH$210,0,MATCH($T54,FinInputs!$G$3:$AH$3,0))/1000} -> 0 | V54: {=++INDEX(FinInputs!$G$211:$AH$211,0,MATCH($T54,FinInputs!$G$3:$AH$3,0))} -> 0 | W54: {=++INDEX(FinInputs!$G$219:$AH$219,0,MATCH($T54,FinInputs!$G$3:$AH$3,0))/1000} -> 0 | X54: =++IFERROR(W54/$U54,0) -> 0 | Y54: {=++INDEX(FinInputs!$G$281:$AH$281,0,MATCH($T54,FinInputs!$G$3:$AH$3,0))/1000} -> 0 | Z54: =++IFERROR(Y54/$U54,0) -> 0 | AA54: 100 | AB54: 100 | AC54: 50 | AD54: =++SUM(AA54:AC54) -> 250 | AE54: =++IFERROR(AD54/$U54,0) -> 0
T55: =++EOMONTH(T54,3) -> 45473 | U55: {=++INDEX(FinInputs!$G$210:$AH$210,0,MATCH($T55,FinInputs!$G$3:$AH$3,0))/1000} -> 0 | V55: {=++INDEX(FinInputs!$G$211:$AH$211,0,MATCH($T55,FinInputs!$G$3:$AH$3,0))} -> 0 | W55: {=++INDEX(FinInputs!$G$219:$AH$219,0,MATCH($T55,FinInputs!$G$3:$AH$3,0))/1000} -> 0 | X55: =++IFERROR(W55/$U55,0) -> 0 | Y55: {=++INDEX(FinInputs!$G$281:$AH$281,0,MATCH($T55,FinInputs!$G$3:$AH$3,0))/1000} -> 0 | Z55: =++IFERROR(Y55/$U55,0) -> 0 | AA55: 100 | AB55: 100 | AC55: 50 | AD55: =++SUM(AA55:AC55) -> 250 | AE55: =++IFERROR(AD55/$U55,0) -> 0
T56: =++EOMONTH(T55,3) -> 45565 | U56: {=++INDEX(FinInputs!$G$210:$AH$210,0,MATCH($T56,FinInputs!$G$3:$AH$3,0))/1000} -> 0 | V56: {=++INDEX(FinInputs!$G$211:$AH$211,0,MATCH($T56,FinInputs!$G$3:$AH$3,0))} -> 0 | W56: {=++INDEX(FinInputs!$G$219:$AH$219,0,MATCH($T56,FinInputs!$G$3:$AH$3,0))/1000} -> 0 | X56: =++IFERROR(W56/$U56,0) -> 0 | Y56: {=++INDEX(FinInputs!$G$281:$AH$281,0,MATCH($T56,FinInputs!$G$3:$AH$3,0))/1000} -> 0 | Z56: =++IFERROR(Y56/$U56,0) -> 0 | AA56: 100 | AB56: 100 | AC56: 50 | AD56: =++SUM(AA56:AC56) -> 250 | AE56: =++IFERROR(AD56/$U56,0) -> 0
T57: =++EOMONTH(T56,3) -> 45657 | U57: {=++INDEX(FinInputs!$G$210:$AH$210,0,MATCH($T57,FinInputs!$G$3:$AH$3,0))/1000} -> 0 | V57: {=++INDEX(FinInputs!$G$211:$AH$211,0,MATCH($T57,FinInputs!$G$3:$AH$3,0))} -> 0 | W57: {=++INDEX(FinInputs!$G$219:$AH$219,0,MATCH($T57,FinInputs!$G$3:$AH$3,0))/1000} -> 0 | X57: =++IFERROR(W57/$U57,0) -> 0 | Y57: {=++INDEX(FinInputs!$G$281:$AH$281,0,MATCH($T57,FinInputs!$G$3:$AH$3,0))/1000} -> 0 | Z57: =++IFERROR(Y57/$U57,0) -> 0 | AA57: 100 | AB57: 100 | AC57: 50 | AD57: =++SUM(AA57:AC57) -> 250 | AE57: =++IFERROR(AD57/$U57,0) -> 0
T58: =++EOMONTH(T57,3) -> 45747 | U58: {=++INDEX(FinInputs!$G$210:$AH$210,0,MATCH($T58,FinInputs!$G$3:$AH$3,0))/1000} -> 0 | V58: {=++INDEX(FinInputs!$G$211:$AH$211,0,MATCH($T58,FinInputs!$G$3:$AH$3,0))} -> 0 | W58: {=++INDEX(FinInputs!$G$219:$AH$219,0,MATCH($T58,FinInputs!$G$3:$AH$3,0))/1000} -> 0 | X58: =++IFERROR(W58/$U58,0) -> 0 | Y58: {=++INDEX(FinInputs!$G$281:$AH$281,0,MATCH($T58,FinInputs!$G$3:$AH$3,0))/1000} -> 0 | Z58: =++IFERROR(Y58/$U58,0) -> 0 | AA58: 100 | AB58: 100 | AC58: 50 | AD58: =++SUM(AA58:AC58) -> 250 | AE58: =++IFERROR(AD58/$U58,0) -> 0
T59: =++EOMONTH(T58,3) -> 45838 | U59: {=++INDEX(FinInputs!$G$210:$AH$210,0,MATCH($T59,FinInputs!$G$3:$AH$3,0))/1000} -> 0 | V59: {=++INDEX(FinInputs!$G$211:$AH$211,0,MATCH($T59,FinInputs!$G$3:$AH$3,0))} -> 0 | W59: {=++INDEX(FinInputs!$G$219:$AH$219,0,MATCH($T59,FinInputs!$G$3:$AH$3,0))/1000} -> 0 | X59: =++IFERROR(W59/$U59,0) -> 0 | Y59: {=++INDEX(FinInputs!$G$281:$AH$281,0,MATCH($T59,FinInputs!$G$3:$AH$3,0))/1000} -> 0 | Z59: =++IFERROR(Y59/$U59,0) -> 0 | AA59: 100 | AB59: 100 | AC59: 50 | AD59: =++SUM(AA59:AC59) -> 250 | AE59: =++IFERROR(AD59/$U59,0) -> 0
T60: =++EOMONTH(T59,3) -> 45930 | U60: {=++INDEX(FinInputs!$G$210:$AH$210,0,MATCH($T60,FinInputs!$G$3:$AH$3,0))/1000} -> 0 | V60: {=++INDEX(FinInputs!$G$211:$AH$211,0,MATCH($T60,FinInputs!$G$3:$AH$3,0))} -> 0 | W60: {=++INDEX(FinInputs!$G$219:$AH$219,0,MATCH($T60,FinInputs!$G$3:$AH$3,0))/1000} -> 0 | X60: =++IFERROR(W60/$U60,0) -> 0 | Y60: {=++INDEX(FinInputs!$G$281:$AH$281,0,MATCH($T60,FinInputs!$G$3:$AH$3,0))/1000} -> 0 | Z60: =++IFERROR(Y60/$U60,0) -> 0 | AA60: 100 | AB60: 100 | AC60: 50 | AD60: =++SUM(AA60:AC60) -> 250 | AE60: =++IFERROR(AD60/$U60,0) -> 0
T61: =++EOMONTH(T60,3) -> 46022 | U61: {=++INDEX(FinInputs!$G$210:$AH$210,0,MATCH($T61,FinInputs!$G$3:$AH$3,0))/1000} -> 0 | V61: {=++INDEX(FinInputs!$G$211:$AH$211,0,MATCH($T61,FinInputs!$G$3:$AH$3,0))} -> 0 | W61: {=++INDEX(FinInputs!$G$219:$AH$219,0,MATCH($T61,FinInputs!$G$3:$AH$3,0))/1000} -> 0 | X61: =++IFERROR(W61/$U61,0) -> 0 | Y61: {=++INDEX(FinInputs!$G$281:$AH$281,0,MATCH($T61,FinInputs!$G$3:$AH$3,0))/1000} -> 0 | Z61: =++IFERROR(Y61/$U61,0) -> 0 | AA61: 100 | AB61: 100 | AC61: 50 | AD61: =++SUM(AA61:AC61) -> 250 | AE61: =++IFERROR(AD61/$U61,0) -> 0

Sheet EBITDA
C1: =++CoName -> [Company Name] ([Sponsor Name / Non-Sponsored])
C2: EBITDA Adjustment Detail | H2: =++EOMONTH(I2,-12) -> 44926 | I2: =++EOMONTH(J2,-12) -> 45291 | J2: =++LastFYE -> 45657 | K2: =+LastActDate -> 45930 | L2: =++LTMDate -> 45930
C3: =++TEXT(TODAY(),"MMMM D, YYYY") -> April 21, 2026
A5: x | B5: x | C5: =++C2 -> EBITDA Adjustment Detail
C7: USD in 000s, except where noted | H7: Trailing Twelve Month Period Ending, | N7: % Total
C9: =++"FYE "&TEXT(LastFYE,"MMMM DD")&"st" -> FYE December 31st | H9: =++"FY'"&RIGHT(YEAR(H$2),2)&"A" -> FY'22A | I9: =++"FY'"&RIGHT(YEAR(I$2),2)&"A" -> FY'23A | J9: =++"FY'"&RIGHT(YEAR(J$2),2)&"A" -> FY'24A | K9: =++"LTM "&TEXT(K$2,"M/YY")&"A" -> LTM 9/25A | L9: =++"LTM "&TEXT(L$2,"M/YY")&IF(LTMDate>LastActDate,"E","A") -> LTM 9/25A | N9: =++L9 -> LTM 9/25A
A11: x | B11: x | C11: Net Income (GAAP) | H11: {=++INDEX(FinInputs!$G248:$AH248,0,MATCH(H$2,FinInputs!$G$3:$AH$3,0))} -> 0 | I11: {=++INDEX(FinInputs!$G248:$AH248,0,MATCH(I$2,FinInputs!$G$3:$AH$3,0))} -> 0 | J11: {=++INDEX(FinInputs!$G248:$AH248,0,MATCH(J$2,FinInputs!$G$3:$AH$3,0))} -> 0 | K11: {=++INDEX(FinInputs!$G248:$AH248,0,MATCH(K$2,FinInputs!$G$3:$AH$3,0))} -> 0 | L11: {=++INDEX(FinInputs!$G248:$AH248,0,MATCH(L$2,FinInputs!$G$3:$AH$3,0))} -> 0
C13: Definitional Adjustments
C14: Income Tax Expense (Benefit) | H14: {=++INDEX(FinInputs!$G249:$AH249,0,MATCH(H$2,FinInputs!$G$3:$AH$3,0))} -> 0 | I14: {=++INDEX(FinInputs!$G249:$AH249,0,MATCH(I$2,FinInputs!$G$3:$AH$3,0))} -> 0 | J14: {=++INDEX(FinInputs!$G249:$AH249,0,MATCH(J$2,FinInputs!$G$3:$AH$3,0))} -> 0 | K14: {=++INDEX(FinInputs!$G249:$AH249,0,MATCH(K$2,FinInputs!$G$3:$AH$3,0))} -> 0 | L14: {=++INDEX(FinInputs!$G249:$AH249,0,MATCH(L$2,FinInputs!$G$3:$AH$3,0))} -> 0
C15: Interest Expense (Income) | H15: {=++INDEX(FinInputs!$G250:$AH250,0,MATCH(H$2,FinInputs!$G$3:$AH$3,0))} -> 0 | I15: {=++INDEX(FinInputs!$G250:$AH250,0,MATCH(I$2,FinInputs!$G$3:$AH$3,0))} -> 0 | J15: {=++INDEX(FinInputs!$G250:$AH250,0,MATCH(J$2,FinInputs!$G$3:$AH$3,0))} -> 0 | K15: {=++INDEX(FinInputs!$G250:$AH250,0,MATCH(K$2,FinInputs!$G$3:$AH$3,0))} -> 0 | L15: {=++INDEX(FinInputs!$G250:$AH250,0,MATCH(L$2,FinInputs!$G$3:$AH$3,0))} -> 0
C16: Depreciation | H16: {=++INDEX(FinInputs!$G251:$AH251,0,MATCH(H$2,FinInputs!$G$3:$AH$3,0))} -> 0 | I16: {=++INDEX(FinInputs!$G251:$AH251,0,MATCH(I$2,FinInputs!$G$3:$AH$3,0))} -> 0 | J16: {=++INDEX(FinInputs!$G251:$AH251,0,MATCH(J$2,FinInputs!$G$3:$AH$3,0))} -> 0 | K16: {=++INDEX(FinInputs!$G251:$AH251,0,MATCH(K$2,FinInputs!$G$3:$AH$3,0))} -> 0 | L16: {=++INDEX(FinInputs!$G251:$AH251,0,MATCH(L$2,FinInputs!$G$3:$AH$3,0))} -> 0
C17: Amortization | H17: {=++INDEX(FinInputs!$G252:$AH252,0,MATCH(H$2,FinInputs!$G$3:$AH$3,0))} -> 0 | I17: {=++INDEX(FinInputs!$G252:$AH252,0,MATCH(I$2,FinInputs!$G$3:$AH$3,0))} -> 0 | J17: {=++INDEX(FinInputs!$G252:$AH252,0,MATCH(J$2,FinInputs!$G$3:$AH$3,0))} -> 0 | K17: {=++INDEX(FinInputs!$G252:$AH252,0,MATCH(K$2,FinInputs!$G$3:$AH$3,0))} -> 0 | L17: {=++INDEX(FinInputs!$G252:$AH252,0,MATCH(L$2,FinInputs!$G$3:$AH$3,0))} -> 0
B18: x | C18: =++FinInputs!C253 -> EBITDA (Reported) | H18: =++SUM(H11,H14:H17) -> 0 | I18: =++SUM(I11,I14:I17) -> 0 | J18: =++SUM(J11,J14:J17) -> 0 | K18: =++SUM(K11,K14:K17) -> 0 | L18: =++SUM(L11,L14:L17) -> 0 | N18: =++IFERROR(L18/L$48,0) -> 0
C20: Diligence Adjustments
C21: -1 | D21: =++RIGHT(FinInputs!C257,LEN(FinInputs!C257)-6) -> [Diligence Adjustment] | H21: {=++INDEX(FinInputs!$G257:$AH257,0,MATCH(H$2,FinInputs!$G$3:$AH$3,0))} -> 0 | I21: {=++INDEX(FinInputs!$G257:$AH257,0,MATCH(I$2,FinInputs!$G$3:$AH$3,0))} -> 0 | J21: {=++INDEX(FinInputs!$G257:$AH257,0,MATCH(J$2,FinInputs!$G$3:$AH$3,0))} -> 0 | K21: {=++INDEX(FinInputs!$G257:$AH257,0,MATCH(K$2,FinInputs!$G$3:$AH$3,0))} -> 0 | L21: {=++INDEX(FinInputs!$G257:$AH257,0,MATCH(L$2,FinInputs!$G$3:$AH$3,0))} -> 0 | N21: =++IFERROR(L21/L$48,0) -> 0
C22: =++C21-1 -> -2 | D22: =++RIGHT(FinInputs!C258,LEN(FinInputs!C258)-6) -> [Diligence Adjustment] | H22: {=++INDEX(FinInputs!$G258:$AH258,0,MATCH(H$2,FinInputs!$G$3:$AH$3,0))} -> 0 | I22: {=++INDEX(FinInputs!$G258:$AH258,0,MATCH(I$2,FinInputs!$G$3:$AH$3,0))} -> 0 | J22: {=++INDEX(FinInputs!$G258:$AH258,0,MATCH(J$2,FinInputs!$G$3:$AH$3,0))} -> 0 | K22: {=++INDEX(FinInputs!$G258:$AH258,0,MATCH(K$2,FinInputs!$G$3:$AH$3,0))} -> 0 | L22: {=++INDEX(FinInputs!$G258:$AH258,0,MATCH(L$2,FinInputs!$G$3:$AH$3,0))} -> 0 | N22: =++IFERROR(L22/L$48,0) -> 0
C23: =++C22-1 -> -3 | D23: =++RIGHT(FinInputs!C259,LEN(FinInputs!C259)-6) -> [Diligence Adjustment] | H23: {=++INDEX(FinInputs!$G259:$AH259,0,MATCH(H$2,FinInputs!$G$3:$AH$3,0))} -> 0 | I23: {=++INDEX(FinInputs!$G259:$AH259,0,MATCH(I$2,FinInputs!$G$3:$AH$3,0))} -> 0 | J23: {=++INDEX(FinInputs!$G259:$AH259,0,MATCH(J$2,FinInputs!$G$3:$AH$3,0))} -> 0 | K23: {=++INDEX(FinInputs!$G259:$AH259,0,MATCH(K$2,FinInputs!$G$3:$AH$3,0))} -> 0 | L23: {=++INDEX(FinInputs!$G259:$AH259,0,MATCH(L$2,FinInputs!$G$3:$AH$3,0))} -> 0 | N23: =++IFERROR(L23/L$48,0) -> 0
C24: =++C23-1 -> -4 | D24: =++RIGHT(FinInputs!C260,LEN(FinInputs!C260)-6) -> [Diligence Adjustment] | H24: {=++INDEX(FinInputs!$G260:$AH260,0,MATCH(H$2,FinInputs!$G$3:$AH$3,0))} -> 0 | I24: {=++INDEX(FinInputs!$G260:$AH260,0,MATCH(I$2,FinInputs!$G$3:$AH$3,0))} -> 0 | J24: {=++INDEX(FinInputs!$G260:$AH260,0,MATCH(J$2,FinInputs!$G$3:$AH$3,0))} -> 0 | K24: {=++INDEX(FinInputs!$G260:$AH260,0,MATCH(K$2,FinInputs!$G$3:$AH$3,0))} -> 0 | L24: {=++INDEX(FinInputs!$G260:$AH260,0,MATCH(L$2,FinInputs!$G$3:$AH$3,0))} -> 0 | N24: =++IFERROR(L24/L$48,0) -> 0
C25: =++C24-1 -> -5 | D25: =++RIGHT(FinInputs!C261,LEN(FinInputs!C261)-6) -> [Diligence Adjustment] | H25: {=++INDEX(FinInputs!$G261:$AH261,0,MATCH(H$2,FinInputs!$G$3:$AH$3,0))} -> 0 | I25: {=++INDEX(FinInputs!$G261:$AH261,0,MATCH(I$2,FinInputs!$G$3:$AH$3,0))} -> 0 | J25: {=++INDEX(FinInputs!$G261:$AH261,0,MATCH(J$2,FinInputs!$G$3:$AH$3,0))} -> 0 | K25: {=++INDEX(FinInputs!$G261:$AH261,0,MATCH(K$2,FinInputs!$G$3:$AH$3,0))} -> 0 | L25: {=++INDEX(FinInputs!$G261:$AH261,0,MATCH(L$2,FinInputs!$G$3:$AH$3,0))} -> 0 | N25: =++IFERROR(L25/L$48,0) -> 0
C26: =++C25-1 -> -6 | D26: =++RIGHT(FinInputs!C262,LEN(FinInputs!C262)-6) -> [Diligence Adjustment] | H26: {=++INDEX(FinInputs!$G262:$AH262,0,MATCH(H$2,FinInputs!$G$3:$AH$3,0))} -> 0 | I26: {=++INDEX(FinInputs!$G262:$AH262,0,MATCH(I$2,FinInputs!$G$3:$AH$3,0))} -> 0 | J26: {=++INDEX(FinInputs!$G262:$AH262,0,MATCH(J$2,FinInputs!$G$3:$AH$3,0))} -> 0 | K26: {=++INDEX(FinInputs!$G262:$AH262,0,MATCH(K$2,FinInputs!$G$3:$AH$3,0))} -> 0 | L26: {=++INDEX(FinInputs!$G262:$AH262,0,MATCH(L$2,FinInputs!$G$3:$AH$3,0))} -> 0 | N26: =++IFERROR(L26/L$48,0) -> 0
C27: =++C26-1 -> -7 | D27: =++RIGHT(FinInputs!C263,LEN(FinInputs!C263)-6) -> [Diligence Adjustment] | H27: {=++INDEX(FinInputs!$G263:$AH263,0,MATCH(H$2,FinInputs!$G$3:$AH$3,0))} -> 0 | I27: {=++INDEX(FinInputs!$G263:$AH263,0,MATCH(I$2,FinInputs!$G$3:$AH$3,0))} -> 0 | J27: {=++INDEX(FinInputs!$G263:$AH263,0,MATCH(J$2,FinInputs!$G$3:$AH$3,0))} -> 0 | K27: {=++INDEX(FinInputs!$G263:$AH263,0,MATCH(K$2,FinInputs!$G$3:$AH$3,0))} -> 0 | L27: {=++INDEX(FinInputs!$G263:$AH263,0,MATCH(L$2,FinInputs!$G$3:$AH$3,0))} -> 0 | N27: =++IFERROR(L27/L$48,0) -> 0
C28: =++C27-1 -> -8 | D28: =++RIGHT(FinInputs!C264,LEN(FinInputs!C264)-6) -> [Diligence Adjustment] | H28: {=++INDEX(FinInputs!$G264:$AH264,0,MATCH(H$2,FinInputs!$G$3:$AH$3,0))} -> 0 | I28: {=++INDEX(FinInputs!$G264:$AH264,0,MATCH(I$2,FinInputs!$G$3:$AH$3,0))} -> 0 | J28: {=++INDEX(FinInputs!$G264:$AH264,0,MATCH(J$2,FinInputs!$G$3:$AH$3,0))} -> 0 | K28: {=++INDEX(FinInputs!$G264:$AH264,0,MATCH(K$2,FinInputs!$G$3:$AH$3,0))} -> 0 | L28: {=++INDEX(FinInputs!$G264:$AH264,0,MATCH(L$2,FinInputs!$G$3:$AH$3,0))} -> 0 | N28: =++IFERROR(L28/L$48,0) -> 0
C29: =++C28-1 -> -9 | D29: =++RIGHT(FinInputs!C265,LEN(FinInputs!C265)-6) -> [Diligence Adjustment] | H29: {=++INDEX(FinInputs!$G265:$AH265,0,MATCH(H$2,FinInputs!$G$3:$AH$3,0))} -> 0 | I29: {=++INDEX(FinInputs!$G265:$AH265,0,MATCH(I$2,FinInputs!$G$3:$AH$3,0))} -> 0 | J29: {=++INDEX(FinInputs!$G265:$AH265,0,MATCH(J$2,FinInputs!$G$3:$AH$3,0))} -> 0 | K29: {=++INDEX(FinInputs!$G265:$AH265,0,MATCH(K$2,FinInputs!$G$3:$AH$3,0))} -> 0 | L29: {=++INDEX(FinInputs!$G265:$AH265,0,MATCH(L$2,FinInputs!$G$3:$AH$3,0))} -> 0 | N29: =++IFERROR(L29/L$48,0) -> 0
C30: =++C29-1 -> -10 | D30: =++RIGHT(FinInputs!C266,LEN(FinInputs!C266)-6) -> [Diligence Adjustment] | H30: {=++INDEX(FinInputs!$G266:$AH266,0,MATCH(H$2,FinInputs!$G$3:$AH$3,0))} -> 0 | I30: {=++INDEX(FinInputs!$G266:$AH266,0,MATCH(I$2,FinInputs!$G$3:$AH$3,0))} -> 0 | J30: {=++INDEX(FinInputs!$G266:$AH266,0,MATCH(J$2,FinInputs!$G$3:$AH$3,0))} -> 0 | K30: {=++INDEX(FinInputs!$G266:$AH266,0,MATCH(K$2,FinInputs!$G$3:$AH$3,0))} -> 0 | L30: {=++INDEX(FinInputs!$G266:$AH266,0,MATCH(L$2,FinInputs!$G$3:$AH$3,0))} -> 0 | N30: =++IFERROR(L30/L$48,0) -> 0
C31: Total Diligence Adjustments | H31: =++SUM(H21:H30) -> 0 | I31: =++SUM(I21:I30) -> 0 | J31: =++SUM(J21:J30) -> 0 | K31: =++SUM(K21:K30) -> 0 | L31: =++SUM(L21:L30) -> 0 | N31: =++IFERROR(L31/L$48,0) -> 0
