Workbook
Name IQ_CH: 110000
Name IQ_CQ: 5000
Name IQ_CY: 10000
Name IQ_DAILY: 500000
Name IQ_FH: 100000
Name IQ_FQ: 500
Name IQ_FY: 1000
Name IQ_LTM: 2000
Name IQ_MONTH: 15000
Name IQ_NTM: 6000
Name IQ_WEEK: 50000
Name IQ_YTD: 3000

Sheet SUCAP
C1: =++FinSum!$C$1 -> [Company Name]
C2: =++FinSum!$C$2 -> Posting Memo Backup
C3: =++TEXT(TODAY(),"MMMM D, YYYY") -> April 24, 2026
A5: x | B5: x | C5: Sources & Uses
C7: USD in 000's, except where noted
A9: x | B9: x | C9: Sources | H9: Uses | M9: Opening FCCR
C11: =++"Priority RCF ($["&TEXT(U32/1000,"#,##0.0")&"]MM)" -> Priority RCF ($[0.0]MM) | F11: 0 | H11: [Use] | K11: 0 | M11: =++C43 -> LTM 9/25 CA EBITDA | P11: =++I43 -> 0
C12: 1L Term Loan B | F12: 0 | H12: [Use] | K12: 0 | M12: ( – ) Adjustments | P12: =++-FinSum!L22 -> 0
C13: =++"1L DDTL ($["&TEXT(U34/1000,"#,##0.0")&"]MM)" -> 1L DDTL ($[0.0]MM) | F13: 0 | H13: [Use] | K13: 0 | M13: ( – ) Cash Taxes | P13: 0
C14: Owner Equity | F14: =++F21-SUM(F11:F13) -> 0 | H14: [Use] | K14: 0 | M14: ( – ) Capital Expenditures | P14: =++-FinSum!L29 -> 0
H15: Financing Fees | K15: =++V35 -> 0 | M15: FCCR Numerator | P15: =++SUM(P11:P14) -> 0
H16: Transaction Expenses | K16: 0 | S16: SOFR
M17: Cash Interest Expense | P17: =++SUM((U32-F11)*0.5%,(U34-F13)*1%,F11*SUM(S17,S32/10000),F12*SUM(S17,S33/10000),F13*SUM(S17,S34/10000)) -> 0 | S17: 0.0387477
M18: ( + ) Mandatory Amortization | P18: =0.01*F12 -> 0
M19: FCCR Denominator | P19: =++SUM(P17:P18) -> 0
C21: Total Sources | F21: =++K21 -> 0 | H21: Total Uses | K21: =++SUM(K11:K20) -> 0 | M21: FCCR | P21: =++IFERROR(P15/P19,0) -> 0
B24: x | C24: Pro Forma Capitalization
C26: USD in 000's, except where noted | I26: =++"Pro Forma ("&TEXT(FinSum!$L$2,"M/YY")&")" -> Pro Forma (9/25)
C28: FYE December 31st | I28: $ | J28: Multiple | K28: % Cap | M28: Maturity | N28: Pricing | O28: OID | P28: Call Pro
C30: Cash & Equivalents | I30: 0
C32: =++C11 -> Priority RCF ($[0.0]MM) | I32: =++F11 -> 0 | J32: =++IFERROR(I32/I$43,0) -> 0 | K32: =++IFERROR(I32/I$40,0) -> 0 | M32: 5 Years | N32: =++"S + ["&TEXT(S32,"#,###")&"]" -> S + [325] | O32: =++"["&TEXT(T32,"#,##0.00")&"]" -> [99.00] | P32: n/a | S32: 325 | T32: 99 | U32: =++MROUND(I43,1000) -> 0 | V32: =++(100-T32)/100*U32 -> 0
C33: =++C12 -> 1L Term Loan B | I33: =++F12 -> 0 | J33: =++IFERROR(I33/I$43,0) -> 0 | K33: =++IFERROR(I33/I$40,0) -> 0 | M33: 5 Years | N33: =++"S + ["&TEXT(S33,"#,###")&"]" -> S + [575] | O33: =++"["&TEXT(T33,"#,##0.00")&"]" -> [98.00] | P33: [102 / 101] | S33: 575 | T33: 98 | U33: =++I33 -> 0 | V33: =++(100-T33)/100*U33 -> 0
C34: =++C13 -> 1L DDTL ($[0.0]MM) | I34: =++F13 -> 0 | J34: =++IFERROR(I34/I$43,0) -> 0 | K34: =++IFERROR(I34/I$40,0) -> 0 | M34: 5 Years | N34: =++"S + ["&TEXT(S34,"#,###")&"]" -> S + [575] | O34: =++"["&TEXT(T34,"#,##0.00")&"]" -> [98.00] | P34: =++P33 -> [102 / 101] | S34: =++S33 -> 575 | T34: =++T33 -> 98 | U34: 0 | V34: =++((100-T34)/100)/2*U34 -> 0
C35: Total Debt | I35: =++SUM(I32:I34) -> 0 | J35: =++IFERROR(I35/I$43,0) -> 0 | K35: =++IFERROR(I35/I$40,0) -> 0 | N35: =++"S + ["&TEXT(S35,"#,###")&"]" -> S + [] | O35: =++"["&TEXT(T35,"#,##0.00")&"]" -> [0.00] | S35: =++IFERROR(SUMPRODUCT($I$32:$I$34,S$32:S$34)/SUM($I$32:$I$34),0) -> 0 | T35: =++IFERROR(SUMPRODUCT($I$32:$I$34,T$32:T$34)/SUM($I$32:$I$34),0) -> 0 | U35: =SUM(U32:U34) -> 0 | V35: =SUM(V32:V34) -> 0
C36: Total Net Debt | I36: =++I35-I$30 -> 0 | J36: =++IFERROR(I36/I$43,0) -> 0
C38: Common Equity | I38: =++F14 -> 0 | J38: =++IFERROR(I38/I$43,0) -> 0 | K38: =++IFERROR(I38/I$40,0) -> 0
C39: Implied Equity | I39: =++I40-SUM(I35,I38) -> 0 | J39: =++IFERROR(I39/I$43,0) -> 0 | K39: =++IFERROR(I39/I$40,0) -> 0
C40: Total Capitalization | I40: =++SUM(I41,I30) -> 0 | J40: =++IFERROR(I40/I$43,0) -> 0 | K40: =++SUM(K35,K38:K39) -> 0
C41: TEV | I41: =++I43*J41 -> 0 | J41: 0
C43: =++"LTM "&TEXT(FinSum!$L$2,"M/YY")&" CA EBITDA" -> LTM 9/25 CA EBITDA | I43: =++FinSum!L23 -> 0
A46: x | B46: x

Sheet FinSum
C1: [Company Name]
C2: Posting Memo Backup | G2: 44196 | H2: =++EOMONTH(G2,12) -> 44561 | I2: =++EOMONTH(H2,12) -> 44926 | J2: =++EOMONTH(I2,12) -> 45291 | K2: =++EOMONTH(J2,12) -> 45657 | L2: 45930 | M2: =++EOMONTH(K2,12) -> 46022 | R2: =++EOMONTH(L2,-12) -> 45565
C3: =++TEXT(TODAY(),"MMMM D, YYYY") -> April 24, 2026
A5: x | B5: x | C5: Historical Financial Summary
C7: USD in 000's, except where noted | G7: Trailing Twelve Month Period Ending, | O7: CAGR
C9: FYE December 31st | G9: =++"FY'"&RIGHT(YEAR(G$2),2)&"A" -> FY'20A | H9: =++"FY'"&RIGHT(YEAR(H$2),2)&"A" -> FY'21A | I9: =++"FY'"&RIGHT(YEAR(I$2),2)&"A" -> FY'22A | J9: =++"FY'"&RIGHT(YEAR(J$2),2)&"A" -> FY'23A | K9: =++"FY'"&RIGHT(YEAR(K$2),2)&"A" -> FY'24A | L9: =++"LTM "&TEXT(L$2,"M/YY")&"A" -> LTM 9/25A | M9: =++"FY'"&RIGHT(YEAR(M$2),2)&"E" -> FY'25E | O9: =++RIGHT(G9,4)&" - LTM" -> '20A - LTM | R9: =++"LTM "&TEXT(R$2,"M/YY")&"A" -> LTM 9/24A
A11: x | B11: x | C11: Revenue | G11: 0 | H11: 0 | I11: 0 | J11: 0 | K11: 0 | L11: 0 | M11: 0 | O11: =++IFERROR((L11/G11)^(1/YEARFRAC(G$2,L$2,1))-1,0) -> 0 | R11: 0
C12: % y/y | H12: =++IFERROR(H11/G11-1,0) -> 0 | I12: =++IFERROR(I11/H11-1,0) -> 0 | J12: =++IFERROR(J11/I11-1,0) -> 0 | K12: =++IFERROR(K11/J11-1,0) -> 0 | L12: =++IFERROR(L11/R11-1,0) -> 0 | M12: =++IFERROR(M11/K11-1,0) -> 0
C14: Gross Profit | G14: 0 | H14: 0 | I14: 0 | J14: 0 | K14: 0 | L14: 0 | M14: 0 | O14: =++IFERROR((L14/G14)^(1/YEARFRAC(G$2,L$2,1))-1,0) -> 0 | R14: 0
C15: % margin | G15: =++IFERROR(G14/G$11,0) -> 0 | H15: =++IFERROR(H14/H$11,0) -> 0 | I15: =++IFERROR(I14/I$11,0) -> 0 | J15: =++IFERROR(J14/J$11,0) -> 0 | K15: =++IFERROR(K14/K$11,0) -> 0 | L15: =++IFERROR(L14/L$11,0) -> 0 | M15: =++IFERROR(M14/M$11,0) -> 0 | R15: =++IFERROR(R14/R$11,0) -> 0
C16: % y/y | H16: =++IFERROR(H14/G14-1,0) -> 0 | I16: =++IFERROR(I14/H14-1,0) -> 0 | J16: =++IFERROR(J14/I14-1,0) -> 0 | K16: =++IFERROR(K14/J14-1,0) -> 0 | L16: =++IFERROR(L14/R14-1,0) -> 0 | M16: =++IFERROR(M14/K14-1,0) -> 0
C18: EBITDA (Reported) | G18: 0 | H18: 0 | I18: 0 | J18: 0 | K18: 0 | L18: 0 | M18: 0 | O18: =++IFERROR((L18/G18)^(1/YEARFRAC(G$2,L$2,1))-1,0) -> 0 | R18: 0
C19: % margin | G19: =++IFERROR(G18/G$11,0) -> 0 | H19: =++IFERROR(H18/H$11,0) -> 0 | I19: =++IFERROR(I18/I$11,0) -> 0 | J19: =++IFERROR(J18/J$11,0) -> 0 | K19: =++IFERROR(K18/K$11,0) -> 0 | L19: =++IFERROR(L18/L$11,0) -> 0 | M19: =++IFERROR(M18/M$11,0) -> 0 | R19: =++IFERROR(R18/R$11,0) -> 0
C20: % y/y | H20: =++IFERROR(H18/G18-1,0) -> 0 | I20: =++IFERROR(I18/H18-1,0) -> 0 | J20: =++IFERROR(J18/I18-1,0) -> 0 | K20: =++IFERROR(K18/J18-1,0) -> 0 | L20: =++IFERROR(L18/R18-1,0) -> 0 | M20: =++IFERROR(M18/K18-1,0) -> 0
C22: ( + ) Adjustments | G22: =++G23-G18 -> 0 | H22: =++H23-H18 -> 0 | I22: =++I23-I18 -> 0 | J22: =++J23-J18 -> 0 | K22: =++K23-K18 -> 0 | L22: =++L23-L18 -> 0 | M22: =++M23-M18 -> 0 | O22: =++IFERROR((L22/G22)^(1/YEARFRAC(G$2,L$2,1))-1,0) -> 0 | R22: =++R23-R18 -> 0
C23: CA EBITDA | G23: 0 | H23: 0 | I23: 0 | J23: 0 | K23: 0 | L23: 0 | M23: 0 | O23: =++IFERROR((L23/G23)^(1/YEARFRAC(G$2,L$2,1))-1,0) -> 0 | R23: 0
C24: % margin | G24: =++IFERROR(G23/G$11,0) -> 0 | H24: =++IFERROR(H23/H$11,0) -> 0 | I24: =++IFERROR(I23/I$11,0) -> 0 | J24: =++IFERROR(J23/J$11,0) -> 0 | K24: =++IFERROR(K23/K$11,0) -> 0 | L24: =++IFERROR(L23/L$11,0) -> 0 | M24: =++IFERROR(M23/M$11,0) -> 0 | R24: =++IFERROR(R23/R$11,0) -> 0
C25: % y/y | H25: =++IFERROR(H23/G23-1,0) -> 0 | I25: =++IFERROR(I23/H23-1,0) -> 0 | J25: =++IFERROR(J23/I23-1,0) -> 0 | K25: =++IFERROR(K23/J23-1,0) -> 0 | L25: =++IFERROR(L23/R23-1,0) -> 0 | M25: =++IFERROR(M23/K23-1,0) -> 0
C27: Maintenance | G27: 0 | H27: 0 | I27: 0 | J27: 0 | K27: 0 | L27: 0 | M27: 0 | O27: =++IFERROR((L27/G27)^(1/YEARFRAC(G$2,L$2,1))-1,0) -> 0 | R27: 0
C28: Growth | G28: 0 | H28: 0 | I28: 0 | J28: 0 | K28: 0 | L28: 0 | M28: 0 | O28: =++IFERROR((L28/G28)^(1/YEARFRAC(G$2,L$2,1))-1,0) -> 0 | R28: 0
C29: Capital Expenditures | G29: =++SUM(G27:G28) -> 0 | H29: =++SUM(H27:H28) -> 0 | I29: =++SUM(I27:I28) -> 0 | J29: =++SUM(J27:J28) -> 0 | K29: =++SUM(K27:K28) -> 0 | L29: =++SUM(L27:L28) -> 0 | M29: =++SUM(M27:M28) -> 0 | O29: =++IFERROR((L29/G29)^(1/YEARFRAC(G$2,L$2,1))-1,0) -> 0 | R29: =++SUM(R27:R28) -> 0
C30: % revenue | G30: =++IFERROR(G29/G$11,0) -> 0 | H30: =++IFERROR(H29/H$11,0) -> 0 | I30: =++IFERROR(I29/I$11,0) -> 0 | J30: =++IFERROR(J29/J$11,0) -> 0 | K30: =++IFERROR(K29/K$11,0) -> 0 | L30: =++IFERROR(L29/L$11,0) -> 0 | M30: =++IFERROR(M29/M$11,0) -> 0 | R30: =++IFERROR(R29/R$11,0) -> 0
B34: x | C34: Supporting Posting Memo MD&A Calcs:
C37: Days in Period | G37: =++G2-EOMONTH(G2,-12) -> 366 | H37: =++H2-EOMONTH(H2,-12) -> 365 | I37: =++I2-EOMONTH(I2,-12) -> 365 | J37: =++J2-EOMONTH(J2,-12) -> 365 | K37: =++K2-EOMONTH(K2,-12) -> 366 | L37: =++L2-EOMONTH(L2,-12) -> 365 | M37: =++M2-EOMONTH(M2,-12) -> 365 | O37: Average
C39: TTM Revenue | G39: =++G11 -> 0 | H39: =++H11 -> 0 | I39: =++I11 -> 0 | J39: =++J11 -> 0 | K39: =++K11 -> 0 | L39: =++L11 -> 0 | M39: =++M11 -> 0
C40: TTM COGS | G40: =++(G11-G14) -> 0 | H40: =++(H11-H14) -> 0 | I40: =++(I11-I14) -> 0 | J40: =++(J11-J14) -> 0 | K40: =++(K11-K14) -> 0 | L40: =++(L11-L14) -> 0 | M40: =++(M11-M14) -> 0
C42: =++C27 -> Maintenance | G42: =++IFERROR(G27/G$39,0) -> 0 | H42: =++IFERROR(H27/H$39,0) -> 0 | I42: =++IFERROR(I27/I$39,0) -> 0 | J42: =++IFERROR(J27/J$39,0) -> 0 | K42: =++IFERROR(K27/K$39,0) -> 0 | L42: =++IFERROR(L27/L$39,0) -> 0 | M42: =++IFERROR(M27/M$39,0) -> 0 | O42: =++IFERROR(AVERAGEIF(G42:M42,"<>"&0),0) -> 0
C43: =++C28 -> Growth | G43: =++IFERROR(G28/G$39,0) -> 0 | H43: =++IFERROR(H28/H$39,0) -> 0 | I43: =++IFERROR(I28/I$39,0) -> 0 | J43: =++IFERROR(J28/J$39,0) -> 0 | K43: =++IFERROR(K28/K$39,0) -> 0 | L43: =++IFERROR(L28/L$39,0) -> 0 | M43: =++IFERROR(M28/M$39,0) -> 0 | O43: =++IFERROR(AVERAGEIF(G43:M43,"<>"&0),0) -> 0
C44: =++C29 -> Capital Expenditures | G44: =++IFERROR(G29/G$39,0) -> 0 | H44: =++IFERROR(H29/H$39,0) -> 0 | I44: =++IFERROR(I29/I$39,0) -> 0 | J44: =++IFERROR(J29/J$39,0) -> 0 | K44: =++IFERROR(K29/K$39,0) -> 0 | L44: =++IFERROR(L29/L$39,0) -> 0 | M44: =++IFERROR(M29/M$39,0) -> 0 | O44: =++IFERROR(AVERAGEIF(G44:M44,"<>"&0),0) -> 0
C46: Accounts Receivable | G46: 0 | H46: 0 | I46: 0 | J46: 0 | K46: 0 | L46: 0 | M46: 0
C47: Costs in Excess of Billings ("CIE") | G47: 0 | H47: 0 | I47: 0 | J47: 0 | K47: 0 | L47: 0 | M47: 0
C48: Inventory | G48: 0 | H48: 0 | I48: 0 | J48: 0 | K48: 0 | L48: 0 | M48: 0
C49: Prepaid & Other | G49: 0 | H49: 0 | I49: 0 | J49: 0 | K49: 0 | L49: 0 | M49: 0
C50: Current Assets | G50: =++SUM(G46:G49) -> 0 | H50: =++SUM(H46:H49) -> 0 | I50: =++SUM(I46:I49) -> 0 | J50: =++SUM(J46:J49) -> 0 | K50: =++SUM(K46:K49) -> 0 | L50: =++SUM(L46:L49) -> 0 | M50: =++SUM(M46:M49) -> 0
C52: Accounts Payable | G52: 0 | H52: 0 | I52: 0 | J52: 0 | K52: 0 | L52: 0 | M52: 0
C53: Billings in Excess of Costs ("BIE") | G53: 0 | H53: 0 | I53: 0 | J53: 0 | K53: 0 | L53: 0 | M53: 0
C54: Deferred Revenue | G54: 0 | H54: 0 | I54: 0 | J54: 0 | K54: 0 | L54: 0 | M54: 0
C55: Accrued & Other | G55: 0 | H55: 0 | I55: 0 | J55: 0 | K55: 0 | L55: 0 | M55: 0
C56: Current Liabilities | G56: =++SUM(G52:G55) -> 0 | H56: =++SUM(H52:H55) -> 0 | I56: =++SUM(I52:I55) -> 0 | J56: =++SUM(J52:J55) -> 0 | K56: =++SUM(K52:K55) -> 0 | L56: =++SUM(L52:L55) -> 0 | M56: =++SUM(M52:M55) -> 0
C58: NWC | G58: =++G50-G56 -> 0 | H58: =++H50-H56 -> 0 | I58: =++I50-I56 -> 0 | J58: =++J50-J56 -> 0 | K58: =++K50-K56 -> 0 | L58: =++L50-L56 -> 0 | M58: =++M50-M56 -> 0
...

Sheet Detailed FinSum
C1: =++FinSum!$C$1 -> [Company Name]
C2: =++FinSum!$C$2 -> Posting Memo Backup | G2: 43830 | H2: =++EOMONTH(G2,12) -> 44196 | I2: =++EOMONTH(H2,12) -> 44561 | J2: =++EOMONTH(I2,12) -> 44926 | K2: =++EOMONTH(J2,12) -> 45291 | L2: 45565 | M2: =++EOMONTH(K2,12) -> 45657 | Q2: =++EOMONTH(R2,-12) -> 45199 | R2: =++L2 -> 45565 | U2: =++EOMONTH(L2,-12) -> 45199 | V2: =++EOMONTH(Q2,-12) -> 44834
C3: =++TEXT(TODAY(),"MMMM D, YYYY") -> April 24, 2026
A5: x | B5: x | C5: Historical Financial Summary
C7: USD in 000's, except where noted | G7: Trailing Twelve Month Period Ending, | O7: CAGR | Q7: YTD Period Ending,
C9: FYE December 31st | G9: =++"FY'"&RIGHT(YEAR(G$2),2)&"A" -> FY'19A | H9: =++"FY'"&RIGHT(YEAR(H$2),2)&"A" -> FY'20A | I9: =++"FY'"&RIGHT(YEAR(I$2),2)&"A" -> FY'21A | J9: =++"FY'"&RIGHT(YEAR(J$2),2)&"A" -> FY'22A | K9: =++"FY'"&RIGHT(YEAR(K$2),2)&"A" -> FY'23A | L9: =++"LTM "&TEXT(L$2,"M/YY")&"A" -> LTM 9/24A | M9: =++"FY'"&RIGHT(YEAR(M$2),2)&"E" -> FY'24E | O9: =++RIGHT(G9,4)&" - LTM" -> '19A - LTM | Q9: =++TEXT(Q$2,"M/YY")&"A" -> 9/23A | R9: =++TEXT(R$2,"M/YY")&"A" -> 9/24A | U9: =++"LTM "&TEXT(U$2,"M/YY")&"A" -> LTM 9/23A | V9: =++TEXT(V$2,"M/YY")&"A" -> 9/22A
A11: x | B11: x | C11: [Segment] | G11: 0 | H11: 0 | I11: 0 | J11: 0 | K11: 0 | L11: 0 | M11: 0 | O11: =++IFERROR((L11/G11)^(1/YEARFRAC(G$2,L$2,1))-1,0) -> 0 | Q11: 0 | R11: 0 | U11: 0 | V11: 0
C12: [Segment] | G12: 0 | H12: 0 | I12: 0 | J12: 0 | K12: 0 | L12: 0 | M12: 0 | O12: =++IFERROR((L12/G12)^(1/YEARFRAC(G$2,L$2,1))-1,0) -> 0 | Q12: 0 | R12: 0 | U12: 0 | V12: 0
C13: [Segment] | G13: 0 | H13: 0 | I13: 0 | J13: 0 | K13: 0 | L13: 0 | M13: 0 | O13: =++IFERROR((L13/G13)^(1/YEARFRAC(G$2,L$2,1))-1,0) -> 0 | Q13: 0 | R13: 0 | U13: 0 | V13: 0
C14: [Segment] | G14: 0 | H14: 0 | I14: 0 | J14: 0 | K14: 0 | L14: 0 | M14: 0 | O14: =++IFERROR((L14/G14)^(1/YEARFRAC(G$2,L$2,1))-1,0) -> 0 | Q14: 0 | R14: 0 | U14: 0 | V14: 0
C15: Other | G15: 0 | H15: 0 | I15: 0 | J15: 0 | K15: 0 | L15: 0 | M15: 0 | O15: =++IFERROR((L15/G15)^(1/YEARFRAC(G$2,L$2,1))-1,0) -> 0 | Q15: 0 | R15: 0 | U15: 0 | V15: 0
C16: Revenue | G16: =++SUM(G11:G15) -> 0 | H16: =++SUM(H11:H15) -> 0 | I16: =++SUM(I11:I15) -> 0 | J16: =++SUM(J11:J15) -> 0 | K16: =++SUM(K11:K15) -> 0 | L16: =++SUM(L11:L15) -> 0 | M16: =++SUM(M11:M15) -> 0 | O16: =++IFERROR((L16/G16)^(1/YEARFRAC(G$2,L$2,1))-1,0) -> 0 | Q16: =++SUM(Q11:Q15) -> 0 | R16: =++SUM(R11:R15) -> 0 | U16: =++SUM(U11:U15) -> 0 | V16: =++SUM(V11:V15) -> 0
C17: % y/y | H17: =++IFERROR(H16/G16-1,0) -> 0 | I17: =++IFERROR(I16/H16-1,0) -> 0 | J17: =++IFERROR(J16/I16-1,0) -> 0 | K17: =++IFERROR(K16/J16-1,0) -> 0 | L17: =++IFERROR(L16/U16-1,0) -> 0 | M17: =++IFERROR(M16/K16-1,0) -> 0 | Q17: =++IFERROR(Q16/V16-1,0) -> 0 | R17: =++IFERROR(R16/Q16-1,0) -> 0
C19: [COGS Expense] | G19: 0 | H19: 0 | I19: 0 | J19: 0 | K19: 0 | L19: 0 | M19: 0 | O19: =++IFERROR((L19/G19)^(1/YEARFRAC(G$2,L$2,1))-1,0) -> 0 | Q19: 0 | R19: 0 | U19: 0 | V19: 0
C20: [COGS Expense] | G20: 0 | H20: 0 | I20: 0 | J20: 0 | K20: 0 | L20: 0 | M20: 0 | O20: =++IFERROR((L20/G20)^(1/YEARFRAC(G$2,L$2,1))-1,0) -> 0 | Q20: 0 | R20: 0 | U20: 0 | V20: 0
C21: [COGS Expense] | G21: 0 | H21: 0 | I21: 0 | J21: 0 | K21: 0 | L21: 0 | M21: 0 | O21: =++IFERROR((L21/G21)^(1/YEARFRAC(G$2,L$2,1))-1,0) -> 0 | Q21: 0 | R21: 0 | U21: 0 | V21: 0
C22: [COGS Expense] | G22: 0 | H22: 0 | I22: 0 | J22: 0 | K22: 0 | L22: 0 | M22: 0 | O22: =++IFERROR((L22/G22)^(1/YEARFRAC(G$2,L$2,1))-1,0) -> 0 | Q22: 0 | R22: 0 | U22: 0 | V22: 0
C23: Other COGS | G23: =++(G16-G24)-SUM(G19:G22) -> 0 | H23: =++(H16-H24)-SUM(H19:H22) -> 0 | I23: =++(I16-I24)-SUM(I19:I22) -> 0 | J23: =++(J16-J24)-SUM(J19:J22) -> 0 | K23: =++(K16-K24)-SUM(K19:K22) -> 0 | L23: =++(L16-L24)-SUM(L19:L22) -> 0 | M23: =++(M16-M24)-SUM(M19:M22) -> 0 | O23: =++IFERROR((L23/G23)^(1/YEARFRAC(G$2,L$2,1))-1,0) -> 0 | Q23: =++(Q16-Q24)-SUM(Q19:Q22) -> 0 | R23: =++(R16-R24)-SUM(R19:R22) -> 0 | U23: =++(U16-U24)-SUM(U19:U22) -> 0 | V23: =++(V16-V24)-SUM(V19:V22) -> 0
C24: Gross Profit | G24: 0 | H24: 0 | I24: 0 | J24: 0 | K24: 0 | L24: 0 | M24: 0 | O24: =++IFERROR((L24/G24)^(1/YEARFRAC(G$2,L$2,1))-1,0) -> 0 | Q24: 0 | R24: 0 | U24: 0 | V24: 0
C25: % margin | G25: =++IFERROR(G24/G$16,0) -> 0 | H25: =++IFERROR(H24/H$16,0) -> 0 | I25: =++IFERROR(I24/I$16,0) -> 0 | J25: =++IFERROR(J24/J$16,0) -> 0 | K25: =++IFERROR(K24/K$16,0) -> 0 | L25: =++IFERROR(L24/L$16,0) -> 0 | M25: =++IFERROR(M24/M$16,0) -> 0 | Q25: =++IFERROR(Q24/Q$16,0) -> 0 | R25: =++IFERROR(R24/R$16,0) -> 0 | U25: =++IFERROR(U24/U$16,0) -> 0 | V25: =++IFERROR(V24/V$16,0) -> 0
C26: % y/y | H26: =++IFERROR(H24/G24-1,0) -> 0 | I26: =++IFERROR(I24/H24-1,0) -> 0 | J26: =++IFERROR(J24/I24-1,0) -> 0 | K26: =++IFERROR(K24/J24-1,0) -> 0 | L26: =++IFERROR(L24/U24-1,0) -> 0 | M26: =++IFERROR(M24/K24-1,0) -> 0 | Q26: =++IFERROR(Q24/V24-1,0) -> 0 | R26: =++IFERROR(R24/Q24-1,0) -> 0
C28: [SG&A Expense] | G28: 0 | H28: 0 | I28: 0 | J28: 0 | K28: 0 | L28: 0 | M28: 0 | O28: =++IFERROR((L28/G28)^(1/YEARFRAC(G$2,L$2,1))-1,0) -> 0 | Q28: 0 | R28: 0 | U28: 0 | V28: 0
C29: [SG&A Expense] | G29: 0 | H29: 0 | I29: 0 | J29: 0 | K29: 0 | L29: 0 | M29: 0 | O29: =++IFERROR((L29/G29)^(1/YEARFRAC(G$2,L$2,1))-1,0) -> 0 | Q29: 0 | R29: 0 | U29: 0 | V29: 0
C30: [SG&A Expense] | G30: 0 | H30: 0 | I30: 0 | J30: 0 | K30: 0 | L30: 0 | M30: 0 | O30: =++IFERROR((L30/G30)^(1/YEARFRAC(G$2,L$2,1))-1,0) -> 0 | Q30: 0 | R30: 0 | U30: 0 | V30: 0
C31: [SG&A Expense] | G31: 0 | H31: 0 | I31: 0 | J31: 0 | K31: 0 | L31: 0 | M31: 0 | O31: =++IFERROR((L31/G31)^(1/YEARFRAC(G$2,L$2,1))-1,0) -> 0 | Q31: 0 | R31: 0 | U31: 0 | V31: 0
C32: Other Expense (Income) | G32: =++(G24-G33)-SUM(G28:G31) -> 0 | H32: =++(H24-H33)-SUM(H28:H31) -> 0 | I32: =++(I24-I33)-SUM(I28:I31) -> 0 | J32: =++(J24-J33)-SUM(J28:J31) -> 0 | K32: =++(K24-K33)-SUM(K28:K31) -> 0 | L32: =++(L24-L33)-SUM(L28:L31) -> 0 | M32: =++(M24-M33)-SUM(M28:M31) -> 0 | O32: =++IFERROR((L32/G32)^(1/YEARFRAC(G$2,L$2,1))-1,0) -> 0 | Q32: =++(Q24-Q33)-SUM(Q28:Q31) -> 0 | R32: =++(R24-R33)-SUM(R28:R31) -> 0 | U32: =++(U24-U33)-SUM(U28:U31) -> 0 | V32: =++(V24-V33)-SUM(V28:V31) -> 0
C33: EBITDA (Reported) | G33: 0 | H33: 0 | I33: 0 | J33: 0 | K33: 0 | L33: 0 | M33: 0 | O33: =++IFERROR((L33/G33)^(1/YEARFRAC(G$2,L$2,1))-1,0) -> 0 | Q33: 0 | R33: 0 | U33: 0 | V33: 0
C34: % margin | G34: =++IFERROR(G33/G$16,0) -> 0 | H34: =++IFERROR(H33/H$16,0) -> 0 | I34: =++IFERROR(I33/I$16,0) -> 0 | J34: =++IFERROR(J33/J$16,0) -> 0 | K34: =++IFERROR(K33/K$16,0) -> 0 | L34: =++IFERROR(L33/L$16,0) -> 0 | M34: =++IFERROR(M33/M$16,0) -> 0 | Q34: =++IFERROR(Q33/Q$16,0) -> 0 | R34: =++IFERROR(R33/R$16,0) -> 0 | U34: =++IFERROR(U33/U$16,0) -> 0 | V34: =++IFERROR(V33/V$16,0) -> 0
C35: % y/y | H35: =++IFERROR(H33/G33-1,0) -> 0 | I35: =++IFERROR(I33/H33-1,0) -> 0 | J35: =++IFERROR(J33/I33-1,0) -> 0 | K35: =++IFERROR(K33/J33-1,0) -> 0 | L35: =++IFERROR(L33/U33-1,0) -> 0 | M35: =++IFERROR(M33/K33-1,0) -> 0 | Q35: =++IFERROR(Q33/V33-1,0) -> 0 | R35: =++IFERROR(R33/Q33-1,0) -> 0
C37: ( + ) Adjustments | G37: =++G38-G33 -> 0 | H37: =++H38-H33 -> 0 | I37: =++I38-I33 -> 0 | J37: =++J38-J33 -> 0 | K37: =++K38-K33 -> 0 | L37: =++L38-L33 -> 0 | M37: =++M38-M33 -> 0 | O37: =++IFERROR((L37/G37)^(1/YEARFRAC(G$2,L$2,1))-1,0) -> 0 | Q37: =++Q38-Q33 -> 0 | R37: =++R38-R33 -> 0 | U37: =++U38-U33 -> 0 | V37: =++V38-V33 -> 0
C38: CA EBITDA | G38: 0 | H38: 0 | I38: 0 | J38: 0 | K38: 0 | L38: 0 | M38: 0 | O38: =++IFERROR((L38/G38)^(1/YEARFRAC(G$2,L$2,1))-1,0) -> 0 | Q38: 0 | R38: 0 | U38: 0 | V38: 0
C39: % margin | G39: =++IFERROR(G38/G$16,0) -> 0 | H39: =++IFERROR(H38/H$16,0) -> 0 | I39: =++IFERROR(I38/I$16,0) -> 0 | J39: =++IFERROR(J38/J$16,0) -> 0 | K39: =++IFERROR(K38/K$16,0) -> 0 | L39: =++IFERROR(L38/L$16,0) -> 0 | M39: =++IFERROR(M38/M$16,0) -> 0 | Q39: =++IFERROR(Q38/Q$16,0) -> 0 | R39: =++IFERROR(R38/R$16,0) -> 0 | U39: =++IFERROR(U38/U$16,0) -> 0 | V39: =++IFERROR(V38/V$16,0) -> 0
C40: % y/y | H40: =++IFERROR(H38/G38-1,0) -> 0 | I40: =++IFERROR(I38/H38-1,0) -> 0 | J40: =++IFERROR(J38/I38-1,0) -> 0 | K40: =++IFERROR(K38/J38-1,0) -> 0 | L40: =++IFERROR(L38/U38-1,0) -> 0 | M40: =++IFERROR(M38/K38-1,0) -> 0 | Q40: =++IFERROR(Q38/V38-1,0) -> 0 | R40: =++IFERROR(R38/Q38-1,0) -> 0
C42: Maintenance | G42: 0 | H42: 0 | I42: 0 | J42: 0 | K42: 0 | L42: 0 | M42: 0 | O42: =++IFERROR((L42/G42)^(1/YEARFRAC(G$2,L$2,1))-1,0) -> 0 | Q42: 0 | R42: 0 | U42: 0 | V42: 0
C43: Growth | G43: 0 | H43: 0 | I43: 0 | J43: 0 | K43: 0 | L43: 0 | M43: 0 | O43: =++IFERROR((L43/G43)^(1/YEARFRAC(G$2,L$2,1))-1,0) -> 0 | Q43: 0 | R43: 0 | U43: 0 | V43: 0
C44: Capital Expenditures | G44: =++SUM(G42:G43) -> 0 | H44: =++SUM(H42:H43) -> 0 | I44: =++SUM(I42:I43) -> 0 | J44: =++SUM(J42:J43) -> 0 | K44: =++SUM(K42:K43) -> 0 | L44: =++SUM(L42:L43) -> 0 | M44: =++SUM(M42:M43) -> 0 | O44: =++IFERROR((L44/G44)^(1/YEARFRAC(G$2,L$2,1))-1,0) -> 0 | Q44: =++SUM(Q42:Q43) -> 0 | R44: =++SUM(R42:R43) -> 0 | U44: =++SUM(U42:U43) -> 0 | V44: =++SUM(V42:V43) -> 0
C45: % revenue | G45: =++IFERROR(G44/G$16,0) -> 0 | H45: =++IFERROR(H44/H$16,0) -> 0 | I45: =++IFERROR(I44/I$16,0) -> 0 | J45: =++IFERROR(J44/J$16,0) -> 0 | K45: =++IFERROR(K44/K$16,0) -> 0 | L45: =++IFERROR(L44/L$16,0) -> 0 | M45: =++IFERROR(M44/M$16,0) -> 0 | Q45: =++IFERROR(Q44/Q$16,0) -> 0 | R45: =++IFERROR(R44/R$16,0) -> 0 | U45: =++IFERROR(U44/U$16,0) -> 0 | V45: =++IFERROR(V44/V$16,0) -> 0
A49: x | B49: x

Sheet Returns
C1: =++FinSum!$C$1 -> [Company Name]
C2: =++FinSum!$C$2 -> Posting Memo Backup | H2: =++TODAY() -> 46136 | I2: 45657 | J2: =++EOMONTH(I2,3) -> 45747 | K2: =++EOMONTH(J2,3) -> 45838 | L2: =++EOMONTH(K2,3) -> 45930 | M2: =++EOMONTH(L2,3) -> 46022 | N2: =++EOMONTH(M2,3) -> 46112 | O2: =++EOMONTH(N2,3) -> 46203 | P2: =++EOMONTH(O2,3) -> 46295 | Q2: =++EOMONTH(P2,3) -> 46387 | ... AB2: =++EOMONTH(AA2,3) -> 47391 | AC2: 47422
C3: =++TEXT(TODAY(),"MMMM D, YYYY") -> April 24, 2026
A5: x | B5: x | C5: Posing Memo Returns Analysis
C7: USD in 000s, except where noted | H7: =++TEXT(H$2,"M/D/YY") -> 4/24/26 | I7: =++TEXT(I$2,"M/D/YY") -> 12/31/24 | J7: =++TEXT(J$2,"M/D/YY") -> 3/31/25 | K7: =++TEXT(K$2,"M/D/YY") -> 6/30/25 | L7: =++TEXT(L$2,"M/D/YY") -> 9/30/25 | M7: =++TEXT(M$2,"M/D/YY") -> 12/31/25 | N7: =++TEXT(N$2,"M/D/YY") -> 3/31/26 | O7: =++TEXT(O$2,"M/D/YY") -> 6/30/26 | ... AC7: =++TEXT(AC$2,"M/D/YY") -> 10/31/29
A9: x | B9: x | C9: Overland Unlevered Returns
C11: Overland TLB Face Value (BoP) | I11: =++H13 -> 0 | J11: =++I13 -> 0 | K11: =++J13 -> 0 | L11: =++K13 -> 0 | M11: =++L13 -> 0 | N11: =++M13 -> 0 | O11: =++N13 -> 0 | P11: =++O13 -> 0 | ... AC11: =++AB13 -> 0
C12: ( – ) Amortization | F12: 0.01 | J12: =++-$H13*$F12/4 -> 0 | K12: =++-$H13*$F12/4 -> 0 | L12: =++-$H13*$F12/4 -> 0 | M12: =++-$H13*$F12/4 -> 0 | N12: =++-$H13*$F12/4 -> 0 | O12: =++-$H13*$F12/4 -> 0 | P12: =++-$H13*$F12/4 -> 0 | Q12: =++-$H13*$F12/4 -> 0 | ... AB12: =++-$H13*$F12/4 -> 0 | AC12: =++-AC11 -> 0
C13: Overland TLB Face Value (EoP) | H13: =++SUCAP!F12 -> 0 | I13: =++SUM(I11:I12) -> 0 | J13: =++SUM(J11:J12) -> 0 | K13: =++SUM(K11:K12) -> 0 | L13: =++SUM(L11:L12) -> 0 | M13: =++SUM(M11:M12) -> 0 | N13: =++SUM(N11:N12) -> 0 | O13: =++SUM(O11:O12) -> 0 | P13: =++SUM(P11:P12) -> 0 | ... AC13: =++SUM(AC11:AC12) -> 0
C16: 3M USD SOFR Curve | H16: 0 | I16: 0 | J16: 0 | K16: 0 | L16: 0 | M16: 0 | N16: 0 | O16: 0 | P16: 0 | Q16: 0 | R16: 0 | S16: 0 | T16: 0 | U16: 0 | V16: 0 | W16: 0 | X16: 0 | Y16: 0 | Z16: 0 | AA16: 0 | AB16: 0 | AC16: 0
C17: SOFR Floor | F17: 0.01 | H17: =++$F17 -> 0.01 | I17: =++$F17 -> 0.01 | J17: =++$F17 -> 0.01 | K17: =++$F17 -> 0.01 | L17: =++$F17 -> 0.01 | M17: =++$F17 -> 0.01 | N17: =++$F17 -> 0.01 | O17: =++$F17 -> 0.01 | ... AC17: =++$F17 -> 0.01
C18: Spread | F18: 0.055 | H18: =++$F18 -> 0.055 | I18: =++$F18 -> 0.055 | J18: =++$F18 -> 0.055 | K18: =++$F18 -> 0.055 | L18: =++$F18 -> 0.055 | M18: =++$F18 -> 0.055 | N18: =++$F18 -> 0.055 | O18: =++$F18 -> 0.055 | ... AC18: =++$F18 -> 0.055
C19: All-In Borrower Rate | H19: =++SUM(MAX(H16:H17),H18) -> 0.065 | I19: =++SUM(MAX(I16:I17),I18) -> 0.065 | J19: =++SUM(MAX(J16:J17),J18) -> 0.065 | K19: =++SUM(MAX(K16:K17),K18) -> 0.065 | L19: =++SUM(MAX(L16:L17),L18) -> 0.065 | M19: =++SUM(MAX(M16:M17),M18) -> 0.065 | N19: =++SUM(MAX(N16:N17),N18) -> 0.065 | O19: =++SUM(MAX(O16:O17),O18) -> 0.065 | ... AC19: =++SUM(MAX(AC16:AC17),AC18) -> 0.065
C22: Overland TLB Face Value | H22: =++-H13 -> 0
C23: ( + ) OID | F23: 0.02 | H23: =++-H22*$F23 -> 0
C24: ( + ) Borrower Interest Payments | I24: =++H13*YEARFRAC(H$2,I$2,2)*H19 -> 0 | J24: =++I13*YEARFRAC(I$2,J$2,2)*I19 -> 0 | K24: =++J13*YEARFRAC(J$2,K$2,2)*J19 -> 0 | L24: =++K13*YEARFRAC(K$2,L$2,2)*K19 -> 0 | M24: =++L13*YEARFRAC(L$2,M$2,2)*L19 -> 0 | N24: =++M13*YEARFRAC(M$2,N$2,2)*M19 -> 0 | O24: =++N13*YEARFRAC(N$2,O$2,2)*N19 -> 0 | P24: =++O13*YEARFRAC(O$2,P$2,2)*O19 -> 0 | ... AC24: =++AB13*YEARFRAC(AB$2,AC$2,2)*AB19 -> 0
C25: ( + ) Borrower Scheduled Principal Repayments | J25: =++-J12 -> 0 | K25: =++-K12 -> 0 | L25: =++-L12 -> 0 | M25: =++-M12 -> 0 | N25: =++-N12 -> 0 | O25: =++-O12 -> 0 | P25: =++-P12 -> 0 | Q25: =++-Q12 -> 0 | ... AC25: =++-AC12 -> 0
C26: Total Unlevered Cash Flows | H26: =++SUM(H22:H25) -> 0 | I26: =++SUM(I22:I25) -> 0 | J26: =++SUM(J22:J25) -> 0 | K26: =++SUM(K22:K25) -> 0 | L26: =++SUM(L22:L25) -> 0 | M26: =++SUM(M22:M25) -> 0 | N26: =++SUM(N22:N25) -> 0 | O26: =++SUM(O22:O25) -> 0 | ... AC26: =++SUM(AC22:AC25) -> 0
C28: Gross Unlevered MOIC | F28: =++IFERROR(SUM(I26:AC26)/-H26,0) -> 0
C29: Gross Unlevered IRR | F29: =++IFERROR(XIRR(H26:AC26,$H$2:$AC$2),0) -> 0
B32: x | C32: Overland Levered Returns
C34: Overland TLB Face Value (BoP) | I34: =++H36 -> 0 | J34: =++I36 -> 0 | K34: =++J36 -> 0 | L34: =++K36 -> 0 | M34: =++L36 -> 0 | N34: =++M36 -> 0 | O34: =++N36 -> 0 | P34: =++O36 -> 0 | ... AC34: =++AB36 -> 0
C35: ( – ) Amortization | F35: =++F$12 -> 0.01 | J35: =++-$H36*$F35/4 -> 0 | K35: =++-$H36*$F35/4 -> 0 | L35: =++-$H36*$F35/4 -> 0 | M35: =++-$H36*$F35/4 -> 0 | N35: =++-$H36*$F35/4 -> 0 | O35: =++-$H36*$F35/4 -> 0 | P35: =++-$H36*$F35/4 -> 0 | Q35: =++-$H36*$F35/4 -> 0 | ... AB35: =++-$H36*$F35/4 -> 0 | AC35: =++-AC34 -> 0
C36: Overland TLB Face Value (EoP) | H36: =++H13 -> 0 | I36: =++SUM(I34:I35) -> 0 | J36: =++SUM(J34:J35) -> 0 | K36: =++SUM(K34:K35) -> 0 | L36: =++SUM(L34:L35) -> 0 | M36: =++SUM(M34:M35) -> 0 | N36: =++SUM(N34:N35) -> 0 | O36: =++SUM(O34:O35) -> 0 | P36: =++SUM(P34:P35) -> 0 | ... AC36: =++SUM(AC34:AC35) -> 0
C39: 3M USD SOFR Curve | H39: =++H$16 -> 0 | I39: =++I$16 -> 0 | J39: =++J$16 -> 0 | K39: =++K$16 -> 0 | L39: =++L$16 -> 0 | M39: =++M$16 -> 0 | N39: =++N$16 -> 0 | O39: =++O$16 -> 0 | ... AC39: =++AC$16 -> 0
C40: SOFR Floor | F40: =++F$17 -> 0.01 | H40: =++$F40 -> 0.01 | I40: =++$F40 -> 0.01 | J40: =++$F40 -> 0.01 | K40: =++$F40 -> 0.01 | L40: =++$F40 -> 0.01 | M40: =++$F40 -> 0.01 | N40: =++$F40 -> 0.01 | O40: =++$F40 -> 0.01 | ... AC40: =++$F40 -> 0.01
C41: Spread | F41: =++F$18 -> 0.055 | H41: =++$F41 -> 0.055 | I41: =++$F41 -> 0.055 | J41: =++$F41 -> 0.055 | K41: =++$F41 -> 0.055 | L41: =++$F41 -> 0.055 | M41: =++$F41 -> 0.055 | N41: =++$F41 -> 0.055 | O41: =++$F41 -> 0.055 | ... AC41: =++$F41 -> 0.055
C42: All-In Borrower Rate | H42: =++SUM(MAX(H39:H40),H41) -> 0.065 | I42: =++SUM(MAX(I39:I40),I41) -> 0.065 | J42: =++SUM(MAX(J39:J40),J41) -> 0.065 | K42: =++SUM(MAX(K39:K40),K41) -> 0.065 | L42: =++SUM(MAX(L39:L40),L41) -> 0.065 | M42: =++SUM(MAX(M39:M40),M41) -> 0.065 | N42: =++SUM(MAX(N39:N40),N41) -> 0.065 | O42: =++SUM(MAX(O39:O40),O41) -> 0.065 | ... AC42: =++SUM(MAX(AC39:AC40),AC41) -> 0.065
C45: 3M USD SOFR Curve | H45: =++H$16 -> 0 | I45: =++I$16 -> 0 | J45: =++J$16 -> 0 | K45: =++K$16 -> 0 | L45: =++L$16 -> 0 | M45: =++M$16 -> 0 | N45: =++N$16 -> 0 | O45: =++O$16 -> 0 | ... AC45: =++AC$16 -> 0
C46: SOFR Floor | F46: 0 | H46: =++$F46 -> 0 | I46: =++$F46 -> 0 | J46: =++$F46 -> 0 | K46: =++$F46 -> 0 | L46: =++$F46 -> 0 | M46: =++$F46 -> 0 | N46: =++$F46 -> 0 | O46: =++$F46 -> 0 | ... AC46: =++$F46 -> 0
C47: Spread | H47: =++INDEX($AG$91:$AG$97,MATCH(H$2,$AF$91:$AF$97,-1)) -> 0.0235 | I47: =++INDEX($AG$91:$AG$97,MATCH(I$2,$AF$91:$AF$97,-1)) -> 0.0235 | J47: =++INDEX($AG$91:$AG$97,MATCH(J$2,$AF$91:$AF$97,-1)) -> 0.0235 | K47: =++INDEX($AG$91:$AG$97,MATCH(K$2,$AF$91:$AF$97,-1)) -> 0.0235 | L47: =++INDEX($AG$91:$AG$97,MATCH(L$2,$AF$91:$AF$97,-1)) -> 0.0235 | M47: =++INDEX($AG$91:$AG$97,MATCH(M$2,$AF$91:$AF$97,-1)) -> 0.0235 | N47: =++INDEX($AG$91:$AG$97,MATCH(N$2,$AF$91:$AF$97,-1)) -> 0.0235 | O47: =++INDEX($AG$91:$AG$97,MATCH(O$2,$AF$91:$AF$97,-1)) -> 0.0235 | ... AC47: =++INDEX($AG$91:$AG$97,MATCH(AC$2,$AF$91:$AF$97,-1)) -> 0.0285
C48: All-In Overland Backleverage Rate | I48: =++SUM(MAX(AVERAGE(H45:I45),I46),I47) -> 0.0235 | J48: =++SUM(MAX(AVERAGE(I45:J45),J46),J47) -> 0.0235 | K48: =++SUM(MAX(AVERAGE(J45:K45),K46),K47) -> 0.0235 | L48: =++SUM(MAX(AVERAGE(K45:L45),L46),L47) -> 0.0235 | M48: =++SUM(MAX(AVERAGE(L45:M45),M46),M47) -> 0.0235 | N48: =++SUM(MAX(AVERAGE(M45:N45),N46),N47) -> 0.0235 | O48: =++SUM(MAX(AVERAGE(N45:O45),O46),O47) -> 0.0235 | P48: =++SUM(MAX(AVERAGE(O45:P45),P46),P47) -> 0.0235 | ... AC48: =++SUM(MAX(AVERAGE(AB45:AC45),AC46),AC47) -> 0.0285
C51: Borrower Opening SNL | F51: =++SUCAP!J36 -> 0 | H51: =++IFERROR(INDEX($AG$76:$AG$79,MATCH($F51,$AF$76:$AF$79,-1)),$AG$76) -> 0.65 | I51: =++IFERROR(INDEX($AG$76:$AG$79,MATCH($F51,$AF$76:$AF$79,-1)),$AG$76) -> 0.65 | J51: =++IFERROR(INDEX($AG$76:$AG$79,MATCH($F51,$AF$76:$AF$79,-1)),$AG$76) -> 0.65 | K51: =++IFERROR(INDEX($AG$76:$AG$79,MATCH($F51,$AF$76:$AF$79,-1)),$AG$76) -> 0.65 | L51: =++IFERROR(INDEX($AG$76:$AG$79,MATCH($F51,$AF$76:$AF$79,-1)),$AG$76) -> 0.65 | M51: =++IFERROR(INDEX($AG$76:$AG$79,MATCH($F51,$AF$76:$AF$79,-1)),$AG$76) -> 0.65 | N51: =++IFERROR(INDEX($AG$76:$AG$79,MATCH($F51,$AF$76:$AF$79,-1)),$AG$76) -> 0.65 | O51: =++IFERROR(INDEX($AG$76:$AG$79,MATCH($F51,$AF$76:$AF$79,-1)),$AG$76) -> 0.65 | ... AC51: =++IFERROR(INDEX($AG$76:$AG$79,MATCH($F51,$AF$76:$AF$79,-1)),$AG$76) -> 0.65
C52: Facility Type | F52: Uni | H52: =++INDEX($AG$82:$AG$86,MATCH($F52,$AF$82:$AF$86,0)) -> 0.6 | I52: =++INDEX($AG$82:$AG$86,MATCH($F52,$AF$82:$AF$86,0)) -> 0.6 | J52: =++INDEX($AG$82:$AG$86,MATCH($F52,$AF$82:$AF$86,0)) -> 0.6 | K52: =++INDEX($AG$82:$AG$86,MATCH($F52,$AF$82:$AF$86,0)) -> 0.6 | L52: =++INDEX($AG$82:$AG$86,MATCH($F52,$AF$82:$AF$86,0)) -> 0.6 | M52: =++INDEX($AG$82:$AG$86,MATCH($F52,$AF$82:$AF$86,0)) -> 0.6 | N52: =++INDEX($AG$82:$AG$86,MATCH($F52,$AF$82:$AF$86,0)) -> 0.6 | O52: =++INDEX($AG$82:$AG$86,MATCH($F52,$AF$82:$AF$86,0)) -> 0.6 | ... AC52: =++INDEX($AG$82:$AG$86,MATCH($F52,$AF$82:$AF$86,0)) -> 0.6
C53: Overland Advance Rate | H53: =++MIN(H51:H52) -> 0.6 | I53: =++MIN(I51:I52) -> 0.6 | J53: =++MIN(J51:J52) -> 0.6 | K53: =++MIN(K51:K52) -> 0.6 | L53: =++MIN(L51:L52) -> 0.6 | M53: =++MIN(M51:M52) -> 0.6 | N53: =++MIN(N51:N52) -> 0.6 | O53: =++MIN(O51:O52) -> 0.6 | ... AC53: =++MIN(AC51:AC52) -> 0.6
C56: Overland MS Funding | F56: =+(1.1/2.1*H13)/H53 -> 0 | H56: =++$F56 -> 0 | I56: =++$F56 -> 0 | J56: =++$F56 -> 0 | K56: =++$F56 -> 0 | L56: =++$F56 -> 0 | M56: =++$F56 -> 0 | N56: =++$F56 -> 0 | O56: =++$F56 -> 0 | ... AC56: =++$F56 -> 0
C57: =++"( x ) "&C53 -> ( x ) Overland Advance Rate | H57: =++H53 -> 0.6 | I57: =++I53 -> 0.6 | J57: =++J53 -> 0.6 | K57: =++K53 -> 0.6 | L57: =++L53 -> 0.6 | M57: =++M53 -> 0.6 | N57: =++N53 -> 0.6 | O57: =++O53 -> 0.6 | ... AC57: =++AC53 -> 0.6
C58: Overland Closing Backleverage | H58: =++H56*H57 -> 0 | I58: =++I56*I57 -> 0 | J58: =++J56*J57 -> 0 | K58: =++K56*K57 -> 0 | L58: =++L56*L57 -> 0 | M58: =++M56*M57 -> 0 | N58: =++N56*N57 -> 0 | O58: =++O56*O57 -> 0 | ... AC58: =++AC56*AC57 -> 0
C61: Overland TLB Face Value | H61: =++-H36 -> 0
C62: ( + ) OID | F62: =++F$23 -> 0.02 | H62: =++-H61*$F62 -> 0
...
