Workbook
Name FinChartType: Dashboard!$AC$2
Name FYEDate: Dashboard!$E$11
Name IQ_CH: 110000
Name IQ_CQ: 5000
Name IQ_CY: 10000
Name IQ_DAILY: 500000
Name IQ_FH: 100000
Name IQ_FQ: 500
Name IQ_FY: 1000
Name IQ_LTM: 2000
Name IQ_MONTH: 15000
Name IQ_NTM: 6000
Name IQ_WEEK: 50000
Name IQ_YTD: 3000
Name LTMDate: Dashboard!$AC$1

Sheet _CIQHiddenCacheSheet
A1: 25 | B1: BAABTAVMT0NBTAFI/////wFQdgAAADFDSVEuQkRSQkYuSVFfRElMVVRfRVBTX0VYQ0wuMjAwMC4xMi8zMS8yMDIzLi4uVVNEAQAAAKSbCgACAAAAAzQuNwEIAAAABQAAAAExAQAAAAstMjAxMTM1MDkzNwMAAAADMTYwAgAAAAMxNDIEAAAAATAHAAAACjEyLzMxLzIwMjMIAAAACjEyLzMxLzIwMjMJAAAAATDFOMGuxNfcCHJSy67E19wIL0NJUS5SVFguSVFfRElMVVRfRVBTX0VYQ0wuMjAwMC4xMi8zMS8yMDIzLi4uVVNEAQAAAP5tAgACAAAABDIuMjMBCAAAAAUAAAABMQEAAAALLTIwMTE2NzU4NjQDAAAAAzE2MAIAAAADMTQyBAAAAAEwBwAAAAoxMi8zMS8yMDIzCAAAAAoxMi8zMS8yMDIzCQAAAAEwxTjBrsTX3AiK5MyuxNfcCC9DSVEuSFdNLklRX0RJTFVUX0VQU19FWENMLjIwMDAuMTIvMzEvMjAyMy4uLlVTRAEAAAAKsc8YAgAAAAQxLjgzAQgAAAAFAAAAATEBAAAACy0yMDEwMzM3OTcyAwAAAAMxNjACAAAAAzE0MgQAAAABMAcAAAAKMTIvMzEvMjAyMwgAAAAKMTIvMzEvMjAyMwkAAAABMMU4wa7E19wIS8HMrsTX3AgvQ0lRLlRYVC5JUV9ESUxVVF9FUFNfRVhDTC4yMDAwLjEyLzMxLzIwMjMuLi5VU0QBAAAA54kAAAIAAAAENC41NwEIAAAABQAAAAExAQAAAAstMjAxMDc5MDQ2NgMAAAADMTYwAgAAAAMxNDIEAAAAATAHAAAACjEyLzMxLzIwMjMIAAAACjEyLzMwLzIwMjMJAAAAATDFOMGuxNfcCEvB | C1: zK7E19wIL0NJUS5IWEwuSVFfRElMVVRfRVBTX0VYQ0wuMjAwMC4xMi8zMS8yMDIzLi4uVVNEAQAAAPE/BAACAAAABDEuMjQBCAAAAAUAAAABMQEAAAALLTIwMTEzOTc2OTgDAAAAAzE2MAIAAAADMTQyBAAAAAEwBwAAAAoxMi8zMS8yMDIzCAAAAAoxMi8zMS8yMDIzCQAAAAEwxTjBrsTX3AhyUsuuxNfcCC9DSVEuSEVJLklRX0RJTFVUX0VQU19FWENMLjIwMDAuMTIvMzEvMjAyMy4uLlVTRAEAAAB/PgQAAgAAAAQyLjkxAQgAAAAFAAAAATEBAAAACy0yMDE0NTE2MDgyAwAAAAMxNjACAAAAAzE0MgQAAAABMAcAAAAKMTIvMzEvMjAyMwgAAAAKMTAvMzEvMjAyMwkAAAABMMU4wa7E19wIclLLrsTX3AgvQ0lRLlNQUi5JUV9ESUxVVF9FUFNfRVhDTC4yMDAwLjEyLzMxLzIwMjMuLi5VU0QBAAAAax6pAQIAAAAJLTUuNzgwNDg3AQgAAAAFAAAAATEBAAAACy0yMDA5MDgzMzE3AwAAAAMxNjACAAAAAzE0MgQAAAABMAcAAAAKMTIvMzEvMjAyMwgAAAAKMTIvMzEvMjAyMwkAAAABMMU4wa7E19wIclLLrsTX3AgvQ0lRLkVSSi5JUV9ESUxVVF9FUFNfRVhDTC4yMDAwLjEyLzMxLzIwMjMuLi5VU0QBAAAAx24KAAIAAAAIMC4yMTk4MTMBCAAAAAUAAAABMQEAAAALLTIwMDU1NTcxMjMDAAAAAzE2MAIAAAADMTQyBAAAAAEwBwAAAAoxMi8zMS8yMDIzCAAAAAoxMi8zMS8yMDIzCQAAAAEwxTjBrsTX3AhyUsuuxNfcCC5D | D1: SVEuQkEuSVFfRElMVVRfRVBTX0VYQ0wuMjAwMC4xMi8zMS8yMDIzLi4uVVNEAQAAAKmoBQACAAAABS0zLjY3AQgAAAAFAAAAATEBAAAACy0yMDEyMDQ5NTA4AwAAAAMxNjACAAAAAzE0MgQAAAABMAcAAAAKMTIvMzEvMjAyMwgAAAAKMTIvMzEvMjAyMwkAAAABMMU4wa7E19wIS8HMrsTX3AgvQ0lRLldXRC5JUV9ESUxVVF9FUFNfRVhDTC4yMDAwLjEyLzMxLzIwMjMuLi5VU0QBAAAAQs0EAAIAAAAINC43NDUzNDUBCAAAAAUAAAABMQEAAAALLTIwMTE4MTI3OTkDAAAAAzE2MAIAAAADMTQyBAAAAAEwBwAAAAoxMi8zMS8yMDIzCAAAAAoxMi8zMS8yMDIzCQAAAAEwxTjBrsTX3AhyUsuuxNfcCC9DSVEuVERHLklRX0RJTFVUX0VQU19FWENMLjIwMDAuMTIvMzEvMjAyMy4uLlVTRAEAAAA051sBAgAAAAkyMy41NTcxMDUBCAAAAAUAAAABMQEAAAALLTIwMTEyNDg3NjQDAAAAAzE2MAIAAAADMTQyBAAAAAEwBwAAAAoxMi8zMS8yMDIzCAAAAAoxMi8zMC8yMDIzCQAAAAEwxTjBrsTX3AhLwcyuxNfcCC5DSVEuQ1cuSVFfRElMVVRfRVBTX0VYQ0wuMjAwMC4xMi8zMS8yMDIzLi4uVVNEAQAAAKoMBAACAAAAAzkuMgEIAAAABQAAAAExAQAAAAstMjAwOTU2MjM0OAMAAAADMTYwAgAAAAMxNDIEAAAAATAHAAAACjEyLzMxLzIwMjMIAAAACjEyLzMxLzIwMjMJAAAAATDFOMGuxNfcCHJSy67E19wIL0NJUS5MTVQuSVFf | E1: RElMVVRfRVBTX0VYQ0wuMjAwMC4xMi8zMS8yMDIzLi4uVVNEAQAAAINcBAACAAAABTI3LjU1AQgAAAAFAAAAATEBAAAACy0yMDEyNjg0MjQ2AwAAAAMxNjACAAAAAzE0MgQAAAABMAcAAAAKMTIvMzEvMjAyMwgAAAAKMTIvMzEvMjAyMwkAAAABMMU4wa7E19wIiuTMrsTX3AgxQ0lRLk1PRy9BLklRX0RJTFVUX0VQU19FWENMLjIwMDAuMTIvMzEvMjAyMy4uLlVTRAEAAABUawQAAgAAAAg1LjM4MTM2MgEIAAAABQAAAAExAQAAAAstMjAxMTc1Njg5NAMAAAADMTYwAgAAAAMxNDIEAAAAATAHAAAACjEyLzMxLzIwMjMIAAAACjEyLzMwLzIwMjMJAAAAATDFOMGuxNfcCHJSy67E19wIFENJUS4uSVFfQ09NUEFOWV9OQU1FBQAAAAAAAAAIAAAAFChJbnZhbGlkIElkZW50aWZpZXIpxTjBrsTX3AiK5MyuxNfcCB1DSVEuUlRYLklRX1RFVi4xMi8zMS8yMDIzLlVTRAEAAAD+bQIAAgAAAA0xNTM2OTAuOTQyNDY5AQYAAAAFAAAAATEBAAAACy0yMDIzMTQyNTI0AwAAAAMxNjACAAAABjEwMDA2MAQAAAABMAcAAAAKMTIvMzEvMjAyM8U4wa7E19wIiuTMrsTX3AgdQ0lRLkxNVC5JUV9URVYuMTIvMzEvMjAyMy5VU0QBAAAAg1wEAAIAAAANMTI2Mjg2LjI2MTU4NgEGAAAABQAAAAExAQAAAAstMjAyMzgxOTMxOQMAAAADMTYwAgAAAAYxMDAwNjAEAAAAATAHAAAACjEyLzMxLzIwMjPFOMGuxNfcCJ2Vza7E19wIHENJUS5C | F1: QS5JUV9URVYuMTIvMzEvMjAyMy5VU0QBAAAAqagFAAIAAAANMTk2NjA1LjI1MTkwNgEGAAAABQAAAAExAQAAAAstMjAyMjk5NzExNgMAAAADMTYwAgAAAAYxMDAwNjAEAAAAATAHAAAACjEyLzMxLzIwMjPFOMGuxNfcCCXLFK/E19wIHUNJUS5UREcuSVFfVEVWLjEyLzMxLzIwMjMuVVNEAQAAADTnWwECAAAADDcyMjQ0Ljc0NzYwNgEGAAAABQAAAAExAQAAAAstMjAyMDExNDk3MwMAAAADMTYwAgAAAAYxMDAwNjAEAAAAATAHAAAACjEyLzMxLzIwMjPFOMGuxNfcCBW9za7E19wIHUNJUS5IV00uSVFfVEVWLjEyLzMxLzIwMjMuVVNEAQAAAAqxzxgCAAAADDI1ODIzLjYwNDQzOAEGAAAABQAAAAExAQAAAAstMjAyMTQwMDg3NQMAAAADMTYwAgAAAAYxMDAwNjAEAAAAATAHAAAACjEyLzMxLzIwMjPFOMGuxNfcCCnkza7E19wIHUNJUS5UWFQuSVFfVEVWLjEyLzMxLzIwMjMuVVNEAQAAAOeJAAACAAAADDE3OTk0Ljc1ODg1MQEGAAAABQAAAAExAQAAAAstMjAyMjczNjIwNwMAAAADMTYwAgAAAAYxMDAwNjAEAAAAATAHAAAACjEyLzMxLzIwMjPFOMGuxNfcCKoyzq7E19wIHUNJUS5IRUkuSVFfVEVWLjEyLzMxLzIwMjMuVVNEAQAAAH8+BAACAAAADDI0NTMwLjc1MjQ3MgEGAAAABQAAAAExAQAAAAstMjAxNDUxNjA4NAMAAAADMTYwAgAAAAYxMDAwNjAEAAAAATAHAAAACjEyLzMxLzIwMjPFOMGuxNfcCIkLzq7E | G1: 19wIHENJUS5DVy5JUV9URVYuMTIvMzEvMjAyMy5VU0QBAAAAqgwEAAIAAAALOTUzOC45ODQ5NTgBBgAAAAUAAAABMQEAAAALLTIwMjE0MDA4NDMDAAAAAzE2MAIAAAAGMTAwMDYwBAAAAAEwBwAAAAoxMi8zMS8yMDIzxTjBrsTX3AiqMs6uxNfcCB1DSVEuV1dELklRX1RFVi4xMi8zMS8yMDIzLlVTRAEAAABCzQQAAgAAAAo4Nzg1LjA2MTk4AQYAAAAFAAAAATEBAAAACy0yMDE4MjMzNTM5AwAAAAMxNjACAAAABjEwMDA2MAQAAAABMAcAAAAKMTIvMzEvMjAyM8U4wa7E19wIqjLOrsTX3AgdQ0lRLkhYTC5JUV9URVYuMTIvMzEvMjAyMy5VU0QBAAAA8T8EAAIAAAALNjg1OS43MDc5MzIBBgAAAAUAAAABMQEAAAALLTIwMjMwOTEzNzEDAAAAAzE2MAIAAAAGMTAwMDYwBAAAAAEwBwAAAAoxMi8zMS8yMDIzxTjBrsTX3AiqMs6uxNfcCB1DSVEuU1BSLklRX1RFVi4xMi8zMS8yMDIzLlVTRAEAAABrHqkBAgAAAAs3Mjg1LjM5MDQ4NQEGAAAABQAAAAExAQAAAAstMjAyMTI0Nzk2MAMAAAADMTYwAgAAAAYxMDAwNjAEAAAAATAHAAAACjEyLzMxLzIwMjPFOMGuxNfcCKoyzq7E19wIH0NJUS5NT0cvQS5JUV9URVYuMTIvMzEvMjAyMy5VU0QBAAAAVGsEAAIAAAALNTgyNS4wNTYxMjcBBgAAAAUAAAABMQEAAAALLTIwMTkxODU3MzADAAAAAzE2MAIAAAAGMTAwMDYwBAAAAAEwBwAAAAoxMi8zMS8yMDIzxTjBrsTX3Aiq | H1: Ms6uxNfcCB9DSVEuQkRSQkYuSVFfVEVWLjEyLzMxLzIwMjMuVVNEAQAAAKSbCgACAAAAEDkzNjQuMDE1MjM4MjIxMTcBBgAAAAUAAAABMQEAAAALLTIwMjE2NTkzNTkDAAAAAzE2MAIAAAAGMTAwMDYwBAAAAAEwBwAAAAoxMi8zMS8yMDIzxTjBrsTX3AiqMs6uxNfcCB1DSVEuRVJKLklRX1RFVi4xMi8zMS8yMDIzLlVTRAEAAADHbgoAAgAAABA1MDQ5Ljc0NTE4NjY5MTMzAQYAAAAFAAAAATEBAAAACy0yMDIwNDA0NzE1AwAAAAMxNjACAAAABjEwMDA2MAQAAAABMAcAAAAKMTIvMzEvMjAyM8U4wa7E19wISurOrsTX3AgnQ0lRLlJUWC5JUV9MQVNUU0FMRVBSSUNFLjEyLzMxLzIwMjMuVVNEAQAAAP5tAgACAAAABTg0LjE0AMU4wa7E19wIiuTMrsTX3AgnQ0lRLkxNVC5JUV9MQVNUU0FMRVBSSUNFLjEyLzMxLzIwMjMuVVNEAQAAAINcBAACAAAABjQ1My4yNADFOMGuxNfcCIrkzK7E19wIJkNJUS5CQS5JUV9MQVNUU0FMRVBSSUNFLjEyLzMxLzIwMjMuVVNEAQAAAKmoBQACAAAABjI2MC42NgDFOMGuxNfcCEvBzK7E19wIJ0NJUS5UREcuSVFfTEFTVFNBTEVQUklDRS4xMi8zMS8yMDIzLlVTRAEAAAA051sBAgAAAAYxMDExLjYAxTjBrsTX3AhLwcyuxNfcCCdDSVEuSFdNLklRX0xBU1RTQUxFUFJJQ0UuMTIvMzEvMjAyMy5VU0QBAAAACrHPGAIAAAAFNTQuMTIAxTjBrsTX3AhLwcyuxNfcCCdDSVEuVFhULklR | I1: X0xBU1RTQUxFUFJJQ0UuMTIvMzEvMjAyMy5VU0QBAAAA54kAAAIAAAAFODAuNDIAxTjBrsTX3AhLwcyuxNfcCCdDSVEuSEVJLklRX0xBU1RTQUxFUFJJQ0UuMTIvMzEvMjAyMy5VU0QBAAAAfz4EAAIAAAAGMTc4Ljg3AMU4wa7E19wIclLLrsTX3AgmQ0lRLkNXLklRX0xBU1RTQUxFUFJJQ0UuMTIvMzEvMjAyMy5VU0QBAAAAqgwEAAIAAAAGMjIyLjc5AMU4wa7E19wIclLLrsTX3AgnQ0lRLldXRC5JUV9MQVNUU0FMRVBSSUNFLjEyLzMxLzIwMjMuVVNEAQAAAELNBAACAAAABjEzNi4xMwDFOMGuxNfcCHJSy67E19wIJ0NJUS5IWEwuSVFfTEFTVFNBTEVQUklDRS4xMi8zMS8yMDIzLlVTRAEAAADxPwQAAgAAAAU3My43NQDFOMGuxNfcCHJSy67E19wIJ0NJUS5TUFIuSVFfTEFTVFNBTEVQUklDRS4xMi8zMS8yMDIzLlVTRAEAAABrHqkBAgAAAAUzMS43OADFOMGuxNfcCHJSy67E19wIKUNJUS5NT0cvQS5JUV9MQVNUU0FMRVBSSUNFLjEyLzMxLzIwMjMuVVNEAQAAAFRrBAADAAAAAADFOMGuxNfcCHJSy67E19wIKUNJUS5CRFJCRi5JUV9MQVNUU0FMRVBSSUNFLjEyLzMxLzIwMjMuVVNEAQAAAKSbCgADAAAAAADFOMGuxNfcCHJSy67E19wIJ0NJUS5FUkouSVFfTEFTVFNBTEVQUklDRS4xMi8zMS8yMDIzLlVTRAEAAADHbgoAAgAAAAUxOC40NQDFOMGuxNfcCHJSy67E19wIGkNJUS4uSVFfVEVWLjEyLzMxLzIw | J1: MjMuVVNEBQAAAAEAAAAIAAAAFChJbnZhbGlkIElkZW50aWZpZXIpNS0Nr8TX3Ag1LQ2vxNfcCCBDSVEuLklRX01BUktFVENBUC4xMi8zMS8yMDIzLlVTRAUAAAABAAAACAAAABQoSW52YWxpZCBJZGVudGlmaWVyKTUtDa/E19wINS0Nr8TX3AgnQ0lRLi5JUV9UT1RBTF9SRVYuMjAwMC4xMi8zMS8yMDIzLi4uVVNEBQAAAAEAAAAIAAAAFChJbnZhbGlkIElkZW50aWZpZXIpNS0Nr8TX3Ag1LQ2vxNfcCCRDSVEuLklRX0VCSVREQS4yMDAwLjEyLzMxLzIwMjMuLi5VU0QFAAAAAQAAAAgAAAAUKEludmFsaWQgSWRlbnRpZmllcik1LQ2vxNfcCDUtDa/E19wILkNJUS4uSVFfVE9UQUxfUkVWXzVZUl9BTk5fQ0FHUi4yMDAwLjEyLzMxLzIwMjMFAAAAAQAAAAgAAAAUKEludmFsaWQgSWRlbnRpZmllcik1LQ2vxNfcCDUtDa/E19wIFkNJUS5CQS5JUV9DT01QQU5ZX05BTUUBAAAAqagFAAMAAAASVGhlIEJvZWluZyBDb21wYW55ADUtDa/E19wIJcsUr8TX3AgXQ0lRLlJUWC5JUV9DT01QQU5ZX05BTUUBAAAA/m0CAAMAAAAPUlRYIENvcnBvcmF0aW9uADUtDa/E19wIJcsUr8TX3AgXQ0lRLkxNVC5JUV9DT01QQU5ZX05BTUUBAAAAg1wEAAMAAAAbTG9ja2hlZWQgTWFydGluIENvcnBvcmF0aW9uADUtDa/E19wIJcsUr8TX3AgXQ0lRLlRERy5JUV9DT01QQU5ZX05BTUUBAAAANOdbAQMAAAAcVHJhbnNEaWdtIEdyb3Vw | K1: IEluY29ycG9yYXRlZAA1LQ2vxNfcCCXLFK/E19wIF0NJUS5IV00uSVFfQ09NUEFOWV9OQU1FAQAAAAqxzxgDAAAAFUhvd21ldCBBZXJvc3BhY2UgSW5jLgA1LQ2vxNfcCCXLFK/E19wIF0NJUS5IRUkuSVFfQ09NUEFOWV9OQU1FAQAAAH8+BAADAAAAEUhFSUNPIENvcnBvcmF0aW9uADUtDa/E19wI0scUr8TX3AgXQ0lRLlRYVC5JUV9DT01QQU5ZX05BTUUBAAAA54kAAAMAAAAMVGV4dHJvbiBJbmMuADUtDa/E19wI3rAUr8TX3AgWQ0lRLkNXLklRX0NPTVBBTllfTkFNRQEAAACqDAQAAwAAABpDdXJ0aXNzLVdyaWdodCBDb3Jwb3JhdGlvbgA1LQ2vxNfcCN6wFK/E19wIGUNJUS5CRFJCRi5JUV9DT01QQU5ZX05BTUUBAAAApJsKAAMAAAAPQm9tYmFyZGllciBJbmMuADUtDa/E19wI3rAUr8TX3AgXQ0lRLldXRC5JUV9DT01QQU5ZX05BTUUBAAAAQs0EAAMAAAAOV29vZHdhcmQsIEluYy4ANS0Nr8TX3AjesBSvxNfcCBdDSVEuU1BSLklRX0NPTVBBTllfTkFNRQEAAABrHqkBAwAAACFTcGlyaXQgQWVyb1N5c3RlbXMgSG9sZGluZ3MsIEluYy4ANS0Nr8TX3AjesBSvxNfcCBdDSVEuSFhMLklRX0NPTVBBTllfTkFNRQEAAADxPwQAAwAAABJIZXhjZWwgQ29ycG9yYXRpb24ANS0Nr8TX3AjesBSvxNfcCBlDSVEuTU9HL0EuSVFfQ09NUEFOWV9OQU1FAQAAAFRrBAADAAAACU1vb2cgSW5jLgA1LQ2vxNfcCN6wFK/E | L1: 19wIF0NJUS5FUkouSVFfQ09NUEFOWV9OQU1FAQAAAMduCgADAAAADEVtYnJhZXIgUy5BLgA1LQ2vxNfcCE6JFK/E19wIMENJUS5CQS5JUV9UT1RBTF9SRVZfNVlSX0FOTl9DQUdSLjIwMDAuMTIvMzEvMjAyMwEAAACpqAUAAgAAAAYtNS4xMTEBCAAAAAUAAAABMQEAAAALLTIwMTIwNDk1MDgDAAAAAzE2MAIAAAAENDIzMwQAAAABMAcAAAAKMTIvMzEvMjAyMwgAAAAKMTIvMzEvMjAyMwkAAAABMDUtDa/E19wIJcsUr8TX3AgmQ0lRLkJBLklRX0VCSVREQS4yMDAwLjEyLzMxLzIwMjMuLi5VU0QBAAAAqagFAAIAAAAEMzE1NAEIAAAABQAAAAExAQAAAAstMjAxMjA0OTUwOAMAAAADMTYwAgAAAAQ0MDUxBAAAAAEwBwAAAAoxMi8zMS8yMDIzCAAAAAoxMi8zMS8yMDIzCQAAAAEwNS0Nr8TX3AglyxSvxNfcCClDSVEuQkEuSVFfVE9UQUxfUkVWLjIwMDAuMTIvMzEvMjAyMy4uLlVTRAEAAACpqAUAAgAAAAU3Nzc5NAEIAAAABQAAAAExAQAAAAstMjAxMjA0OTUwOAMAAAADMTYwAgAAAAIyOAQAAAABMAcAAAAKMTIvMzEvMjAyMwgAAAAKMTIvMzEvMjAyMwkAAAABMDUtDa/E19wIJcsUr8TX3AgqQ0lRLlJUWC5JUV9UT1RBTF9SRVYuMjAwMC4xMi8zMS8yMDIzLi4uVVNEAQAAAP5tAgACAAAABTY4OTIwAQgAAAAFAAAAATEBAAAACy0yMDExNjc1ODY0AwAAAAMxNjACAAAAAjI4BAAAAAEwBwAAAAoxMi8zMS8yMDIz | M1: CAAAAAoxMi8zMS8yMDIzCQAAAAEwNS0Nr8TX3AglyxSvxNfcCCdDSVEuUlRYLklRX0VCSVREQS4yMDAwLjEyLzMxLzIwMjMuLi5VU0QBAAAA/m0CAAIAAAAEOTYxMQEIAAAABQAAAAExAQAAAAstMjAxMTY3NTg2NAMAAAADMTYwAgAAAAQ0MDUxBAAAAAEwBwAAAAoxMi8zMS8yMDIzCAAAAAoxMi8zMS8yMDIzCQAAAAEwNS0Nr8TX3AglyxSvxNfcCDFDSVEuUlRYLklRX1RPVEFMX1JFVl81WVJfQU5OX0NBR1IuMjAwMC4xMi8zMS8yMDIzAQAAAP5tAgACAAAABzE0LjcwOTgBCAAAAAUAAAABMQEAAAALLTIwMTE2NzU4NjQDAAAAAzE2MAIAAAAENDIzMwQAAAABMAcAAAAKMTIvMzEvMjAyMwgAAAAKMTIvMzEvMjAyMwkAAAABMDUtDa/E19wIJcsUr8TX3AgqQ0lRLkxNVC5JUV9UT1RBTF9SRVYuMjAwMC4xMi8zMS8yMDIzLi4uVVNEAQAAAINcBAACAAAABTY3NTcxAQgAAAAFAAAAATEBAAAACy0yMDEyNjg0MjQ2AwAAAAMxNjACAAAAAjI4BAAAAAEwBwAAAAoxMi8zMS8yMDIzCAAAAAoxMi8zMS8yMDIzCQAAAAEwNS0Nr8TX3AglyxSvxNfcCCdDSVEuTE1ULklRX0VCSVREQS4yMDAwLjEyLzMxLzIwMjMuLi5VU0QBAAAAg1wEAAIAAAAFMTAyMjUBCAAAAAUAAAABMQEAAAALLTIwMTI2ODQyNDYDAAAAAzE2MAIAAAAENDA1MQQAAAABMAcAAAAKMTIvMzEvMjAyMwgAAAAKMTIvMzEvMjAyMwkAAAABMDUtDa/E19wI | N1: JcsUr8TX3AgxQ0lRLkxNVC5JUV9UT1RBTF9SRVZfNVlSX0FOTl9DQUdSLjIwMDAuMTIvMzEvMjAyMwEAAACDXAQAAgAAAAY0LjY3ODQBCAAAAAUAAAABMQEAAAALLTIwMTI2ODQyNDYDAAAAAzE2MAIAAAAENDIzMwQAAAABMAcAAAAKMTIvMzEvMjAyMwgAAAAKMTIvMzEvMjAyMwkAAAABMDUtDa/E19wIJcsUr8TX3AgqQ0lRLlRERy5JUV9UT1RBTF9SRVYuMjAwMC4xMi8zMS8yMDIzLi4uVVNEAQAAADTnWwECAAAABDY5NzcBCAAAAAUAAAABMQEAAAALLTIwMTEyNDg3NjQDAAAAAzE2MAIAAAACMjgEAAAAATAHAAAACjEyLzMxLzIwMjMIAAAACjEyLzMwLzIwMjMJAAAAATA1LQ2vxNfcCCXLFK/E19wIJ0NJUS5UREcuSVFfRUJJVERBLjIwMDAuMTIvMzEvMjAyMy4uLlVTRAEAAAA051sBAgAAAAQzNDE2AQgAAAAFAAAAATEBAAAACy0yMDExMjQ4NzY0AwAAAAMxNjACAAAABDQwNTEEAAAAATAHAAAACjEyLzMxLzIwMjMIAAAACjEyLzMwLzIwMjMJAAAAATA1LQ2vxNfcCCXLFK/E19wIMUNJUS5UREcuSVFfVE9UQUxfUkVWXzVZUl9BTk5fQ0FHUi4yMDAwLjEyLzMxLzIwMjMBAAAANOdbAQIAAAAHMTIuMDE1NwEIAAAABQAAAAExAQAAAAstMjAxMTI0ODc2NAMAAAADMTYwAgAAAAQ0MjMzBAAAAAEwBwAAAAoxMi8zMS8yMDIzCAAAAAoxMi8zMC8yMDIzCQAAAAEwNS0Nr8TX3AglyxSvxNfcCCpDSVEuSFdNLklR | O1: X1RPVEFMX1JFVi4yMDAwLjEyLzMxLzIwMjMuLi5VU0QBAAAACrHPGAIAAAAENjY0MAEIAAAABQAAAAExAQAAAAstMjAxMDMzNzk3MgMAAAADMTYwAgAAAAIyOAQAAAABMAcAAAAKMTIvMzEvMjAyMwgAAAAKMTIvMzEvMjAyMwkAAAABMDUtDa/E19wI0scUr8TX3AgnQ0lRLkhXTS5JUV9FQklUREEuMjAwMC4xMi8zMS8yMDIzLi4uVVNEAQAAAAqxzxgCAAAABDE0NTcBCAAAAAUAAAABMQEAAAALLTIwMTAzMzc5NzIDAAAAAzE2MAIAAAAENDA1MQQAAAABMAcAAAAKMTIvMzEvMjAyMwgAAAAKMTIvMzEvMjAyMwkAAAABMDUtDa/E19wI0scUr8TX3AgxQ0lRLkhXTS5JUV9UT1RBTF9SRVZfNVlSX0FOTl9DQUdSLjIwMDAuMTIvMzEvMjAyMwEAAAAKsc8YAgAAAActMC40MTA2AQgAAAAFAAAAATEBAAAACy0yMDEwMzM3OTcyAwAAAAMxNjACAAAABDQyMzMEAAAAATAHAAAACjEyLzMxLzIwMjMIAAAACjEyLzMxLzIwMjMJAAAAATA1LQ2vxNfcCNLHFK/E19wIKkNJUS5IRUkuSVFfVE9UQUxfUkVWLjIwMDAuMTIvMzEvMjAyMy4uLlVTRAEAAAB/PgQAAgAAAAgyOTY4LjEwNQEIAAAABQAAAAExAQAAAAstMjAxNDUxNjA4MgMAAAADMTYwAgAAAAIyOAQAAAABMAcAAAAKMTIvMzEvMjAyMwgAAAAKMTAvMzEvMjAyMwkAAAABMDUtDa/E19wI0scUr8TX3AgnQ0lRLkhFSS5JUV9FQklUREEuMjAwMC4xMi8zMS8yMDIzLi4u | P1: VVNEAQAAAH8+BAACAAAABzc2Ny4yMzkBCAAAAAUAAAABMQEAAAALLTIwMTQ1MTYwODIDAAAAAzE2MAIAAAAENDA1MQQAAAABMAcAAAAKMTIvMzEvMjAyMwgAAAAKMTAvMzEvMjAyMwkAAAABMDUtDa/E19wI3rAUr8TX3AgxQ0lRLkhFSS5JUV9UT1RBTF9SRVZfNVlSX0FOTl9DQUdSLjIwMDAuMTIvMzEvMjAyMwEAAAB/PgQAAgAAAAcxMC43OTU4AQgAAAAFAAAAATEBAAAACy0yMDE0NTE2MDgyAwAAAAMxNjACAAAABDQyMzMEAAAAATAHAAAACjEyLzMxLzIwMjMIAAAACjEwLzMxLzIwMjMJAAAAATA1LQ2vxNfcCN6wFK/E19wIKkNJUS5UWFQuSVFfVE9UQUxfUkVWLjIwMDAuMTIvMzEvMjAyMy4uLlVTRAEAAADniQAAAgAAAAUxMzY4MwEIAAAABQAAAAExAQAAAAstMjAxMDc5MDQ2NgMAAAADMTYwAgAAAAIyOAQAAAABMAcAAAAKMTIvMzEvMjAyMwgAAAAKMTIvMzAvMjAyMwkAAAABMDUtDa/E19wI3rAUr8TX3AgnQ0lRLlRYVC5JUV9FQklUREEuMjAwMC4xMi8zMS8yMDIzLi4uVVNEAQAAAOeJAAACAAAABDE2NzABCAAAAAUAAAABMQEAAAALLTIwMTA3OTA0NjYDAAAAAzE2MAIAAAAENDA1MQQAAAABMAcAAAAKMTIvMzEvMjAyMwgAAAAKMTIvMzAvMjAyMwkAAAABMDUtDa/E19wI3rAUr8TX3AgxQ0lRLlRYVC5JUV9UT1RBTF9SRVZfNVlSX0FOTl9DQUdSLjIwMDAuMTIvMzEvMjAyMwEAAADniQAAAgAAAAct | Q1: MC40MTcyAQgAAAAFAAAAATEBAAAACy0yMDEwNzkwNDY2AwAAAAMxNjACAAAABDQyMzMEAAAAATAHAAAACjEyLzMxLzIwMjMIAAAACjEyLzMwLzIwMjMJAAAAATA1LQ2vxNfcCN6wFK/E19wIKUNJUS5DVy5JUV9UT1RBTF9SRVYuMjAwMC4xMi8zMS8yMDIzLi4uVVNEAQAAAKoMBAACAAAACDI4NDUuMzczAQgAAAAFAAAAATEBAAAACy0yMDA5NTYyMzQ4AwAAAAMxNjACAAAAAjI4BAAAAAEwBwAAAAoxMi8zMS8yMDIzCAAAAAoxMi8zMS8yMDIzCQAAAAEwNS0Nr8TX3AjesBSvxNfcCCZDSVEuQ1cuSVFfRUJJVERBLjIwMDAuMTIvMzEvMjAyMy4uLlVTRAEAAACqDAQAAgAAAAc2MjkuNjY5AQgAAAAFAAAAATEBAAAACy0yMDA5NTYyMzQ4AwAAAAMxNjACAAAABDQwNTEEAAAAATAHAAAACjEyLzMxLzIwMjMIAAAACjEyLzMxLzIwMjMJAAAAATA1LQ2vxNfcCN6wFK/E19wIMENJUS5DVy5JUV9UT1RBTF9SRVZfNVlSX0FOTl9DQUdSLjIwMDAuMTIvMzEvMjAyMwEAAACqDAQAAgAAAAYzLjM2MTQBCAAAAAUAAAABMQEAAAALLTIwMDk1NjIzNDgDAAAAAzE2MAIAAAAENDIzMwQAAAABMAcAAAAKMTIvMzEvMjAyMwgAAAAKMTIvMzEvMjAyMwkAAAABMDUtDa/E19wI3rAUr8TX3AgsQ0lRLkJEUkJGLklRX1RPVEFMX1JFVi4yMDAwLjEyLzMxLzIwMjMuLi5VU0QBAAAApJsKAAIAAAAEODA0NgEIAAAABQAAAAExAQAAAAst | R1: MjAxMTM1MDkzNwMAAAADMTYwAgAAAAIyOAQAAAABMAcAAAAKMTIvMzEvMjAyMwgAAAAKMTIvMzEvMjAyMwkAAAABMDUtDa/E19wI3rAUr8TX3AgpQ0lRLkJEUkJGLklRX0VCSVREQS4yMDAwLjEyLzMxLzIwMjMuLi5VU0QBAAAApJsKAAIAAAADOTMzAQgAAAAFAAAAATEBAAAACy0yMDExMzUwOTM3AwAAAAMxNjACAAAABDQwNTEEAAAAATAHAAAACjEyLzMxLzIwMjMIAAAACjEyLzMxLzIwMjMJAAAAATA1LQ2vxNfcCN6wFK/E19wIM0NJUS5CRFJCRi5JUV9UT1RBTF9SRVZfNVlSX0FOTl9DQUdSLjIwMDAuMTIvMzEvMjAyMwEAAACkmwoAAgAAAAgtMTMuMDk5OQEIAAAABQAAAAExAQAAAAstMjAxMTM1MDkzNwMAAAADMTYwAgAAAAQ0MjMzBAAAAAEwBwAAAAoxMi8zMS8yMDIzCAAAAAoxMi8zMS8yMDIzCQAAAAEwNS0Nr8TX3AjesBSvxNfcCCpDSVEuV1dELklRX1RPVEFMX1JFVi4yMDAwLjEyLzMxLzIwMjMuLi5VU0QBAAAAQs0EAAIAAAAIMzA4Mi42NzcBCAAAAAUAAAABMQEAAAALLTIwMTE4MTI3OTkDAAAAAzE2MAIAAAACMjgEAAAAATAHAAAACjEyLzMxLzIwMjMIAAAACjEyLzMxLzIwMjMJAAAAATA1LQ2vxNfcCN6wFK/E19wIJ0NJUS5XV0QuSVFfRUJJVERBLjIwMDAuMTIvMzEvMjAyMy4uLlVTRAEAAABCzQQAAgAAAAc0ODkuMTk4AQgAAAAFAAAAATEBAAAACy0yMDExODEyNzk5AwAAAAMxNjACAAAA | S1: BDQwNTEEAAAAATAHAAAACjEyLzMxLzIwMjMIAAAACjEyLzMxLzIwMjMJAAAAATA1LQ2vxNfcCN6wFK/E19wIMUNJUS5XV0QuSVFfVE9UQUxfUkVWXzVZUl9BTk5fQ0FHUi4yMDAwLjEyLzMxLzIwMjMBAAAAQs0EAAIAAAAGNC4yMDgxAQgAAAAFAAAAATEBAAAACy0yMDExODEyNzk5AwAAAAMxNjACAAAABDQyMzMEAAAAATAHAAAACjEyLzMxLzIwMjMIAAAACjEyLzMxLzIwMjMJAAAAATA1LQ2vxNfcCN6wFK/E19wIKkNJUS5TUFIuSVFfVE9UQUxfUkVWLjIwMDAuMTIvMzEvMjAyMy4uLlVTRAEAAABrHqkBAgAAAAY2MDQ3LjkBCAAAAAUAAAABMQEAAAALLTIwMDkwODMzMTcDAAAAAzE2MAIAAAACMjgEAAAAATAHAAAACjEyLzMxLzIwMjMIAAAACjEyLzMxLzIwMjMJAAAAATA1LQ2vxNfcCN6wFK/E19wIJ0NJUS5TUFIuSVFfRUJJVERBLjIwMDAuMTIvMzEvMjAyMy4uLlVTRAEAAABrHqkBAgAAAAQ4NC43AQgAAAAFAAAAATEBAAAACy0yMDA5MDgzMzE3AwAAAAMxNjACAAAABDQwNTEEAAAAATAHAAAACjEyLzMxLzIwMjMIAAAACjEyLzMxLzIwMjMJAAAAATA1LQ2vxNfcCN6wFK/E19wIMUNJUS5TUFIuSVFfVE9UQUxfUkVWXzVZUl9BTk5fQ0FHUi4yMDAwLjEyLzMxLzIwMjMBAAAAax6pAQIAAAAHLTMuNDg2MgEIAAAABQAAAAExAQAAAAstMjAwOTA4MzMxNwMAAAADMTYwAgAAAAQ0MjMzBAAAAAEwBwAAAAox | T1: Mi8zMS8yMDIzCAAAAAoxMi8zMS8yMDIzCQAAAAEwNS0Nr8TX3AjesBSvxNfcCCpDSVEuSFhMLklRX1RPVEFMX1JFVi4yMDAwLjEyLzMxLzIwMjMuLi5VU0QBAAAA8T8EAAIAAAAEMTc4OQEIAAAABQAAAAExAQAAAAstMjAxMTM5NzY5OAMAAAADMTYwAgAAAAIyOAQAAAABMAcAAAAKMTIvMzEvMjAyMwgAAAAKMTIvMzEvMjAyMwkAAAABMDUtDa/E19wI3rAUr8TX3AgnQ0lRLkhYTC5JUV9FQklUREEuMjAwMC4xMi8zMS8yMDIzLi4uVVNEAQAAAPE/BAACAAAABTM0MC4xAQgAAAAFAAAAATEBAAAACy0yMDExMzk3Njk4AwAAAAMxNjACAAAABDQwNTEEAAAAATAHAAAACjEyLzMxLzIwMjMIAAAACjEyLzMxLzIwMjMJAAAAATA1LQ2vxNfcCN6wFK/E19wIMUNJUS5IWEwuSVFfVE9UQUxfUkVWXzVZUl9BTk5fQ0FHUi4yMDAwLjEyLzMxLzIwMjMBAAAA8T8EAAIAAAAHLTMuOTU2MwEIAAAABQAAAAExAQAAAAstMjAxMTM5NzY5OAMAAAADMTYwAgAAAAQ0MjMzBAAAAAEwBwAAAAoxMi8zMS8yMDIzCAAAAAoxMi8zMS8yMDIzCQAAAAEwNS0Nr8TX3AjesBSvxNfcCCxDSVEuTU9HL0EuSVFfVE9UQUxfUkVWLjIwMDAuMTIvMzEvMjAyMy4uLlVTRAEAAABUawQAAgAAAAgzNDE1Ljg2OQEIAAAABQAAAAExAQAAAAstMjAxMTc1Njg5NAMAAAADMTYwAgAAAAIyOAQAAAABMAcAAAAKMTIvMzEvMjAyMwgAAAAKMTIvMzAvMjAy | U1: MwkAAAABMDUtDa/E19wI3rAUr8TX3AgpQ0lRLk1PRy9BLklRX0VCSVREQS4yMDAwLjEyLzMxLzIwMjMuLi5VU0QBAAAAVGsEAAIAAAAHNDIxLjg3OAEIAAAABQAAAAExAQAAAAstMjAxMTc1Njg5NAMAAAADMTYwAgAAAAQ0MDUxBAAAAAEwBwAAAAoxMi8zMS8yMDIzCAAAAAoxMi8zMC8yMDIzCQAAAAEwNS0Nr8TX3AjesBSvxNfcCDNDSVEuTU9HL0EuSVFfVE9UQUxfUkVWXzVZUl9BTk5fQ0FHUi4yMDAwLjEyLzMxLzIwMjMBAAAAVGsEAAIAAAAGNC4zNDQxAQgAAAAFAAAAATEBAAAACy0yMDExNzU2ODk0AwAAAAMxNjACAAAABDQyMzMEAAAAATAHAAAACjEyLzMxLzIwMjMIAAAACjEyLzMwLzIwMjMJAAAAATA1LQ2vxNfcCE6JFK/E19wIKkNJUS5FUkouSVFfVE9UQUxfUkVWLjIwMDAuMTIvMzEvMjAyMy4uLlVTRAEAAADHbgoAAgAAAAs1MzgxLjA1OTkxOQEIAAAABQAAAAExAQAAAAstMjAwNTU1NzEyMwMAAAADMTYwAgAAAAIyOAQAAAABMAcAAAAKMTIvMzEvMjAyMwgAAAAKMTIvMzEvMjAyMwkAAAABMDUtDa/E19wITokUr8TX3AgnQ0lRLkVSSi5JUV9FQklUREEuMjAwMC4xMi8zMS8yMDIzLi4uVVNEAQAAAMduCgACAAAACjQxMC41NTcwNTYBCAAAAAUAAAABMQEAAAALLTIwMDU1NTcxMjMDAAAAAzE2MAIAAAAENDA1MQQAAAABMAcAAAAKMTIvMzEvMjAyMwgAAAAKMTIvMzEvMjAyMwkAAAABMDUtDa/E | V1: 19wITokUr8TX3AgxQ0lRLkVSSi5JUV9UT1RBTF9SRVZfNVlSX0FOTl9DQUdSLjIwMDAuMTIvMzEvMjAyMwEAAADHbgoAAgAAAAcyNy4wNDg0AQgAAAAFAAAAATEBAAAACy0yMDA1NTU3MTIzAwAAAAIyMQIAAAAENDIzMwQAAAABMAcAAAAKMTIvMzEvMjAyMwgAAAAKMTIvMzEvMjAyMwkAAAABMDUtDa/E19wITokUr8TX3AgiQ0lRLkJBLklRX01BUktFVENBUC4xMi8zMS8yMDIzLlVTRAEAAACpqAUAAgAAAA0xNTc2OTMuMjUxOTA2AQYAAAAFAAAAATEBAAAACy0yMDIyOTk3MTE2AwAAAAMxNjACAAAABjEwMDA1NAQAAAABMAcAAAAKMTIvMzEvMjAyMzUtDa/E19wIJcsUr8TX3AgjQ0lRLlJUWC5JUV9NQVJLRVRDQVAuMTIvMzEvMjAyMy5VU0QBAAAA/m0CAAIAAAAMMTIwNzEzLjk0MjQ3AQYAAAAFAAAAATEBAAAACy0yMDIzMTQyNTI0AwAAAAMxNjACAAAABjEwMDA1NAQAAAABMAcAAAAKMTIvMzEvMjAyMzUtDa/E19wIJcsUr8TX3AgjQ0lRLkxNVC5JUV9NQVJLRVRDQVAuMTIvMzEvMjAyMy5VU0QBAAAAg1wEAAIAAAANMTEyNDQ4LjI2MTU4NwEGAAAABQAAAAExAQAAAAstMjAyMzgxOTMxOQMAAAADMTYwAgAAAAYxMDAwNTQEAAAAATAHAAAACjEyLzMxLzIwMjM1LQ2vxNfcCCXLFK/E19wII0NJUS5UREcuSVFfTUFSS0VUQ0FQLjEyLzMxLzIwMjMuVVNEAQAAADTnWwECAAAADDU1OTU1Ljc0NzYwNgEGAAAA | W1: BQAAAAExAQAAAAstMjAyMDExNDk3MwMAAAADMTYwAgAAAAYxMDAwNTQEAAAAATAHAAAACjEyLzMxLzIwMjM1LQ2vxNfcCCXLFK/E19wII0NJUS5IV00uSVFfTUFSS0VUQ0FQLjEyLzMxLzIwMjMuVVNEAQAAAAqxzxgCAAAADDIyMjgzLjYwNDQzOAEGAAAABQAAAAExAQAAAAstMjAyMTQwMDg3NQMAAAADMTYwAgAAAAYxMDAwNTQEAAAAATAHAAAACjEyLzMxLzIwMjM1LQ2vxNfcCCXLFK/E19wII0NJUS5IRUkuSVFfTUFSS0VUQ0FQLjEyLzMxLzIwMjMuVVNEAQAAAH8+BAACAAAADDIxNjg2LjQ5NzQ3MwEGAAAABQAAAAExAQAAAAstMjAxNDUxNjA4NAMAAAADMTYwAgAAAAYxMDAwNTQEAAAAATAHAAAACjEyLzMxLzIwMjM1LQ2vxNfcCN6wFK/E19wII0NJUS5UWFQuSVFfTUFSS0VUQ0FQLjEyLzMxLzIwMjMuVVNEAQAAAOeJAAACAAAADDE1NzYyLjc1ODg1MgEGAAAABQAAAAExAQAAAAstMjAyMjczNjIwNwMAAAADMTYwAgAAAAYxMDAwNTQEAAAAATAHAAAACjEyLzMxLzIwMjM1LQ2vxNfcCN6wFK/E19wIIkNJUS5DVy5JUV9NQVJLRVRDQVAuMTIvMzEvMjAyMy5VU0QBAAAAqgwEAAIAAAALODUxOS43NjA5NTgBBgAAAAUAAAABMQEAAAALLTIwMjE0MDA4NDMDAAAAAzE2MAIAAAAGMTAwMDU0BAAAAAEwBwAAAAoxMi8zMS8yMDIzNS0Nr8TX3AjesBSvxNfcCCVDSVEuQkRSQkYuSVFfTUFSS0VUQ0FQLjEyLzMx | X1: LzIwMjMuVVNEAQAAAKSbCgACAAAAEDM4NjEuMzU4OTI5NjQ2MTEBBgAAAAUAAAABMQEAAAALLTIwMjE2NTkzNTkDAAAAAzE2MAIAAAAGMTAwMDU0BAAAAAEwBwAAAAoxMi8zMS8yMDIzNS0Nr8TX3AjesBSvxNfcCCNDSVEuV1dELklRX01BUktFVENBUC4xMi8zMS8yMDIzLlVTRAEAAABCzQQAAgAAAAo4MTc1LjcwMzk4AQYAAAAFAAAAATEBAAAACy0yMDE4MjMzNTM5AwAAAAMxNjACAAAABjEwMDA1NAQAAAABMAcAAAAKMTIvMzEvMjAyMzUtDa/E19wI3rAUr8TX3AgjQ0lRLlNQUi5JUV9NQVJLRVRDQVAuMTIvMzEvMjAyMy5VU0QBAAAAax6pAQIAAAALMzY4Ny4yOTA0ODUBBgAAAAUAAAABMQEAAAALLTIwMjEyNDc5NjADAAAAAzE2MAIAAAAGMTAwMDU0BAAAAAEwBwAAAAoxMi8zMS8yMDIzNS0Nr8TX3AjesBSvxNfcCCNDSVEuSFhMLklRX01BUktFVENBUC4xMi8zMS8yMDIzLlVTRAEAAADxPwQAAgAAAAs2MjAzLjIwNzkzMwEGAAAABQAAAAExAQAAAAstMjAyMzA5MTM3MQMAAAADMTYwAgAAAAYxMDAwNTQEAAAAATAHAAAACjEyLzMxLzIwMjM1LQ2vxNfcCN6wFK/E19wIJUNJUS5NT0cvQS5JUV9NQVJLRVRDQVAuMTIvMzEvMjAyMy5VU0QBAAAAVGsEAAIAAAALNDg4Ni4zOTYxMjgBBgAAAAUAAAABMQEAAAALLTIwMTkxODU3MzADAAAAAzE2MAIAAAAGMTAwMDU0BAAAAAEwBwAAAAoxMi8zMS8yMDIzNS0N | Y1: r8TX3AjesBSvxNfcCCNDSVEuRVJKLklRX01BUktFVENBUC4xMi8zMS8yMDIzLlVTRAEAAADHbgoAAgAAABAzMzg5LjgyMTAyNDA3NTU4AQYAAAAFAAAAATEBAAAACy0yMDIwNDA0NzE1AwAAAAMxNjACAAAABjEwMDA1NAQAAAABMAcAAAAKMTIvMzEvMjAyMzUtDa/E19wITokUr8TX3Ag=

Sheet Dashboard
C1: =++$E$6 -> [Company Name] | O1: =++EOMONTH(P1,-12) -> 44926 | P1: =++EOMONTH(Q1,-12) -> 45291 | Q1: =++EOMONTH(S1,-12) -> 45657 | R1: =++LTMDate -> 45930 | S1: =++DATE(YEAR(R1),MONTH($E$11),DAY($E$11)) -> 46022 | T1: =++EOMONTH(U1,-12) -> 45565 | U1: =++LTMDate -> 45930 | V1: =++U1 -> 45930 | W1: =++T1 -> 45565 | X1: =++U1 -> 45930 | Y1: =++V1 -> 45930 | AA1: Financials Date: | AC1: 45930
C2: OL Investment Dashboard | AA2: Financials Type: | AC2: Reported
C3: =++TEXT(TODAY(),"MMMM D, YYYY") -> February 26, 2026
A5: x | B5: x | C5: =++C2 -> OL Investment Dashboard | Y5: =++"Financial Performance Update as of "&TEXT(LTMDate,"MMMM D, YYYY") -> Financial Performance Update as of September 30, 2025
C6: Company Name: | E6: [Company Name] | I6: CFO: | K6: [Name] | O6: WF Sourced (Y/N): | Q6: [Yes/No] | U6: Agent: | W6: [Wells Fargo]
C7: HQ: | E7: [City, State] | I7: CFO Email: | K7: [Email] | O7: WF Origination: | Q7: [Name] | U7: Agent Contact: | W7: [Name]
C8: Address: | E8: [Address] | I8: CFO Phone: | K8: [Phone] | O8: OL U/W: | Q8: [Name] | U8: Agent Contact Email: | W8: [Email]
C9: Sector: | E9: Industrials | I9: Owner: | K9: [Sponsor / Founder / Family Office] | O9: OL Cap Markets: | Q9: [Name] | U9: OL Counsel | W9: [Firm Name]
C10: Industry: | E10: Professional Services | I10: Owner Fund: | K10: [Fund Name / n/a] | O10: OL Coverage: | Q10: [Name] | U10: OL Counsel Contact: | W10: [Name]
C11: FYE: | E11: 45657 | I11: Address: | K11: [Address] | O11: OL Role: | Q11: [Lead Arranger / Bookrunner] | U11: OL Counsel Email: | W11: [Email]
C12: CEO: | E12: [Name] | I12: Owner Contact: | K12: [Name] | O12: OL Maturity Date: | Q12: =++MAX(H20:H24) -> 47664 | U12: Owner Counsel: | W12: [Firm Name]
C13: CEO Email: | E13: [Email] | I13: Owner Contact Email: | K13: [Email] | O13: ESG Category: | Q13: ESG - 1 | U13: Owner Counsel Contact: | W13: [Name]
C14: CEO Phone: | E14: [Phone] | I14: Owner Contact Phone: | K14: [Phone] | O14: ESG Subsector: | Q14: n/a | U14: Owner Counsel Email: | W14: [Email]
B17: x | C17: Overland Investment Summary
C18: USD in 000's, except where noted | G18: Dates | L18: Final Call | M18: Global Commitments | O18: OL Commitments | S18: Fees | V18: Pricing | X18: OL Valuation
C19: Security | F19: Status | G19: Investment | H19: Maturity | I19: Tenor (yrs) | J19: Call Schedule | L19: Expiration | M19: Commit. | N19: Outstand. | O19: Commit. | P19: % Total | Q19: Outstand. | R19: % Commit. | S19: Closing | T19: Structuring | U19: Deferred | V19: Floor | W19: Spread / Coup | X19: Mark | Y19: Val. Date
C20: =++'Trade Ticket Input'!P388 -> ABL Revolver ($0.0MM) | F20: Outstanding | G20: =++'Trade Ticket Input'!S388 -> 45838 | H20: =++'Trade Ticket Input'!T388 -> 47664 | I20: =++YEARFRAC(G20,H20,1) -> 5.0004564 | J20: =++'Trade Ticket Input'!U388 -> n/a | L20: =++'Trade Ticket Input'!W388 -> n/a | M20: =++'Trade Ticket Input'!X388 -> 0 | N20: =++INDEX('Financials Input'!$G$651:$DC$680,MATCH(C20,'Financials Input'!$C$651:$C$680,0),MATCH(LTMDate,'Financials Input'!$G$3:$DC$3,0)) -> 0 | O20: =++'Trade Ticket Input'!Y388 -> 0 | P20: =++IFERROR(O20/M20,0) -> 0 | Q20: 0 | R20: =++IFERROR(Q20/O20,0) -> 0 | S20: =++'Trade Ticket Input'!AA388 -> 0 | T20: =++'Trade Ticket Input'!Z388 -> 0 | U20: =++'Trade Ticket Input'!AB388 -> 0 | V20: =++'Trade Ticket Input'!AC388 -> 0 | W20: =++'Trade Ticket Input'!AD388 -> 0 | X20: 100 | Y20: Q3'25
C21: =++'Trade Ticket Input'!P389 -> Priority Revolver ($0.0MM) | F21: Outstanding | G21: =++'Trade Ticket Input'!S389 -> 45838 | H21: =++'Trade Ticket Input'!T389 -> 47664 | I21: =++YEARFRAC(G21,H21,1) -> 5.0004564 | J21: =++'Trade Ticket Input'!U389 -> n/a | L21: =++'Trade Ticket Input'!W389 -> n/a | M21: =++'Trade Ticket Input'!X389 -> 0 | N21: =++INDEX('Financials Input'!$G$651:$DC$680,MATCH(C21,'Financials Input'!$C$651:$C$680,0),MATCH(LTMDate,'Financials Input'!$G$3:$DC$3,0)) -> 0 | O21: =++'Trade Ticket Input'!Y389 -> 0 | P21: =++IFERROR(O21/M21,0) -> 0 | Q21: 0 | R21: =++IFERROR(Q21/O21,0) -> 0 | S21: =++'Trade Ticket Input'!AA389 -> 0 | T21: =++'Trade Ticket Input'!Z389 -> 0 | U21: =++'Trade Ticket Input'!AB389 -> 0 | V21: =++'Trade Ticket Input'!AC389 -> 0 | W21: =++'Trade Ticket Input'!AD389 -> 0 | X21: 100 | Y21: Q3'25
C22: =++'Trade Ticket Input'!P390 -> First Lien Term Loan | F22: Outstanding | G22: =++'Trade Ticket Input'!S390 -> 45838 | H22: =++'Trade Ticket Input'!T390 -> 47664 | I22: =++YEARFRAC(G22,H22,1) -> 5.0004564 | J22: =++'Trade Ticket Input'!U390 -> 102/101 | L22: =++'Trade Ticket Input'!W390 -> 46568 | M22: =++'Trade Ticket Input'!X390 -> 0 | N22: =++INDEX('Financials Input'!$G$651:$DC$680,MATCH(C22,'Financials Input'!$C$651:$C$680,0),MATCH(LTMDate,'Financials Input'!$G$3:$DC$3,0)) -> 0 | O22: =++'Trade Ticket Input'!Y390 -> 0 | P22: =++IFERROR(O22/M22,0) -> 0 | Q22: 0 | R22: =++IFERROR(Q22/O22,0) -> 0 | S22: =++'Trade Ticket Input'!AA390 -> 0 | T22: =++'Trade Ticket Input'!Z390 -> 0 | U22: =++'Trade Ticket Input'!AB390 -> 0 | V22: =++'Trade Ticket Input'!AC390 -> 0 | W22: =++'Trade Ticket Input'!AD390 -> 0 | X22: 100 | Y22: Q3'25
C23: =++'Trade Ticket Input'!P391 -> First Lien Last-Out Term Loan | F23: Outstanding | G23: =++'Trade Ticket Input'!S391 -> 45838 | H23: =++'Trade Ticket Input'!T391 -> 47664 | I23: =++YEARFRAC(G23,H23,1) -> 5.0004564 | J23: =++'Trade Ticket Input'!U391 -> 102/101 | L23: =++'Trade Ticket Input'!W391 -> 46568 | M23: =++'Trade Ticket Input'!X391 -> 0 | N23: =++INDEX('Financials Input'!$G$651:$DC$680,MATCH(C23,'Financials Input'!$C$651:$C$680,0),MATCH(LTMDate,'Financials Input'!$G$3:$DC$3,0)) -> 0 | O23: =++'Trade Ticket Input'!Y391 -> 0 | P23: =++IFERROR(O23/M23,0) -> 0 | Q23: 0 | R23: =++IFERROR(Q23/O23,0) -> 0 | S23: =++'Trade Ticket Input'!AA391 -> 0 | T23: =++'Trade Ticket Input'!Z391 -> 0 | U23: =++'Trade Ticket Input'!AB391 -> 0 | V23: =++'Trade Ticket Input'!AC391 -> 0 | W23: =++'Trade Ticket Input'!AD391 -> 0 | X23: 100 | Y23: Q3'25
C24: =++'Trade Ticket Input'!P392 -> First Lien DDTL ($0.0MM) | F24: Outstanding | G24: =++'Trade Ticket Input'!S392 -> 45838 | H24: =++'Trade Ticket Input'!T392 -> 47664 | I24: =++YEARFRAC(G24,H24,1) -> 5.0004564 | J24: =++'Trade Ticket Input'!U392 -> 102/101 | L24: =++'Trade Ticket Input'!W392 -> 46568 | M24: =++'Trade Ticket Input'!X392 -> 0 | N24: =++INDEX('Financials Input'!$G$651:$DC$680,MATCH(C24,'Financials Input'!$C$651:$C$680,0),MATCH(LTMDate,'Financials Input'!$G$3:$DC$3,0)) -> 0 | O24: =++'Trade Ticket Input'!Y392 -> 0 | P24: =++IFERROR(O24/M24,0) -> 0 | Q24: 0 | R24: =++IFERROR(Q24/O24,0) -> 0 | S24: =++'Trade Ticket Input'!AA392 -> 0 | T24: =++'Trade Ticket Input'!Z392 -> 0 | U24: =++'Trade Ticket Input'!AB392 -> 0 | V24: =++'Trade Ticket Input'!AC392 -> 0 | W24: =++'Trade Ticket Input'!AD392 -> 0 | X24: 100 | Y24: Q3'25
C25: =++'Trade Ticket Input'!P393 -> Second Lien Term Loan | F25: Outstanding | G25: =++'Trade Ticket Input'!S393 -> 45838 | H25: =++'Trade Ticket Input'!T393 -> 47664 | I25: =++YEARFRAC(G25,H25,1) -> 5.0004564 | J25: =++'Trade Ticket Input'!U393 -> 102/101 | L25: =++'Trade Ticket Input'!W393 -> 46568 | M25: =++'Trade Ticket Input'!X393 -> 0 | N25: =++INDEX('Financials Input'!$G$651:$DC$680,MATCH(C25,'Financials Input'!$C$651:$C$680,0),MATCH(LTMDate,'Financials Input'!$G$3:$DC$3,0)) -> 0 | O25: =++'Trade Ticket Input'!Y393 -> 0 | P25: =++IFERROR(O25/M25,0) -> 0 | Q25: 0 | R25: =++IFERROR(Q25/O25,0) -> 0 | S25: =++'Trade Ticket Input'!AA393 -> 0 | T25: =++'Trade Ticket Input'!Z393 -> 0 | U25: =++'Trade Ticket Input'!AB393 -> 0 | V25: =++'Trade Ticket Input'!AC393 -> 0 | W25: =++'Trade Ticket Input'!AD393 -> 0 | X25: 100 | Y25: Q3'25
C26: =++'Trade Ticket Input'!P394 -> Second Lien DDTL ($0.0MM) | F26: Outstanding | G26: =++'Trade Ticket Input'!S394 -> 45838 | H26: =++'Trade Ticket Input'!T394 -> 47664 | I26: =++YEARFRAC(G26,H26,1) -> 5.0004564 | J26: =++'Trade Ticket Input'!U394 -> 102/101 | L26: =++'Trade Ticket Input'!W394 -> 46568 | M26: =++'Trade Ticket Input'!X394 -> 0 | N26: =++INDEX('Financials Input'!$G$651:$DC$680,MATCH(C26,'Financials Input'!$C$651:$C$680,0),MATCH(LTMDate,'Financials Input'!$G$3:$DC$3,0)) -> 0 | O26: =++'Trade Ticket Input'!Y394 -> 0 | P26: =++IFERROR(O26/M26,0) -> 0 | Q26: 0 | R26: =++IFERROR(Q26/O26,0) -> 0 | S26: =++'Trade Ticket Input'!AA394 -> 0 | T26: =++'Trade Ticket Input'!Z394 -> 0 | U26: =++'Trade Ticket Input'!AB394 -> 0 | V26: =++'Trade Ticket Input'!AC394 -> 0 | W26: =++'Trade Ticket Input'!AD394 -> 0 | X26: 100 | Y26: Q3'25
C27: =++'Trade Ticket Input'!P395 -> Subordinated Notes | F27: Outstanding | G27: =++'Trade Ticket Input'!S395 -> 45838 | H27: =++'Trade Ticket Input'!T395 -> 47664 | I27: =++YEARFRAC(G27,H27,1) -> 5.0004564 | J27: =++'Trade Ticket Input'!U395 -> 102/101 | L27: =++'Trade Ticket Input'!W395 -> 46568 | M27: =++'Trade Ticket Input'!X395 -> 0 | N27: =++INDEX('Financials Input'!$G$651:$DC$680,MATCH(C27,'Financials Input'!$C$651:$C$680,0),MATCH(LTMDate,'Financials Input'!$G$3:$DC$3,0)) -> 0 | O27: =++'Trade Ticket Input'!Y395 -> 0 | P27: =++IFERROR(O27/M27,0) -> 0 | Q27: 0 | R27: =++IFERROR(Q27/O27,0) -> 0 | S27: =++'Trade Ticket Input'!AA395 -> 0 | T27: =++'Trade Ticket Input'!Z395 -> 0 | U27: =++'Trade Ticket Input'!AB395 -> 0 | V27: =++'Trade Ticket Input'!AC395 -> n/a | W27: =++'Trade Ticket Input'!AD395 -> 0 | X27: 100 | Y27: Q3'25
C28: =++'Trade Ticket Input'!P396 -> Subordinated DD Notes ($0.0MM) | F28: Outstanding | G28: =++'Trade Ticket Input'!S396 -> 45838 | H28: =++'Trade Ticket Input'!T396 -> 47664 | I28: =++YEARFRAC(G28,H28,1) -> 5.0004564 | J28: =++'Trade Ticket Input'!U396 -> 102/101 | L28: =++'Trade Ticket Input'!W396 -> 46568 | M28: =++'Trade Ticket Input'!X396 -> 0 | N28: =++INDEX('Financials Input'!$G$651:$DC$680,MATCH(C28,'Financials Input'!$C$651:$C$680,0),MATCH(LTMDate,'Financials Input'!$G$3:$DC$3,0)) -> 0 | O28: =++'Trade Ticket Input'!Y396 -> 0 | P28: =++IFERROR(O28/M28,0) -> 0 | Q28: 0 | R28: =++IFERROR(Q28/O28,0) -> 0 | S28: =++'Trade Ticket Input'!AA396 -> 0 | T28: =++'Trade Ticket Input'!Z396 -> 0 | U28: =++'Trade Ticket Input'!AB396 -> 0 | V28: =++'Trade Ticket Input'!AC396 -> n/a | W28: =++'Trade Ticket Input'!AD396 -> 0 | X28: 100 | Y28: Q3'25
C29: =++'Trade Ticket Input'!P397 -> HoldCo Notes | F29: Outstanding | G29: =++'Trade Ticket Input'!S397 -> 45838 | H29: =++'Trade Ticket Input'!T397 -> 47664 | I29: =++YEARFRAC(G29,H29,1) -> 5.0004564 | J29: =++'Trade Ticket Input'!U397 -> 102/101 | L29: =++'Trade Ticket Input'!W397 -> 46568 | M29: =++'Trade Ticket Input'!X397 -> 0 | N29: =++INDEX('Financials Input'!$G$651:$DC$680,MATCH(C29,'Financials Input'!$C$651:$C$680,0),MATCH(LTMDate,'Financials Input'!$G$3:$DC$3,0)) -> 0 | O29: =++'Trade Ticket Input'!Y397 -> 0 | P29: =++IFERROR(O29/M29,0) -> 0 | Q29: 0 | R29: =++IFERROR(Q29/O29,0) -> 0 | S29: =++'Trade Ticket Input'!AA397 -> 0 | T29: =++'Trade Ticket Input'!Z397 -> 0 | U29: =++'Trade Ticket Input'!AB397 -> 0 | V29: =++'Trade Ticket Input'!AC397 -> n/a | W29: =++'Trade Ticket Input'!AD397 -> 0 | X29: 100 | Y29: Q3'25
C30: =++'Trade Ticket Input'!P398 -> HoldCo DD Notes ($0.0MM) | F30: Outstanding | G30: =++'Trade Ticket Input'!S398 -> 45838 | H30: =++'Trade Ticket Input'!T398 -> 47664 | I30: =++YEARFRAC(G30,H30,1) -> 5.0004564 | J30: =++'Trade Ticket Input'!U398 -> 102/101 | L30: =++'Trade Ticket Input'!W398 -> 46568 | M30: =++'Trade Ticket Input'!X398 -> 0 | N30: =++INDEX('Financials Input'!$G$651:$DC$680,MATCH(C30,'Financials Input'!$C$651:$C$680,0),MATCH(LTMDate,'Financials Input'!$G$3:$DC$3,0)) -> 0 | O30: =++'Trade Ticket Input'!Y398 -> 0 | P30: =++IFERROR(O30/M30,0) -> 0 | Q30: 0 | R30: =++IFERROR(Q30/O30,0) -> 0 | S30: =++'Trade Ticket Input'!AA398 -> 0 | T30: =++'Trade Ticket Input'!Z398 -> 0 | U30: =++'Trade Ticket Input'!AB398 -> 0 | V30: =++'Trade Ticket Input'!AC398 -> n/a | W30: =++'Trade Ticket Input'!AD398 -> 0 | X30: 100 | Y30: Q3'25
C31: =++'Trade Ticket Input'!P399 -> Preferred Equity | F31: Outstanding | G31: =++'Trade Ticket Input'!S399 -> 45838 | H31: =++'Trade Ticket Input'!T399 -> 47664 | I31: =++YEARFRAC(G31,H31,1) -> 5.0004564 | J31: =++'Trade Ticket Input'!U399 -> 102/101 | L31: =++'Trade Ticket Input'!W399 -> 46568 | M31: =++'Trade Ticket Input'!X399 -> 0 | N31: =++INDEX('Financials Input'!$G$651:$DC$680,MATCH(C31,'Financials Input'!$C$651:$C$680,0),MATCH(LTMDate,'Financials Input'!$G$3:$DC$3,0)) -> 0 | O31: =++'Trade Ticket Input'!Y399 -> 0 | P31: =++IFERROR(O31/M31,0) -> 0 | Q31: 0 | R31: =++IFERROR(Q31/O31,0) -> 0 | S31: =++'Trade Ticket Input'!AA399 -> 0 | T31: =++'Trade Ticket Input'!Z399 -> 0 | U31: =++'Trade Ticket Input'!AB399 -> 0 | V31: =++'Trade Ticket Input'!AC399 -> n/a | W31: =++'Trade Ticket Input'!AD399 -> 0 | X31: 1 | Y31: Q3'25
C32: =++'Trade Ticket Input'!P400&" (Cash)" -> Common Equity (Cash) | F32: Outstanding | G32: =++'Trade Ticket Input'!S400 -> 45838 | M32: =++'Trade Ticket Input'!X400 -> 0 | N32: =++INDEX('Financials Input'!$G$651:$DC$680,MATCH(C32,'Financials Input'!$C$651:$C$680,0),MATCH(LTMDate,'Financials Input'!$G$3:$DC$3,0)) -> 0 | O32: =++'Trade Ticket Input'!Y400 -> 0 | P32: =++IFERROR(O32/M32,0) -> 0 | Q32: 0 | R32: =++IFERROR(Q32/O32,0) -> 0 | X32: 1 | Y32: Q3'25
C33: Total | M33: =++SUM(M20:M32) -> 0 | N33: =++SUM(N20:N32) -> 0 | O33: =++SUM(O20:O32) -> 0 | P33: =++IFERROR(O33/M33,0) -> 0 | Q33: =++SUM(Q20:Q32) -> 0 | R33: =++IFERROR(Q33/O33,0) -> 0
B36: x | C36: Company Description | M36: Transaction Description
C37: [X] | M37: [X]
B45: x | C45: Capitalization Summary | M45: Historical Financials
C47: USD in 000's, except where noted | F47: =++"Last Close ("&INDEX('Financials Input'!$G587:$DC587,1,MATCH(LTMDate,'Financials Input'!$G$3:$DC$3,0))&" - "&TEXT(INDEX('Financials Input'!$G588:$DC588,1,MATCH(LTMDate,'Financials Input'!$G$3:$DC$3,0)),"M/YY")&")" -> Last Close (LBO - 11/24) | I47: =++"Current ("&TEXT(LTMDate,"M/YY")&")" -> Current (9/25) | M47: USD in 000's, except where noted | O47: TTM Period Ending, | T47: YTD Period Ending, | W47: Month Ending,
C48: =++"FYE "&TEXT($E$11,"M/D") -> FYE 12/31 | F48: $ | G48: Net Mult. | H48: % Total | I48: $ | J48: Net Mult. | K48: % Total | M48: =++"FYE "&TEXT($E$11,"M/D") -> FYE 12/31 | O48: =++"FY'"&RIGHT(YEAR(O1),2)&"A" -> FY'22A | P48: =++"FY'"&RIGHT(YEAR(P1),2)&"A" -> FY'23A | Q48: =++"FY'"&RIGHT(YEAR(Q1),2)&"A" -> FY'24A | R48: =++"LTM "&TEXT(R$1,"M/YY") -> LTM 9/25 | S48: =++"FY'"&RIGHT(YEAR(S1),2)&"B" -> FY'25B | T48: =++TEXT(T$1,"M/YY")&"A" -> 9/24A | U48: =++TEXT(U$1,"M/YY")&"A" -> 9/25A | V48: =++TEXT(V$1,"M/YY")&"B" -> 9/25B | W48: =++T48 -> 9/24A | X48: =++U48 -> 9/25A | Y48: =++V48 -> 9/25B
C49: =++'Financials Input'!C645 -> Cash & Equivalents (Reported) | F49: =++INDEX('Financials Input'!$G591:$DC591,1,MATCH(LTMDate,'Financials Input'!$G$3:$DC$3,0)) -> 0 | I49: =++INDEX('Financials Input'!$G645:$DC645,1,MATCH(LTMDate,'Financials Input'!$G$3:$DC$3,0)) -> 0 | M49: =++'Financials Input'!C10 -> Revenue | O49: =++INDEX('Financials Input'!$G157:$DC157,1,MATCH(O$1,'Financials Input'!$G$3:$DC$3,0)) -> 0 | P49: =++INDEX('Financials Input'!$G157:$DC157,1,MATCH(P$1,'Financials Input'!$G$3:$DC$3,0)) -> 0 | Q49: =++IF(R$1<EOMONTH(Q$1,12),INDEX('Financials Input'!$G10:$DC10,1,MATCH(Q$1,'Financials Input'!$G$3:$DC$3,0)),INDEX('Financials Input'!$G157:$DC157,1,MATCH(Q$1,'Financials Input'!$G$3:$DC$3,0))) -> 0 | R49: =++INDEX('Financials Input'!$G10:$DC10,1,MATCH(R$1,'Financials Input'!$G$3:$DC$3,0)) -> 0 | S49: =++INDEX('Financials Input'!$G451:$DC451,1,MATCH(S$1,'Financials Input'!$G$3:$DC$3,0)) -> 0 | T49: =++INDEX('Financials Input'!$G206:$DC206,1,MATCH(T$1,'Financials Input'!$G$3:$DC$3,0)) -> 0 | U49: =++INDEX('Financials Input'!$G59:$DC59,1,MATCH(U$1,'Financials Input'!$G$3:$DC$3,0)) -> 0 | V49: =++INDEX('Financials Input'!$G451:$DC451,1,MATCH(V$1,'Financials Input'!$G$3:$DC$3,0)) -> 0 | W49: =++INDEX('Financials Input'!$G255:$DC255,1,MATCH(W$1,'Financials Input'!$G$3:$DC$3,0)) -> 0 | X49: =++INDEX('Financials Input'!$G108:$DC108,1,MATCH(X$1,'Financials Input'!$G$3:$DC$3,0)) -> 0 | Y49: =++INDEX('Financials Input'!$G500:$DC500,1,MATCH(Y$1,'Financials Input'!$G$3:$DC$3,0)) -> 0
M50: =++'Financials Input'!C11 -> % y/y | O50: =++INDEX('Financials Input'!$G158:$DC158,1,MATCH(O$1,'Financials Input'!$G$3:$DC$3,0)) -> n/a | P50: =++INDEX('Financials Input'!$G158:$DC158,1,MATCH(P$1,'Financials Input'!$G$3:$DC$3,0)) -> n/a | Q50: =++IF(R$1<EOMONTH(Q$1,12),INDEX('Financials Input'!$G11:$DC11,1,MATCH(Q$1,'Financials Input'!$G$3:$DC$3,0)),INDEX('Financials Input'!$G158:$DC158,1,MATCH(Q$1,'Financials Input'!$G$3:$DC$3,0))) -> n/a | R50: =++IFERROR(R49/INDEX('Financials Input'!$G157:$DC157,1,MATCH(EOMONTH(R$1,-12),'Financials Input'!$G$3:$DC$3,0))-1,"n/a") -> n/a | S50: =++IFERROR(S49/Q49-1,"n/a") -> n/a | T50: =++INDEX('Financials Input'!$G207:$DC207,1,MATCH(T$1,'Financials Input'!$G$3:$DC$3,0)) -> n/a | U50: =++IFERROR(U49/INDEX('Financials Input'!$G206:$DC206,1,MATCH(EOMONTH(U$1,-12),'Financials Input'!$G$3:$DC$3,0))-1,"n/a") -> n/a | V50: =++IFERROR(V49/T49-1,"n/a") -> n/a | W50: =++INDEX('Financials Input'!$G256:$DC256,1,MATCH(W$1,'Financials Input'!$G$3:$DC$3,0)) -> n/a | X50: =++IFERROR(X49/INDEX('Financials Input'!$G255:$DC255,1,MATCH(EOMONTH(X$1,-12),'Financials Input'!$G$3:$DC$3,0))-1,"n/a") -> n/a | Y50: =++IFERROR(Y49/W49-1,"n/a") -> n/a
C51: =++'Financials Input'!C651 -> ABL Revolver ($0.0MM) | F51: =++INDEX('Financials Input'!$G597:$DC597,1,MATCH(LTMDate,'Financials Input'!$G$3:$DC$3,0)) -> 0 | G51: =++IFERROR(SUM(-F49,F51)/G$84,0) -> 0 | H51: =++IFERROR(F51/F$82,0) -> 0 | I51: =++INDEX('Financials Input'!$G651:$DC651,1,MATCH(LTMDate,'Financials Input'!$G$3:$DC$3,0)) -> 0 | J51: =++IFERROR(SUM(-I49,I51)/J$84,0) -> 0 | K51: =++IFERROR(I51/I$82,0) -> 0
C52: =++'Financials Input'!C652 -> Priority Revolver ($0.0MM) | F52: =++INDEX('Financials Input'!$G598:$DC598,1,MATCH(LTMDate,'Financials Input'!$G$3:$DC$3,0)) -> 0 | G52: =++IFERROR(F52/G$84+G51,0) -> 0 | H52: =++IFERROR(F52/F$82,0) -> 0 | I52: =++INDEX('Financials Input'!$G652:$DC652,1,MATCH(LTMDate,'Financials Input'!$G$3:$DC$3,0)) -> 0 | J52: =++IFERROR(I52/J$84+J51,0) -> 0 | K52: =++IFERROR(I52/I$82,0) -> 0 | M52: =++'Financials Input'!C13 -> Gross Profit | O52: =++INDEX('Financials Input'!$G160:$DC160,1,MATCH(O$1,'Financials Input'!$G$3:$DC$3,0)) -> 0 | P52: =++INDEX('Financials Input'!$G160:$DC160,1,MATCH(P$1,'Financials Input'!$G$3:$DC$3,0)) -> 0 | Q52: =++IF(R$1<EOMONTH(Q$1,12),INDEX('Financials Input'!$G13:$DC13,1,MATCH(Q$1,'Financials Input'!$G$3:$DC$3,0)),INDEX('Financials Input'!$G160:$DC160,1,MATCH(Q$1,'Financials Input'!$G$3:$DC$3,0))) -> 0 | R52: =++INDEX('Financials Input'!$G13:$DC13,1,MATCH(R$1,'Financials Input'!$G$3:$DC$3,0)) -> 0 | S52: =++INDEX('Financials Input'!$G454:$DC454,1,MATCH(S$1,'Financials Input'!$G$3:$DC$3,0)) -> 0 | T52: =++INDEX('Financials Input'!$G209:$DC209,1,MATCH(T$1,'Financials Input'!$G$3:$DC$3,0)) -> 0 | U52: =++INDEX('Financials Input'!$G62:$DC62,1,MATCH(U$1,'Financials Input'!$G$3:$DC$3,0)) -> 0 | V52: =++INDEX('Financials Input'!$G454:$DC454,1,MATCH(V$1,'Financials Input'!$G$3:$DC$3,0)) -> 0 | W52: =++INDEX('Financials Input'!$G258:$DC258,1,MATCH(W$1,'Financials Input'!$G$3:$DC$3,0)) -> 0 | X52: =++INDEX('Financials Input'!$G111:$DC111,1,MATCH(X$1,'Financials Input'!$G$3:$DC$3,0)) -> 0 | Y52: =++INDEX('Financials Input'!$G503:$DC503,1,MATCH(Y$1,'Financials Input'!$G$3:$DC$3,0)) -> 0
C53: =++'Financials Input'!C653 -> First Lien Term Loan | F53: =++INDEX('Financials Input'!$G599:$DC599,1,MATCH(LTMDate,'Financials Input'!$G$3:$DC$3,0)) -> 0 | G53: =++IFERROR(SUM(F53:F55)/G$84+G52,0) -> 0 | H53: =++IFERROR(F53/F$82,0) -> 0 | I53: =++INDEX('Financials Input'!$G653:$DC653,1,MATCH(LTMDate,'Financials Input'!$G$3:$DC$3,0)) -> 0 | J53: =++IFERROR(SUM(I53:I55)/J$84+J52,0) -> 0 | K53: =++IFERROR(I53/I$82,0) -> 0 | M53: =++'Financials Input'!C14 -> % margin | O53: =++INDEX('Financials Input'!$G161:$DC161,1,MATCH(O$1,'Financials Input'!$G$3:$DC$3,0)) -> n/a | P53: =++INDEX('Financials Input'!$G161:$DC161,1,MATCH(P$1,'Financials Input'!$G$3:$DC$3,0)) -> n/a | Q53: =++IF(R$1<EOMONTH(Q$1,12),INDEX('Financials Input'!$G14:$DC14,1,MATCH(Q$1,'Financials Input'!$G$3:$DC$3,0)),INDEX('Financials Input'!$G161:$DC161,1,MATCH(Q$1,'Financials Input'!$G$3:$DC$3,0))) -> n/a | R53: =++INDEX('Financials Input'!$G14:$DC14,1,MATCH(R$1,'Financials Input'!$G$3:$DC$3,0)) -> n/a | S53: =++INDEX('Financials Input'!$G455:$DC455,1,MATCH(S$1,'Financials Input'!$G$3:$DC$3,0)) -> n/a | T53: =++INDEX('Financials Input'!$G210:$DC210,1,MATCH(T$1,'Financials Input'!$G$3:$DC$3,0)) -> n/a | U53: =++INDEX('Financials Input'!$G63:$DC63,1,MATCH(U$1,'Financials Input'!$G$3:$DC$3,0)) -> n/a | V53: =++INDEX('Financials Input'!$G455:$DC455,1,MATCH(V$1,'Financials Input'!$G$3:$DC$3,0)) -> n/a | W53: =++INDEX('Financials Input'!$G259:$DC259,1,MATCH(W$1,'Financials Input'!$G$3:$DC$3,0)) -> n/a | X53: =++INDEX('Financials Input'!$G112:$DC112,1,MATCH(X$1,'Financials Input'!$G$3:$DC$3,0)) -> n/a | Y53: =++INDEX('Financials Input'!$G504:$DC504,1,MATCH(Y$1,'Financials Input'!$G$3:$DC$3,0)) -> n/a
...

Sheet Charts
C1: =++Dashboard!$C$1 -> [Company Name]
C2: Financial Performance Trends
C3: =++TEXT(TODAY(),"MMMM D, YYYY") -> February 26, 2026
A5: x | B5: x | C5: =++C2&" ("&FinChartType&")" -> Financial Performance Trends (Reported) | M5: =++"Financial & Credit KPIs as of "&TEXT(LTMDate,"MMMM D, YYYY") -> Financial & Credit KPIs as of September 30, 2025
C6: =++"FYE "&TEXT(Dashboard!$E$11,"M/D")&" | USD in millions" -> FYE 12/31 | USD in millions
C8: TTM Revenue (% y/y) | I8: TTM Gross Profit (% margin)
C22: TTM CA EBITDA (% margin) | I22: TTM Capex (% revenue)
C36: TTM FCF (% conversion) | I36: NWC (% revenue)
C52: [Total] Net Leverage (% covenant cushion) | I52: Fixed Charge Coverage Ratio (% covenant cushion)
C73: Liquidity (% covenant cushion) | I73: Overland Risk Rating Migration & Mark History
A96: x | B96: x | P96: Date (LU) | Q96: Date Label | R96: Revenue | S96: % y/y | T96: Gross Profit | U96: % margin | V96: CA EBITDA | W96: % margin | X96: Capex | Y96: % revenue | Z96: FCF | AA96: % conversion | AB96: NWC | AC96: % revenue | AE96: =++$Q96 -> Date Label | AF96: =++R96 -> Revenue | AG96: =++S96 -> % y/y | AI96: =++$Q96 -> Date Label | AJ96: =++T96 -> Gross Profit | AK96: =++U96 -> % margin | AM96: =++$Q96 -> Date Label | AN96: =++V96 -> CA EBITDA | AO96: =++W96 -> % margin | AQ96: =++$Q96 -> Date Label | AR96: =++X96 -> Capex | AS96: =++Y96 -> % revenue | AU96: =++$Q96 -> Date Label | AV96: =++Z96 -> FCF | AW96: =++AA96 -> % conversion | AY96: =++$Q96 -> Date Label | AZ96: =++AB96 -> NWC | BA96: =++AC96 -> % revenue | BC96: Date (LU) | BD96: Date Label | BE96: TNL | BF96: Covenant | BG96: % cushion | BH96: FCCR | BI96: Covenant | BJ96: % cushion | BK96: Liquidity | BL96: Covenant | BM96: % cushion | BN96: OL RR | BO96: OL Mark | BQ96: =++$BD96 -> Date Label | BR96: =++BE96 -> TNL | BS96: =++BF96 -> Covenant | BT96: =++BG96 -> % cushion | BV96: =++$BD96 -> Date Label | BW96: =++BH96 -> FCCR | BX96: =++BI96 -> Covenant | BY96: =++BJ96 -> % cushion | CA96: =++$BD96 -> Date Label | CB96: =++BK96 -> Liquidity | CC96: =++BL96 -> Covenant | CD96: =++BM96 -> % cushion | CF96: =++$BD96 -> Date Label | CG96: =++BN96 -> OL RR | CH96: =++BO96 -> OL Mark
P97: {=_xlfn.LET( _xlpm._LTM, N(LTMDate), _xlpm._FYE, N(FYEDate), _xlpm._Avail, 'Financials Input'!$G$3:$DC$3, _xlpm._FYEM, MONTH(_xlpm._FYE), _xlpm._CandPrev, EOMONTH(DATE(YEAR(_xlpm._LTM)-1, _xlpm._FYEM, 1), 0), _xlpm._CandThis, EOMONTH(DATE(YEAR(_xlpm._LTM), _xlpm._FYEM, 1), 0), _xlpm._CandNext, EOMONTH(DATE(YEAR(_xlpm._LTM)+1, _xlpm._FYEM, 1), 0), _xlpm._FYE0_raw, MAX(_xlfn._xlws.FILTER(_xlfn.VSTACK(_xlpm._CandPrev,_xlpm._CandThis,_xlpm._CandNext), _xlfn.VSTACK(_xlpm._CandPrev,_xlpm._CandThis,_xlpm._CandNext)<=_xlpm._LTM)), _xlpm._FYE0, IF(_xlpm._FYE0_raw=_xlpm._LTM, EOMONTH(_xlpm._FYE0_raw,-12), _xlpm._FYE0_raw), _xlpm._FYE_1, EOMONTH(_xlpm._FYE0,-12), _xlpm._FYE_2, EOMONTH(_xlpm._FYE0,-24), _xlpm._FY2_Q1, EOMONTH(_xlpm._FYE_2, 3), _xlpm._FY2_Q2, EOMONTH(_xlpm._FYE_2, 6), _xlpm._FY2_Q3, EOMONTH(_xlpm._FYE_2, 9), _xlpm._FY1_Q1, EOMONTH(_xlpm._FYE_1, 3), _xlpm._FY1_Q2, EOMONTH(_xlpm._FYE_1, 6), _xlpm._FY1_Q3, EOMONTH(_xlpm._FYE_1, 9), _xlpm._MonthStart, EOMONTH(_xlpm._FYE0, 1), _xlpm._MonthCount, MAX(0, (YEAR(_xlpm._LTM)-YEAR(_xlpm._MonthStart))*12 + (MONTH(_xlpm._LTM)-MONTH(_xlpm._MonthStart)) + 1), _xlpm._Months, IF(_xlpm._MonthCount=0, "", EOMONTH(_xlpm._MonthStart, _xlfn.SEQUENCE(_xlpm._MonthCount,1,0,1))), _xlpm._Schedule, _xlfn.VSTACK( _xlpm._FYE_2, _xlpm._FY2_Q1, _xlpm._FY2_Q2, _xlpm._FY2_Q3, _xlpm._FYE_1, _xlpm._FY1_Q1, _xlpm._FY1_Q2, _xlpm._FY1_Q3, _xlpm._FYE0, _xlpm._Months, _xlpm._LTM ), _xlpm._Valid, _xlfn._xlws.FILTER(_xlpm._Schedule, (_xlpm._Schedule<=_xlpm._LTM)*ISNUMBER(MATCH(_xlpm._Schedule,_xlpm._Avail,0)), ""), IFERROR(_xlfn._xlws.SORT(_xlfn.UNIQUE(_xlpm._Valid)), "") )} -> 44926 | Q97: {=_xlfn.LET( _xlpm.LUDate,_xlfn.ANCHORARRAY( P97), _xlpm.FYEMonth, MONTH(FYEDate), _xlpm.LUMonth, MONTH(_xlpm.LUDate), _xlpm.LUYear, YEAR(_xlpm.LUDate), _xlpm.QtrEndMonths, MOD(_xlpm.FYEMonth - {9,6,3,0} - 1, 12) + 1, _xlpm.IsQtrEnd, ISNUMBER(MATCH(_xlpm.LUMonth, _xlpm.QtrEndMonths, 0)), _xlpm.QtrNum, IFERROR(MATCH(_xlpm.LUMonth, _xlpm.QtrEndMonths, 0), 0), _xlpm.FYYear, IF(_xlpm.LUMonth > _xlpm.FYEMonth, _xlpm.LUYear + 1, _xlpm.LUYear), _xlpm.FYLabel, "Q" & _xlpm.QtrNum & "'" & RIGHT(TEXT(DATE(_xlpm.FYYear, 1, 1), "YY"), 2), _xlpm.MonthLabel, TEXT(_xlpm.LUDate, "MMM'YY"), IF(_xlpm.IsQtrEnd, _xlpm.FYLabel, _xlpm.MonthLabel) )} -> Q4'22 | R97: {=++_xlfn.LET(_xlpm.LUDates,_xlfn.ANCHORARRAY($P$97),_xlpm.HeaderRow,'Financials Input'!$G$3:$DD$3,_xlpm.DataRow,CHOOSE(MATCH(FinChartType,{"Reported","Restated","Pro Forma"},0),'Financials Input'!$G$10:$DD$10,'Financials Input'!$G$157:$DD$157,'Financials Input'!$G$304:$DD$304)/1000,IFERROR(INDEX(_xlpm.DataRow,MATCH(_xlpm.LUDates,_xlpm.HeaderRow,0)),""))} -> 0 | S97: {=++_xlfn.LET(_xlpm.LUDates,_xlfn.ANCHORARRAY($P$97),_xlpm.HeaderRow,'Financials Input'!$G$3:$DD$3,_xlpm.DataRow,CHOOSE(MATCH(FinChartType,{"Reported","Restated","Pro Forma"},0),'Financials Input'!$G$11:$DD$11,'Financials Input'!$G$158:$DD$158,'Financials Input'!$G$305:$DD$305),IFERROR(INDEX(_xlpm.DataRow,MATCH(_xlpm.LUDates,_xlpm.HeaderRow,0)),""))} -> n/a | T97: {=_xlfn.LET(_xlpm.LUDates,_xlfn.ANCHORARRAY($P$97),_xlpm.HeaderRow,'Financials Input'!$G$3:$DD$3,_xlpm.DataRow,CHOOSE(MATCH(FinChartType,{"Reported","Restated","Pro Forma"},0),'Financials Input'!$G$13:$DD$13,'Financials Input'!$G$160:$DD$160,'Financials Input'!$G$307:$DD$307)/1000,IFERROR(INDEX(_xlpm.DataRow,MATCH(_xlpm.LUDates,_xlpm.HeaderRow,0)),""))} -> 0 | U97: {=_xlfn.LET(_xlpm.LUDates,_xlfn.ANCHORARRAY($P$97),_xlpm.HeaderRow,'Financials Input'!$G$3:$DD$3,_xlpm.DataRow,CHOOSE(MATCH(FinChartType,{"Reported","Restated","Pro Forma"},0),'Financials Input'!$G$14:$DD$14,'Financials Input'!$G$161:$DD$161,'Financials Input'!$G$308:$DD$308),IFERROR(INDEX(_xlpm.DataRow,MATCH(_xlpm.LUDates,_xlpm.HeaderRow,0)),""))} -> n/a | V97: {=_xlfn.LET(_xlpm.LUDates,_xlfn.ANCHORARRAY($P$97),_xlpm.HeaderRow,'Financials Input'!$G$3:$DD$3,_xlpm.DataRow,CHOOSE(MATCH(FinChartType,{"Reported","Restated","Pro Forma"},0),'Financials Input'!$G$48:$DD$48,'Financials Input'!$G$195:$DD$195,'Financials Input'!$G$342:$DD$342)/1000,IFERROR(INDEX(_xlpm.DataRow,MATCH(_xlpm.LUDates,_xlpm.HeaderRow,0)),""))} -> 0 | W97: {=_xlfn.LET(_xlpm.LUDates,_xlfn.ANCHORARRAY($P$97),_xlpm.HeaderRow,'Financials Input'!$G$3:$DD$3,_xlpm.DataRow,CHOOSE(MATCH(FinChartType,{"Reported","Restated","Pro Forma"},0),'Financials Input'!$G$49:$DD$49,'Financials Input'!$G$196:$DD$196,'Financials Input'!$G$343:$DD$343),IFERROR(INDEX(_xlpm.DataRow,MATCH(_xlpm.LUDates,_xlpm.HeaderRow,0)),""))} -> n/a | X97: {=_xlfn.LET(_xlpm.LUDates,_xlfn.ANCHORARRAY($P$97),_xlpm.HeaderRow,'Financials Input'!$G$3:$DD$3,_xlpm.DataRow,CHOOSE(MATCH(FinChartType,{"Reported","Restated","Pro Forma"},0),'Financials Input'!$G$52:$DD$52,'Financials Input'!$G$199:$DD$199,'Financials Input'!$G$346:$DD$346)/1000,IFERROR(INDEX(_xlpm.DataRow,MATCH(_xlpm.LUDates,_xlpm.HeaderRow,0)),""))} -> 0 | Y97: {=_xlfn.LET(_xlpm.LUDates,_xlfn.ANCHORARRAY($P$97),_xlpm.HeaderRow,'Financials Input'!$G$3:$DD$3,_xlpm.DataRow,CHOOSE(MATCH(FinChartType,{"Reported","Restated","Pro Forma"},0),'Financials Input'!$G$53:$DD$53,'Financials Input'!$G$200:$DD$200,'Financials Input'!$G$347:$DD$347),IFERROR(INDEX(_xlpm.DataRow,MATCH(_xlpm.LUDates,_xlpm.HeaderRow,0)),""))} -> n/a | Z97: {=IFERROR(_xlfn.ANCHORARRAY($V$97)*_xlfn.ANCHORARRAY($AA$97),"")} | AA97: {=_xlfn.LET(_xlpm.LUDates,_xlfn.ANCHORARRAY($P$97),_xlpm.HeaderRow,'Financials Input'!$G$3:$DD$3,_xlpm.DataRow,CHOOSE(MATCH(FinChartType,{"Reported","Restated","Pro Forma"},0),'Financials Input'!$G$54:$DD$54,'Financials Input'!$G$201:$DD$201,'Financials Input'!$G$348:$DD$348),IFERROR(INDEX(_xlpm.DataRow,MATCH(_xlpm.LUDates,_xlpm.HeaderRow,0)),""))} -> n/a | AB97: {=++_xlfn.LET(_xlpm.LUDates,_xlfn.ANCHORARRAY($P$97),_xlpm.HeaderRow,'Financials Input'!$G$3:$DD$3,_xlpm.DataRow,'Financials Input'!$G$575:$DD$575/1000,IFERROR(INDEX(_xlpm.DataRow,MATCH(_xlpm.LUDates,_xlpm.HeaderRow,0)),""))} -> 0 | AC97: {=++_xlfn.LET(_xlpm.LUDates,_xlfn.ANCHORARRAY($P$97),_xlpm.HeaderRow,'Financials Input'!$G$3:$DD$3,_xlpm.DataRow,'Financials Input'!$G$576:$DD$576,IFERROR(INDEX(_xlpm.DataRow,MATCH(_xlpm.LUDates,_xlpm.HeaderRow,0)),""))} -> n/a | AE97: {=++_xlfn.HSTACK(_xlfn.ANCHORARRAY(Charts!$Q$97),_xlfn.ANCHORARRAY( Charts!$R$97), IF(ISNUMBER(_xlfn.ANCHORARRAY(Charts!$S$97)),_xlfn.ANCHORARRAY(Charts!$S$97),NA()))} -> Q4'22 | AF97: 0 | AG97: #N/A | AI97: {=++_xlfn.HSTACK(_xlfn.ANCHORARRAY(Charts!$Q$97),_xlfn.ANCHORARRAY( Charts!$T$97), IF(ISNUMBER(_xlfn.ANCHORARRAY(Charts!$U$97)),_xlfn.ANCHORARRAY(Charts!$U$97),NA()))} -> Q4'22 | AJ97: 0 | AK97: #N/A | AM97: {=++_xlfn.HSTACK(_xlfn.ANCHORARRAY(Charts!$Q$97),_xlfn.ANCHORARRAY( Charts!$V$97), IF(ISNUMBER(_xlfn.ANCHORARRAY(Charts!$W$97)),_xlfn.ANCHORARRAY(Charts!$W$97),NA()))} -> Q4'22 | AN97: 0 | AO97: #N/A | AQ97: {=++_xlfn.HSTACK(_xlfn.ANCHORARRAY(Charts!$Q$97),_xlfn.ANCHORARRAY( Charts!$X$97), IF(ISNUMBER(_xlfn.ANCHORARRAY(Charts!$Y$97)),_xlfn.ANCHORARRAY(Charts!$Y$97),NA()))} -> Q4'22 | AR97: 0 | AS97: #N/A | AU97: {=++_xlfn.HSTACK(_xlfn.ANCHORARRAY(Charts!$Q$97),_xlfn.ANCHORARRAY( Charts!$Z$97), IF(ISNUMBER(_xlfn.ANCHORARRAY(Charts!$AA$97)),_xlfn.ANCHORARRAY(Charts!$AA$97),NA()))} -> Q4'22 | AW97: #N/A | AY97: {=++_xlfn.HSTACK(_xlfn.ANCHORARRAY(Charts!$Q$97),_xlfn.ANCHORARRAY( Charts!$AB$97), IF(ISNUMBER(_xlfn.ANCHORARRAY(Charts!$AC$97)),_xlfn.ANCHORARRAY(Charts!$AC$97),NA()))} -> Q4'22 | AZ97: 0 | BA97: #N/A | BC97: {=++_xlfn.LET( _xlpm.qtrs,'Covenant Input'!$I$3:$AO$3, _xlpm.close,'Financials Input'!$G$588:$DC$588, _xlpm.q_all,IFERROR(_xlfn.TOCOL(_xlpm.qtrs,1),""), _xlpm.c_all,IFERROR(_xlfn.TOCOL(_xlpm.close,1),""), _xlpm.q_dates,_xlfn._xlws.FILTER(_xlpm.q_all,(_xlpm.q_all<>"")*(ISNUMBER(_xlpm.q_all)),""), _xlpm.c_dates,_xlfn._xlws.FILTER(_xlpm.c_all,(_xlpm.c_all<>"")*(ISNUMBER(_xlpm.c_all)),""), _xlpm.startClose,MIN(_xlpm.c_dates), _xlpm.combined,_xlfn.VSTACK(_xlpm.q_dates,_xlpm.c_dates), _xlpm.window,_xlfn._xlws.FILTER(_xlpm.combined,(_xlpm.combined>=_xlpm.startClose)*(_xlpm.combined<=LTMDate),""), _xlfn._xlws.SORT(_xlfn.UNIQUE(_xlpm.window)) )} -> 45611 | BD97: {=++_xlfn.LET( _xlpm.d,_xlfn.ANCHORARRAY( $BC$97), _xlfn.MAP(_xlpm.d, _xlfn.LAMBDA(_xlpm.x, IFERROR( INDEX('Covenant Input'!$I$2:$AO$2, 1, MATCH(_xlpm.x, 'Covenant Input'!$I$3:$AO$3, 0)) & "A", INDEX('Financials Input'!$G$587:$DC$587, 1, MATCH(_xlpm.x, 'Financials Input'!$G$588:$DC$588, 0)) & " (" & TEXT( INDEX('Financials Input'!$G$588:$DC$588, 1, MATCH(_xlpm.x, 'Financials Input'!$G$588:$DC$588, 0)), "M/YY" ) & ")" ) ) ) )} -> LBO (11/24) | BE97: {=++_xlfn.LET(_xlpm.d,_xlfn.ANCHORARRAY($BC$97),_xlfn.MAP(_xlpm.d,_xlfn.LAMBDA(_xlpm.x,IFERROR(INDEX('Covenant Input'!$I$195:$AO$195,0,MATCH(_xlpm.x,'Covenant Input'!$I$3:$AO$3,0)),INDEX('Financials Input'!$G$636:$DC$636,0,MATCH(_xlpm.x,'Financials Input'!$G$588:$DC$588,0))))))} -> 0 | BF97: {=_xlfn.LET( _xlpm.d,_xlfn.ANCHORARRAY( $BC$97), _xlpm.q_raw, 'Covenant Input'!$I$3:$AO$3, _xlpm.v_raw, 'Covenant Input'!$I$196:$AO$196, _xlpm.m, ISNUMBER(_xlpm.q_raw), _xlpm.q, _xlfn._xlws.FILTER(_xlpm.q_raw, _xlpm.m), _xlpm.v, _xlfn._xlws.FILTER(_xlpm.v_raw, _xlpm.m), _xlfn.MAP(_xlpm.d, _xlfn.LAMBDA(_xlpm.x, _xlfn.LET( _xlpm.pe, IFERROR(MATCH(_xlpm.x, _xlpm.q, 0), ""), _xlpm.pp, IFERROR(MATCH(_xlpm.x, _xlpm.q, 1), 0), _xlpm.p, IF(_xlpm.pe<>"", _xlpm.pe, MIN(_xlpm.pp+1, COLUMNS(_xlpm.q))), INDEX(_xlpm.v, 1, _xlpm.p) ) ) ) )} -> 0 | BG97: {=++_xlfn.LET(_xlpm.lev_report,_xlfn.ANCHORARRAY($BE$97),_xlpm.lev_cov,_xlfn.ANCHORARRAY($BF$97),IFERROR(1-_xlpm.lev_report/_xlpm.lev_cov,0))} -> 0 | BH97: {=++_xlfn.LET(_xlpm.d,_xlfn.ANCHORARRAY($BC$97),_xlfn.MAP(_xlpm.d,_xlfn.LAMBDA(_xlpm.x,IFERROR(INDEX('Covenant Input'!$I$212:$AO$212,0,MATCH(_xlpm.x,'Covenant Input'!$I$3:$AO$3,0)),INDEX('Financials Input'!$G$639:$DC$639,0,MATCH(_xlpm.x,'Financials Input'!$G$588:$DC$588,0))))))} -> 0 | BI97: {=_xlfn.LET( _xlpm.d,_xlfn.ANCHORARRAY( $BC$97), _xlpm.q_raw, 'Covenant Input'!$I$3:$AO$3, _xlpm.v_raw, 'Covenant Input'!$I$213:$AO$213, _xlpm.m, ISNUMBER(_xlpm.q_raw), _xlpm.q, _xlfn._xlws.FILTER(_xlpm.q_raw, _xlpm.m), _xlpm.v, _xlfn._xlws.FILTER(_xlpm.v_raw, _xlpm.m), _xlfn.MAP(_xlpm.d, _xlfn.LAMBDA(_xlpm.x, _xlfn.LET( _xlpm.pe, IFERROR(MATCH(_xlpm.x, _xlpm.q, 0), ""), _xlpm.pp, IFERROR(MATCH(_xlpm.x, _xlpm.q, 1), 0), _xlpm.p, IF(_xlpm.pe<>"", _xlpm.pe, MIN(_xlpm.pp+1, COLUMNS(_xlpm.q))), INDEX(_xlpm.v, 1, _xlpm.p) ) ) ) )} -> 0 | BJ97: {=++_xlfn.LET(_xlpm.fccr_report,_xlfn.ANCHORARRAY(BH97),_xlpm.fccr_cov,_xlfn.ANCHORARRAY(BI97),IFERROR(1-_xlpm.fccr_cov/_xlpm.fccr_report,0))} -> 0 | BK97: {=++_xlfn.LET(_xlpm.d,_xlfn.ANCHORARRAY($BC$97),_xlfn.MAP(_xlpm.d,_xlfn.LAMBDA(_xlpm.x,IFERROR(INDEX('Covenant Input'!$I$223:$AO$223,0,MATCH(_xlpm.x,'Covenant Input'!$I$3:$AO$3,0)),INDEX('Financials Input'!$G$640:$DC$640,0,MATCH(_xlpm.x,'Financials Input'!$G$588:$DC$588,0)))/1000)))} -> 0 | BL97: {=_xlfn.LET( _xlpm.d,_xlfn.ANCHORARRAY( $BC$97), _xlpm.q_raw, 'Covenant Input'!$I$3:$AO$3, _xlpm.v_raw, 'Covenant Input'!$I$224:$AO$224, _xlpm.m, ISNUMBER(_xlpm.q_raw), _xlpm.q, _xlfn._xlws.FILTER(_xlpm.q_raw, _xlpm.m), _xlpm.v, _xlfn._xlws.FILTER(_xlpm.v_raw, _xlpm.m), _xlfn.MAP(_xlpm.d, _xlfn.LAMBDA(_xlpm.x, _xlfn.LET( _xlpm.pe, IFERROR(MATCH(_xlpm.x, _xlpm.q, 0), ""), _xlpm.pp, IFERROR(MATCH(_xlpm.x, _xlpm.q, 1), 0), _xlpm.p, IF(_xlpm.pe<>"", _xlpm.pe, MIN(_xlpm.pp+1, COLUMNS(_xlpm.q))), INDEX(_xlpm.v, 1, _xlpm.p) ) ) ) )/1000} -> 0 | BM97: {=++_xlfn.LET(_xlpm.liq_report,_xlfn.ANCHORARRAY($BK$97),_xlpm.liq_cov,_xlfn.ANCHORARRAY($BL$97),IFERROR(1-_xlpm.liq_cov/_xlpm.liq_report,0))} -> 0 | BQ97: {=++_xlfn.HSTACK(_xlfn.ANCHORARRAY(Charts!$BD$97),_xlfn.ANCHORARRAY( Charts!$BE$97),_xlfn.ANCHORARRAY( Charts!$BF$97),_xlfn.ANCHORARRAY( Charts!$BG$97))} -> LBO (11/24) | BR97: 0 | BS97: 0 | BT97: 0 | BV97: {=++_xlfn.HSTACK(_xlfn.ANCHORARRAY(Charts!$BD$97),_xlfn.ANCHORARRAY( Charts!$BH$97),_xlfn.ANCHORARRAY( Charts!$BI$97),_xlfn.ANCHORARRAY( Charts!$BJ$97))} -> LBO (11/24) | BW97: 0 | BX97: 0 | BY97: 0 | CA97: {=++_xlfn.HSTACK(_xlfn.ANCHORARRAY(Charts!$BD$97),_xlfn.ANCHORARRAY( Charts!$BK$97),_xlfn.ANCHORARRAY( Charts!$BL$97),_xlfn.ANCHORARRAY( Charts!$BM$97))} -> LBO (11/24) | CB97: 0 | CC97: 0 | CD97: 0 | CF97: {=++_xlfn.HSTACK(_xlfn.ANCHORARRAY(Charts!$BD$97),_xlfn.ANCHORARRAY( Charts!$BL$97),_xlfn.ANCHORARRAY( Charts!$BM$97))} -> LBO (11/24) | CG97: 0 | CH97: 0
P98: 45016 | Q98: Q1'23 | R98: 0 | S98: n/a | T98: 0 | U98: n/a | V98: 0 | W98: n/a | X98: 0 | Y98: n/a | AA98: n/a | AB98: 0 | AC98: n/a | AE98: Q1'23 | AF98: 0 | AG98: #N/A | AI98: Q1'23 | AJ98: 0 | AK98: #N/A | AM98: Q1'23 | AN98: 0 | AO98: #N/A | AQ98: Q1'23 | AR98: 0 | AS98: #N/A | AU98: Q1'23 | AW98: #N/A | AY98: Q1'23 | AZ98: 0 | BA98: #N/A | BC98: 45657 | BD98: Q4'24A | BE98: 0 | BF98: 0 | BG98: 0 | BH98: 0 | BI98: 0 | BJ98: 0 | BK98: 0 | BL98: 0 | BM98: 0 | BQ98: Q4'24A | BR98: 0 | BS98: 0 | BT98: 0 | BV98: Q4'24A | BW98: 0 | BX98: 0 | BY98: 0 | CA98: Q4'24A | CB98: 0 | CC98: 0 | CD98: 0 | CF98: Q4'24A | CG98: 0 | CH98: 0
P99: 45107 | Q99: Q2'23 | R99: 0 | S99: n/a | T99: 0 | U99: n/a | V99: 0 | W99: n/a | X99: 0 | Y99: n/a | AA99: n/a | AB99: 0 | AC99: n/a | AE99: Q2'23 | AF99: 0 | AG99: #N/A | AI99: Q2'23 | AJ99: 0 | AK99: #N/A | AM99: Q2'23 | AN99: 0 | AO99: #N/A | AQ99: Q2'23 | AR99: 0 | AS99: #N/A | AU99: Q2'23 | AW99: #N/A | AY99: Q2'23 | AZ99: 0 | BA99: #N/A | BC99: 45747 | BD99: Q1'25A | BE99: 0 | BF99: 0 | BG99: 0 | BH99: 0 | BI99: 0 | BJ99: 0 | BK99: 0 | BL99: 0 | BM99: 0 | BQ99: Q1'25A | BR99: 0 | BS99: 0 | BT99: 0 | BV99: Q1'25A | BW99: 0 | BX99: 0 | BY99: 0 | CA99: Q1'25A | CB99: 0 | CC99: 0 | CD99: 0 | CF99: Q1'25A | CG99: 0 | CH99: 0
P100: 45199 | Q100: Q3'23 | R100: 0 | S100: n/a | T100: 0 | U100: n/a | V100: 0 | W100: n/a | X100: 0 | Y100: n/a | AA100: n/a | AB100: 0 | AC100: n/a | AE100: Q3'23 | AF100: 0 | AG100: #N/A | AI100: Q3'23 | AJ100: 0 | AK100: #N/A | AM100: Q3'23 | AN100: 0 | AO100: #N/A | AQ100: Q3'23 | AR100: 0 | AS100: #N/A | AU100: Q3'23 | AW100: #N/A | AY100: Q3'23 | AZ100: 0 | BA100: #N/A | BC100: 45838 | BD100: Q2'25A | BE100: 0 | BF100: 0 | BG100: 0 | BH100: 0 | BI100: 0 | BJ100: 0 | BK100: 0 | BL100: 0 | BM100: 0 | BQ100: Q2'25A | BR100: 0 | BS100: 0 | BT100: 0 | BV100: Q2'25A | BW100: 0 | BX100: 0 | BY100: 0 | CA100: Q2'25A | CB100: 0 | CC100: 0 | CD100: 0 | CF100: Q2'25A | CG100: 0 | CH100: 0
P101: 45291 | Q101: Q4'23 | R101: 0 | S101: n/a | T101: 0 | U101: n/a | V101: 0 | W101: n/a | X101: 0 | Y101: n/a | AA101: n/a | AB101: 0 | AC101: n/a | AE101: Q4'23 | AF101: 0 | AG101: #N/A | AI101: Q4'23 | AJ101: 0 | AK101: #N/A | AM101: Q4'23 | AN101: 0 | AO101: #N/A | AQ101: Q4'23 | AR101: 0 | AS101: #N/A | AU101: Q4'23 | AW101: #N/A | AY101: Q4'23 | AZ101: 0 | BA101: #N/A | BC101: 45930 | BD101: Q3'25A | BE101: 0 | BF101: 0 | BG101: 0 | BH101: 0 | BI101: 0 | BJ101: 0 | BK101: 0 | BL101: 0 | BM101: 0 | BQ101: Q3'25A | BR101: 0 | BS101: 0 | BT101: 0 | BV101: Q3'25A | BW101: 0 | BX101: 0 | BY101: 0 | CA101: Q3'25A | CB101: 0 | CC101: 0 | CD101: 0 | CF101: Q3'25A | CG101: 0 | CH101: 0
